2016-03-24 02:20:29 [11152] [INFO] Starting gunicorn 17.5
2016-03-24 02:20:29 [11152] [ERROR] Connection in use: ('0', 8000)
2016-03-24 02:20:29 [11152] [ERROR] Retrying in 1 second.
2016-03-24 02:20:30 [11152] [ERROR] Connection in use: ('0', 8000)
2016-03-24 02:20:30 [11152] [ERROR] Retrying in 1 second.
2016-03-24 02:20:31 [11152] [ERROR] Connection in use: ('0', 8000)
2016-03-24 02:20:31 [11152] [ERROR] Retrying in 1 second.
2016-03-24 02:20:32 [11152] [DEBUG] Arbiter booted
2016-03-24 02:20:32 [11152] [INFO] Listening at: http://0.0.0.0:8000 (11152)
2016-03-24 02:20:32 [11152] [INFO] Using worker: sync
2016-03-24 02:20:32 [11157] [INFO] Booting worker with pid: 11157
2016-03-23 23:20:43 [11157] [DEBUG] POST /ask/
Not Found: /ask/
2016-03-23 23:27:41 [11157] [DEBUG] POST /ask/
2016-03-23 23:27:41 [11157] [DEBUG] GET /question/81
Not Found: /question/81
2016-03-23 23:27:41 [11157] [DEBUG] GET /question/81/
/usr/local/lib/python2.7/dist-packages/django/template/utils.py:37: RemovedInDjango110Warning: You haven't defined a TEMPLATES setting. You must do so before upgrading to Django 1.10. Otherwise Django will be unable to load templates.
  "unable to load templates.", RemovedInDjango110Warning)

2016-03-23 23:28:31 [11157] [DEBUG] POST /ask/
Not Found: /ask/
2016-03-23 23:28:39 [11157] [DEBUG] POST /ask/
Not Found: /ask/
2016-03-23 23:29:39 [11157] [INFO] Parent changed, shutting down: <Worker 11157>
2016-03-23 23:29:39 [11157] [INFO] Worker exiting (pid: 11157)
2016-03-24 02:29:42 [11237] [INFO] Starting gunicorn 17.5
2016-03-24 02:29:42 [11237] [DEBUG] Arbiter booted
2016-03-24 02:29:42 [11237] [INFO] Listening at: http://0.0.0.0:8000 (11237)
2016-03-24 02:29:42 [11237] [INFO] Using worker: sync
2016-03-24 02:29:42 [11242] [INFO] Booting worker with pid: 11242
2016-03-24 02:29:42 [11242] [ERROR] Exception in worker process:
Traceback (most recent call last):
  File "/usr/lib/python2.7/dist-packages/gunicorn/arbiter.py", line 473, in spawn_worker
    worker.init_process()
  File "/usr/lib/python2.7/dist-packages/gunicorn/workers/base.py", line 100, in init_process
    self.wsgi = self.app.wsgi()
  File "/usr/lib/python2.7/dist-packages/gunicorn/app/base.py", line 115, in wsgi
    self.callable = self.load()
  File "/usr/lib/python2.7/dist-packages/gunicorn/app/wsgiapp.py", line 33, in load
    return util.import_app(self.app_uri)
  File "/usr/lib/python2.7/dist-packages/gunicorn/util.py", line 362, in import_app
    __import__(module)
ImportError: No module named ask.wsgi
Traceback (most recent call last):
  File "/usr/lib/python2.7/dist-packages/gunicorn/arbiter.py", line 473, in spawn_worker
    worker.init_process()
  File "/usr/lib/python2.7/dist-packages/gunicorn/workers/base.py", line 100, in init_process
    self.wsgi = self.app.wsgi()
  File "/usr/lib/python2.7/dist-packages/gunicorn/app/base.py", line 115, in wsgi
    self.callable = self.load()
  File "/usr/lib/python2.7/dist-packages/gunicorn/app/wsgiapp.py", line 33, in load
    return util.import_app(self.app_uri)
  File "/usr/lib/python2.7/dist-packages/gunicorn/util.py", line 362, in import_app
    __import__(module)
ImportError: No module named ask.wsgi
2016-03-24 02:29:42 [11242] [INFO] Worker exiting (pid: 11242)
2016-03-24 02:29:42 [11237] [INFO] Shutting down: Master
2016-03-24 02:29:42 [11237] [INFO] Reason: Worker failed to boot.
2016-03-24 02:29:52 [11246] [INFO] Starting gunicorn 17.5
2016-03-24 02:29:52 [11246] [DEBUG] Arbiter booted
2016-03-24 02:29:52 [11246] [INFO] Listening at: http://0.0.0.0:8000 (11246)
2016-03-24 02:29:52 [11246] [INFO] Using worker: sync
2016-03-24 02:29:52 [11251] [INFO] Booting worker with pid: 11251
2016-03-24 02:29:52 [11251] [ERROR] Exception in worker process:
Traceback (most recent call last):
  File "/usr/lib/python2.7/dist-packages/gunicorn/arbiter.py", line 473, in spawn_worker
    worker.init_process()
  File "/usr/lib/python2.7/dist-packages/gunicorn/workers/base.py", line 100, in init_process
    self.wsgi = self.app.wsgi()
  File "/usr/lib/python2.7/dist-packages/gunicorn/app/base.py", line 115, in wsgi
    self.callable = self.load()
  File "/usr/lib/python2.7/dist-packages/gunicorn/app/wsgiapp.py", line 33, in load
    return util.import_app(self.app_uri)
  File "/usr/lib/python2.7/dist-packages/gunicorn/util.py", line 362, in import_app
    __import__(module)
ImportError: No module named ask.wsgi
Traceback (most recent call last):
  File "/usr/lib/python2.7/dist-packages/gunicorn/arbiter.py", line 473, in spawn_worker
    worker.init_process()
  File "/usr/lib/python2.7/dist-packages/gunicorn/workers/base.py", line 100, in init_process
    self.wsgi = self.app.wsgi()
  File "/usr/lib/python2.7/dist-packages/gunicorn/app/base.py", line 115, in wsgi
    self.callable = self.load()
  File "/usr/lib/python2.7/dist-packages/gunicorn/app/wsgiapp.py", line 33, in load
    return util.import_app(self.app_uri)
  File "/usr/lib/python2.7/dist-packages/gunicorn/util.py", line 362, in import_app
    __import__(module)
ImportError: No module named ask.wsgi
2016-03-24 02:29:52 [11251] [INFO] Worker exiting (pid: 11251)
2016-03-24 02:29:52 [11246] [INFO] Shutting down: Master
2016-03-24 02:29:52 [11246] [INFO] Reason: Worker failed to boot.
2016-03-24 02:30:20 [11256] [INFO] Starting gunicorn 17.5
2016-03-24 02:30:20 [11256] [DEBUG] Arbiter booted
2016-03-24 02:30:20 [11256] [INFO] Listening at: http://0.0.0.0:8000 (11256)
2016-03-24 02:30:20 [11256] [INFO] Using worker: sync
2016-03-24 02:30:20 [11261] [INFO] Booting worker with pid: 11261
2016-03-23 23:30:22 [11261] [DEBUG] POST /ask/
2016-03-23 23:30:52 [11261] [INFO] Parent changed, shutting down: <Worker 11261>
2016-03-23 23:30:52 [11261] [INFO] Worker exiting (pid: 11261)
2016-03-24 02:31:15 [11270] [INFO] Starting gunicorn 17.5
2016-03-24 02:31:15 [11270] [DEBUG] Arbiter booted
2016-03-24 02:31:15 [11270] [INFO] Listening at: http://0.0.0.0:8000 (11270)
2016-03-24 02:31:15 [11270] [INFO] Using worker: sync
2016-03-24 02:31:15 [11275] [INFO] Booting worker with pid: 11275
2016-03-23 23:31:19 [11275] [DEBUG] POST /ask/
2016-03-23 23:31:19 [11275] [DEBUG] GET /
/usr/local/lib/python2.7/dist-packages/django/template/utils.py:37: RemovedInDjango110Warning: You haven't defined a TEMPLATES setting. You must do so before upgrading to Django 1.10. Otherwise Django will be unable to load templates.
  "unable to load templates.", RemovedInDjango110Warning)

2016-03-24 02:32:55 [11285] [INFO] Starting gunicorn 17.5
2016-03-24 02:32:55 [11285] [ERROR] Connection in use: ('0', 8000)
2016-03-24 02:32:55 [11285] [ERROR] Retrying in 1 second.
2016-03-24 02:32:56 [11285] [ERROR] Connection in use: ('0', 8000)
2016-03-24 02:32:56 [11285] [ERROR] Retrying in 1 second.
2016-03-24 02:32:57 [11292] [INFO] Starting gunicorn 17.5

Error: Already running on PID 11292 (or pid file '/home/tayfen/develop/stepic/web_apps/web/gunicorn.pid' is stale)

2016-03-24 02:32:57 [11285] [ERROR] Connection in use: ('0', 8000)
2016-03-24 02:32:57 [11285] [ERROR] Retrying in 1 second.
2016-03-24 02:32:58 [11285] [ERROR] Connection in use: ('0', 8000)
2016-03-24 02:32:58 [11285] [ERROR] Retrying in 1 second.
2016-03-24 02:32:59 [11285] [ERROR] Connection in use: ('0', 8000)
2016-03-24 02:32:59 [11285] [ERROR] Retrying in 1 second.
2016-03-24 02:33:00 [11285] [ERROR] Can't connect to ('0', 8000)
2016-03-23 23:33:01 [11275] [DEBUG] POST /ask/
2016-03-23 23:33:01 [11275] [INFO] Parent changed, shutting down: <Worker 11275>
2016-03-23 23:33:01 [11275] [INFO] Worker exiting (pid: 11275)
2016-03-24 02:33:12 [11300] [INFO] Starting gunicorn 17.5
2016-03-24 02:33:12 [11300] [DEBUG] Arbiter booted
2016-03-24 02:33:12 [11300] [INFO] Listening at: http://0.0.0.0:8000 (11300)
2016-03-24 02:33:12 [11300] [INFO] Using worker: sync
2016-03-24 02:33:12 [11305] [INFO] Booting worker with pid: 11305
2016-03-23 23:33:15 [11305] [DEBUG] POST /ask/
2016-03-23 23:33:15 [11305] [DEBUG] GET /question/85
Not Found: /question/85
2016-03-23 23:33:15 [11305] [DEBUG] GET /question/85/
/usr/local/lib/python2.7/dist-packages/django/template/utils.py:37: RemovedInDjango110Warning: You haven't defined a TEMPLATES setting. You must do so before upgrading to Django 1.10. Otherwise Django will be unable to load templates.
  "unable to load templates.", RemovedInDjango110Warning)

2016-03-23 23:35:03 [11305] [DEBUG] GET /question/85/
2016-03-23 23:36:39 [11305] [DEBUG] POST /ask/
Not Found: /ask/
2016-03-23 23:37:47 [11305] [DEBUG] POST /ask/
Not Found: /ask/
2016-03-24 02:37:55 [11319] [INFO] Starting gunicorn 17.5
2016-03-24 02:37:55 [11319] [ERROR] Connection in use: ('0', 8000)
2016-03-24 02:37:55 [11319] [ERROR] Retrying in 1 second.
2016-03-24 02:37:56 [11319] [ERROR] Connection in use: ('0', 8000)
2016-03-24 02:37:56 [11319] [ERROR] Retrying in 1 second.
2016-03-24 02:37:57 [11319] [ERROR] Connection in use: ('0', 8000)
2016-03-24 02:37:57 [11319] [ERROR] Retrying in 1 second.
2016-03-24 02:37:58 [11319] [ERROR] Connection in use: ('0', 8000)
2016-03-24 02:37:58 [11319] [ERROR] Retrying in 1 second.
2016-03-24 02:37:59 [11326] [INFO] Starting gunicorn 17.5

Error: Already running on PID 11326 (or pid file '/home/tayfen/develop/stepic/web_apps/web/gunicorn.pid' is stale)

2016-03-24 02:37:59 [11319] [ERROR] Connection in use: ('0', 8000)
2016-03-24 02:37:59 [11319] [ERROR] Retrying in 1 second.
2016-03-24 02:38:00 [11319] [ERROR] Can't connect to ('0', 8000)
2016-03-23 23:38:01 [11305] [DEBUG] POST /ask/
Not Found: /ask/
2016-03-23 23:38:01 [11305] [INFO] Parent changed, shutting down: <Worker 11305>
2016-03-23 23:38:01 [11305] [INFO] Worker exiting (pid: 11305)
2016-03-24 02:38:11 [11333] [INFO] Starting gunicorn 17.5
2016-03-24 02:38:11 [11333] [DEBUG] Arbiter booted
2016-03-24 02:38:11 [11333] [INFO] Listening at: http://0.0.0.0:8000 (11333)
2016-03-24 02:38:11 [11333] [INFO] Using worker: sync
2016-03-24 02:38:11 [11338] [INFO] Booting worker with pid: 11338
2016-03-23 23:38:14 [11338] [DEBUG] POST /ask/
2016-03-23 23:38:14 [11338] [DEBUG] GET /question/
Not Found: /question/
2016-03-24 02:38:51 [11347] [INFO] Starting gunicorn 17.5
2016-03-24 02:38:51 [11347] [ERROR] Connection in use: ('0', 8000)
2016-03-24 02:38:51 [11347] [ERROR] Retrying in 1 second.
2016-03-24 02:38:52 [11347] [ERROR] Connection in use: ('0', 8000)
2016-03-24 02:38:52 [11347] [ERROR] Retrying in 1 second.
2016-03-24 02:38:53 [11347] [ERROR] Connection in use: ('0', 8000)
2016-03-24 02:38:53 [11347] [ERROR] Retrying in 1 second.
2016-03-24 02:38:54 [11347] [ERROR] Connection in use: ('0', 8000)
2016-03-24 02:38:54 [11347] [ERROR] Retrying in 1 second.
2016-03-24 02:38:55 [11347] [ERROR] Connection in use: ('0', 8000)
2016-03-24 02:38:55 [11347] [ERROR] Retrying in 1 second.
2016-03-24 02:38:55 [11355] [INFO] Starting gunicorn 17.5

Error: Already running on PID 11355 (or pid file '/home/tayfen/develop/stepic/web_apps/web/gunicorn.pid' is stale)

2016-03-24 02:38:56 [11347] [ERROR] Can't connect to ('0', 8000)
2016-03-23 23:38:59 [11338] [INFO] Parent changed, shutting down: <Worker 11338>
2016-03-23 23:38:59 [11338] [INFO] Worker exiting (pid: 11338)
2016-03-24 02:39:01 [11363] [INFO] Starting gunicorn 17.5
2016-03-24 02:39:01 [11363] [DEBUG] Arbiter booted
2016-03-24 02:39:01 [11363] [INFO] Listening at: http://0.0.0.0:8000 (11363)
2016-03-24 02:39:01 [11363] [INFO] Using worker: sync
2016-03-24 02:39:01 [11368] [INFO] Booting worker with pid: 11368
2016-03-23 23:39:08 [11368] [DEBUG] POST /ask/
2016-03-23 23:39:08 [11368] [DEBUG] GET /question/1/
/usr/local/lib/python2.7/dist-packages/django/template/utils.py:37: RemovedInDjango110Warning: You haven't defined a TEMPLATES setting. You must do so before upgrading to Django 1.10. Otherwise Django will be unable to load templates.
  "unable to load templates.", RemovedInDjango110Warning)

2016-03-23 23:52:07 [11368] [DEBUG] GET /ask/
2016-03-23 23:52:15 [11368] [DEBUG] GET /ask/
2016-03-23 23:52:16 [11368] [DEBUG] GET /ask/
2016-03-23 23:53:51 [11368] [DEBUG] GET /ask/21312
2016-03-23 23:53:54 [11368] [DEBUG] GET /ask/21312
2016-03-23 23:54:01 [11368] [DEBUG] GET /ask/
2016-03-24 03:14:55 [11433] [INFO] Starting gunicorn 17.5
2016-03-24 03:14:55 [11433] [ERROR] Connection in use: ('0', 8000)
2016-03-24 03:14:55 [11433] [ERROR] Retrying in 1 second.
2016-03-24 03:14:56 [11433] [ERROR] Connection in use: ('0', 8000)
2016-03-24 03:14:56 [11433] [ERROR] Retrying in 1 second.
2016-03-24 03:14:57 [11433] [ERROR] Connection in use: ('0', 8000)
2016-03-24 03:14:57 [11433] [ERROR] Retrying in 1 second.
2016-03-24 03:14:58 [11433] [ERROR] Connection in use: ('0', 8000)
2016-03-24 03:14:58 [11433] [ERROR] Retrying in 1 second.
2016-03-24 03:14:59 [11433] [ERROR] Connection in use: ('0', 8000)
2016-03-24 03:14:59 [11433] [ERROR] Retrying in 1 second.
2016-03-24 03:15:00 [11441] [INFO] Starting gunicorn 17.5

Error: Already running on PID 11441 (or pid file '/home/tayfen/develop/stepic/web_apps/web/gunicorn.pid' is stale)

2016-03-24 03:15:00 [11433] [ERROR] Can't connect to ('0', 8000)
2016-03-24 00:15:02 [11368] [INFO] Parent changed, shutting down: <Worker 11368>
2016-03-24 00:15:02 [11368] [INFO] Worker exiting (pid: 11368)
2016-03-24 03:15:08 [11449] [INFO] Starting gunicorn 17.5
2016-03-24 03:15:08 [11449] [DEBUG] Arbiter booted
2016-03-24 03:15:08 [11449] [INFO] Listening at: http://0.0.0.0:8000 (11449)
2016-03-24 03:15:08 [11449] [INFO] Using worker: sync
2016-03-24 03:15:08 [11454] [INFO] Booting worker with pid: 11454
2016-03-24 00:15:23 [11454] [DEBUG] GET /ask
Not Found: /ask
2016-03-24 00:15:23 [11454] [DEBUG] GET /ask/
/usr/local/lib/python2.7/dist-packages/django/template/utils.py:37: RemovedInDjango110Warning: You haven't defined a TEMPLATES setting. You must do so before upgrading to Django 1.10. Otherwise Django will be unable to load templates.
  "unable to load templates.", RemovedInDjango110Warning)

2016-03-24 00:15:58 [11454] [DEBUG] POST /ask/
Internal Server Error: /ask/
Traceback (most recent call last):
  File "/usr/local/lib/python2.7/dist-packages/django/core/handlers/base.py", line 149, in get_response
    response = self.process_exception_by_middleware(e, request)
  File "/usr/local/lib/python2.7/dist-packages/django/core/handlers/base.py", line 147, in get_response
    response = wrapped_callback(request, *callback_args, **callback_kwargs)
  File "/home/tayfen/develop/stepic/web_apps/web/ask/qa/views.py", line 66, in ask
    if form.is_valid():
  File "/usr/local/lib/python2.7/dist-packages/django/forms/forms.py", line 161, in is_valid
    return self.is_bound and not self.errors
  File "/usr/local/lib/python2.7/dist-packages/django/forms/forms.py", line 153, in errors
    self.full_clean()
  File "/usr/local/lib/python2.7/dist-packages/django/forms/forms.py", line 363, in full_clean
    self._clean_form()
  File "/usr/local/lib/python2.7/dist-packages/django/forms/forms.py", line 390, in _clean_form
    cleaned_data = self.clean()
  File "/home/tayfen/develop/stepic/web_apps/web/ask/qa/forms.py", line 11, in clean
    if not text.is_valid():
AttributeError: 'unicode' object has no attribute 'is_valid'
2016-03-24 00:17:16 [11454] [DEBUG] POST /ask/
Internal Server Error: /ask/
Traceback (most recent call last):
  File "/usr/local/lib/python2.7/dist-packages/django/core/handlers/base.py", line 149, in get_response
    response = self.process_exception_by_middleware(e, request)
  File "/usr/local/lib/python2.7/dist-packages/django/core/handlers/base.py", line 147, in get_response
    response = wrapped_callback(request, *callback_args, **callback_kwargs)
  File "/home/tayfen/develop/stepic/web_apps/web/ask/qa/views.py", line 66, in ask
    if form.is_valid():
  File "/usr/local/lib/python2.7/dist-packages/django/forms/forms.py", line 161, in is_valid
    return self.is_bound and not self.errors
  File "/usr/local/lib/python2.7/dist-packages/django/forms/forms.py", line 153, in errors
    self.full_clean()
  File "/usr/local/lib/python2.7/dist-packages/django/forms/forms.py", line 363, in full_clean
    self._clean_form()
  File "/usr/local/lib/python2.7/dist-packages/django/forms/forms.py", line 390, in _clean_form
    cleaned_data = self.clean()
  File "/home/tayfen/develop/stepic/web_apps/web/ask/qa/forms.py", line 11, in clean
    if not text.is_valid():
AttributeError: 'unicode' object has no attribute 'is_valid'
2016-03-24 03:19:25 [11470] [INFO] Starting gunicorn 17.5

Error: Already running on PID 11470 (or pid file '/home/tayfen/develop/stepic/web_apps/web/gunicorn.pid' is stale)

2016-03-24 03:19:50 [11482] [INFO] Starting gunicorn 17.5
2016-03-24 03:19:50 [11482] [ERROR] Connection in use: ('0', 8000)
2016-03-24 03:19:50 [11482] [ERROR] Retrying in 1 second.
2016-03-24 03:19:51 [11482] [ERROR] Connection in use: ('0', 8000)
2016-03-24 03:19:51 [11482] [ERROR] Retrying in 1 second.
2016-03-24 03:19:52 [11482] [ERROR] Connection in use: ('0', 8000)
2016-03-24 03:19:52 [11482] [ERROR] Retrying in 1 second.
2016-03-24 03:19:53 [11482] [ERROR] Connection in use: ('0', 8000)
2016-03-24 03:19:53 [11482] [ERROR] Retrying in 1 second.
2016-03-24 03:19:54 [11482] [ERROR] Connection in use: ('0', 8000)
2016-03-24 03:19:54 [11482] [ERROR] Retrying in 1 second.
2016-03-24 03:19:55 [11482] [ERROR] Can't connect to ('0', 8000)
2016-03-24 03:19:58 [11494] [INFO] Starting gunicorn 17.5
2016-03-24 03:19:58 [11494] [ERROR] Connection in use: ('0', 8000)
2016-03-24 03:19:58 [11494] [ERROR] Retrying in 1 second.
2016-03-24 03:19:59 [11494] [ERROR] Connection in use: ('0', 8000)
2016-03-24 03:19:59 [11494] [ERROR] Retrying in 1 second.
2016-03-24 03:20:00 [11494] [ERROR] Connection in use: ('0', 8000)
2016-03-24 03:20:00 [11494] [ERROR] Retrying in 1 second.
2016-03-24 00:20:01 [11454] [INFO] Parent changed, shutting down: <Worker 11454>
2016-03-24 00:20:01 [11454] [INFO] Worker exiting (pid: 11454)
2016-03-24 03:20:01 [11494] [DEBUG] Arbiter booted
2016-03-24 03:20:01 [11494] [INFO] Listening at: http://0.0.0.0:8000 (11494)
2016-03-24 03:20:01 [11494] [INFO] Using worker: sync
2016-03-24 03:20:01 [11501] [INFO] Booting worker with pid: 11501
2016-03-24 00:20:11 [11501] [DEBUG] POST /ask/
2016-03-24 00:20:11 [11501] [DEBUG] GET /question/86
Not Found: /question/86
2016-03-24 00:20:11 [11501] [DEBUG] GET /question/86/
/usr/local/lib/python2.7/dist-packages/django/template/utils.py:37: RemovedInDjango110Warning: You haven't defined a TEMPLATES setting. You must do so before upgrading to Django 1.10. Otherwise Django will be unable to load templates.
  "unable to load templates.", RemovedInDjango110Warning)

