2016-03-24 02:20:29 [11152] [INFO] Starting gunicorn 17.5
2016-03-24 02:20:29 [11152] [ERROR] Connection in use: ('0', 8000)
2016-03-24 02:20:29 [11152] [ERROR] Retrying in 1 second.
2016-03-24 02:20:30 [11152] [ERROR] Connection in use: ('0', 8000)
2016-03-24 02:20:30 [11152] [ERROR] Retrying in 1 second.
2016-03-24 02:20:31 [11152] [ERROR] Connection in use: ('0', 8000)
2016-03-24 02:20:31 [11152] [ERROR] Retrying in 1 second.
2016-03-24 02:20:32 [11152] [DEBUG] Arbiter booted
2016-03-24 02:20:32 [11152] [INFO] Listening at: http://0.0.0.0:8000 (11152)
2016-03-24 02:20:32 [11152] [INFO] Using worker: sync
2016-03-24 02:20:32 [11157] [INFO] Booting worker with pid: 11157
2016-03-23 23:20:43 [11157] [DEBUG] POST /ask/
Not Found: /ask/
2016-03-23 23:27:41 [11157] [DEBUG] POST /ask/
2016-03-23 23:27:41 [11157] [DEBUG] GET /question/81
Not Found: /question/81
2016-03-23 23:27:41 [11157] [DEBUG] GET /question/81/
/usr/local/lib/python2.7/dist-packages/django/template/utils.py:37: RemovedInDjango110Warning: You haven't defined a TEMPLATES setting. You must do so before upgrading to Django 1.10. Otherwise Django will be unable to load templates.
  "unable to load templates.", RemovedInDjango110Warning)

2016-03-23 23:28:31 [11157] [DEBUG] POST /ask/
Not Found: /ask/
2016-03-23 23:28:39 [11157] [DEBUG] POST /ask/
Not Found: /ask/
2016-03-23 23:29:39 [11157] [INFO] Parent changed, shutting down: <Worker 11157>
2016-03-23 23:29:39 [11157] [INFO] Worker exiting (pid: 11157)
2016-03-24 02:29:42 [11237] [INFO] Starting gunicorn 17.5
2016-03-24 02:29:42 [11237] [DEBUG] Arbiter booted
2016-03-24 02:29:42 [11237] [INFO] Listening at: http://0.0.0.0:8000 (11237)
2016-03-24 02:29:42 [11237] [INFO] Using worker: sync
2016-03-24 02:29:42 [11242] [INFO] Booting worker with pid: 11242
2016-03-24 02:29:42 [11242] [ERROR] Exception in worker process:
Traceback (most recent call last):
  File "/usr/lib/python2.7/dist-packages/gunicorn/arbiter.py", line 473, in spawn_worker
    worker.init_process()
  File "/usr/lib/python2.7/dist-packages/gunicorn/workers/base.py", line 100, in init_process
    self.wsgi = self.app.wsgi()
  File "/usr/lib/python2.7/dist-packages/gunicorn/app/base.py", line 115, in wsgi
    self.callable = self.load()
  File "/usr/lib/python2.7/dist-packages/gunicorn/app/wsgiapp.py", line 33, in load
    return util.import_app(self.app_uri)
  File "/usr/lib/python2.7/dist-packages/gunicorn/util.py", line 362, in import_app
    __import__(module)
ImportError: No module named ask.wsgi
Traceback (most recent call last):
  File "/usr/lib/python2.7/dist-packages/gunicorn/arbiter.py", line 473, in spawn_worker
    worker.init_process()
  File "/usr/lib/python2.7/dist-packages/gunicorn/workers/base.py", line 100, in init_process
    self.wsgi = self.app.wsgi()
  File "/usr/lib/python2.7/dist-packages/gunicorn/app/base.py", line 115, in wsgi
    self.callable = self.load()
  File "/usr/lib/python2.7/dist-packages/gunicorn/app/wsgiapp.py", line 33, in load
    return util.import_app(self.app_uri)
  File "/usr/lib/python2.7/dist-packages/gunicorn/util.py", line 362, in import_app
    __import__(module)
ImportError: No module named ask.wsgi
2016-03-24 02:29:42 [11242] [INFO] Worker exiting (pid: 11242)
2016-03-24 02:29:42 [11237] [INFO] Shutting down: Master
2016-03-24 02:29:42 [11237] [INFO] Reason: Worker failed to boot.
2016-03-24 02:29:52 [11246] [INFO] Starting gunicorn 17.5
2016-03-24 02:29:52 [11246] [DEBUG] Arbiter booted
2016-03-24 02:29:52 [11246] [INFO] Listening at: http://0.0.0.0:8000 (11246)
2016-03-24 02:29:52 [11246] [INFO] Using worker: sync
2016-03-24 02:29:52 [11251] [INFO] Booting worker with pid: 11251
2016-03-24 02:29:52 [11251] [ERROR] Exception in worker process:
Traceback (most recent call last):
  File "/usr/lib/python2.7/dist-packages/gunicorn/arbiter.py", line 473, in spawn_worker
    worker.init_process()
  File "/usr/lib/python2.7/dist-packages/gunicorn/workers/base.py", line 100, in init_process
    self.wsgi = self.app.wsgi()
  File "/usr/lib/python2.7/dist-packages/gunicorn/app/base.py", line 115, in wsgi
    self.callable = self.load()
  File "/usr/lib/python2.7/dist-packages/gunicorn/app/wsgiapp.py", line 33, in load
    return util.import_app(self.app_uri)
  File "/usr/lib/python2.7/dist-packages/gunicorn/util.py", line 362, in import_app
    __import__(module)
ImportError: No module named ask.wsgi
Traceback (most recent call last):
  File "/usr/lib/python2.7/dist-packages/gunicorn/arbiter.py", line 473, in spawn_worker
    worker.init_process()
  File "/usr/lib/python2.7/dist-packages/gunicorn/workers/base.py", line 100, in init_process
    self.wsgi = self.app.wsgi()
  File "/usr/lib/python2.7/dist-packages/gunicorn/app/base.py", line 115, in wsgi
    self.callable = self.load()
  File "/usr/lib/python2.7/dist-packages/gunicorn/app/wsgiapp.py", line 33, in load
    return util.import_app(self.app_uri)
  File "/usr/lib/python2.7/dist-packages/gunicorn/util.py", line 362, in import_app
    __import__(module)
ImportError: No module named ask.wsgi
2016-03-24 02:29:52 [11251] [INFO] Worker exiting (pid: 11251)
2016-03-24 02:29:52 [11246] [INFO] Shutting down: Master
2016-03-24 02:29:52 [11246] [INFO] Reason: Worker failed to boot.
2016-03-24 02:30:20 [11256] [INFO] Starting gunicorn 17.5
2016-03-24 02:30:20 [11256] [DEBUG] Arbiter booted
2016-03-24 02:30:20 [11256] [INFO] Listening at: http://0.0.0.0:8000 (11256)
2016-03-24 02:30:20 [11256] [INFO] Using worker: sync
2016-03-24 02:30:20 [11261] [INFO] Booting worker with pid: 11261
2016-03-23 23:30:22 [11261] [DEBUG] POST /ask/
2016-03-23 23:30:52 [11261] [INFO] Parent changed, shutting down: <Worker 11261>
2016-03-23 23:30:52 [11261] [INFO] Worker exiting (pid: 11261)
2016-03-24 02:31:15 [11270] [INFO] Starting gunicorn 17.5
2016-03-24 02:31:15 [11270] [DEBUG] Arbiter booted
2016-03-24 02:31:15 [11270] [INFO] Listening at: http://0.0.0.0:8000 (11270)
2016-03-24 02:31:15 [11270] [INFO] Using worker: sync
2016-03-24 02:31:15 [11275] [INFO] Booting worker with pid: 11275
2016-03-23 23:31:19 [11275] [DEBUG] POST /ask/
2016-03-23 23:31:19 [11275] [DEBUG] GET /
/usr/local/lib/python2.7/dist-packages/django/template/utils.py:37: RemovedInDjango110Warning: You haven't defined a TEMPLATES setting. You must do so before upgrading to Django 1.10. Otherwise Django will be unable to load templates.
  "unable to load templates.", RemovedInDjango110Warning)

2016-03-24 02:32:55 [11285] [INFO] Starting gunicorn 17.5
2016-03-24 02:32:55 [11285] [ERROR] Connection in use: ('0', 8000)
2016-03-24 02:32:55 [11285] [ERROR] Retrying in 1 second.
2016-03-24 02:32:56 [11285] [ERROR] Connection in use: ('0', 8000)
2016-03-24 02:32:56 [11285] [ERROR] Retrying in 1 second.
2016-03-24 02:32:57 [11292] [INFO] Starting gunicorn 17.5

Error: Already running on PID 11292 (or pid file '/home/tayfen/develop/stepic/web_apps/web/gunicorn.pid' is stale)

2016-03-24 02:32:57 [11285] [ERROR] Connection in use: ('0', 8000)
2016-03-24 02:32:57 [11285] [ERROR] Retrying in 1 second.
2016-03-24 02:32:58 [11285] [ERROR] Connection in use: ('0', 8000)
2016-03-24 02:32:58 [11285] [ERROR] Retrying in 1 second.
2016-03-24 02:32:59 [11285] [ERROR] Connection in use: ('0', 8000)
2016-03-24 02:32:59 [11285] [ERROR] Retrying in 1 second.
2016-03-24 02:33:00 [11285] [ERROR] Can't connect to ('0', 8000)
2016-03-23 23:33:01 [11275] [DEBUG] POST /ask/
2016-03-23 23:33:01 [11275] [INFO] Parent changed, shutting down: <Worker 11275>
2016-03-23 23:33:01 [11275] [INFO] Worker exiting (pid: 11275)
2016-03-24 02:33:12 [11300] [INFO] Starting gunicorn 17.5
2016-03-24 02:33:12 [11300] [DEBUG] Arbiter booted
2016-03-24 02:33:12 [11300] [INFO] Listening at: http://0.0.0.0:8000 (11300)
2016-03-24 02:33:12 [11300] [INFO] Using worker: sync
2016-03-24 02:33:12 [11305] [INFO] Booting worker with pid: 11305
2016-03-23 23:33:15 [11305] [DEBUG] POST /ask/
2016-03-23 23:33:15 [11305] [DEBUG] GET /question/85
Not Found: /question/85
2016-03-23 23:33:15 [11305] [DEBUG] GET /question/85/
/usr/local/lib/python2.7/dist-packages/django/template/utils.py:37: RemovedInDjango110Warning: You haven't defined a TEMPLATES setting. You must do so before upgrading to Django 1.10. Otherwise Django will be unable to load templates.
  "unable to load templates.", RemovedInDjango110Warning)

2016-03-23 23:35:03 [11305] [DEBUG] GET /question/85/
2016-03-23 23:36:39 [11305] [DEBUG] POST /ask/
Not Found: /ask/
2016-03-23 23:37:47 [11305] [DEBUG] POST /ask/
Not Found: /ask/
2016-03-24 02:37:55 [11319] [INFO] Starting gunicorn 17.5
2016-03-24 02:37:55 [11319] [ERROR] Connection in use: ('0', 8000)
2016-03-24 02:37:55 [11319] [ERROR] Retrying in 1 second.
2016-03-24 02:37:56 [11319] [ERROR] Connection in use: ('0', 8000)
2016-03-24 02:37:56 [11319] [ERROR] Retrying in 1 second.
2016-03-24 02:37:57 [11319] [ERROR] Connection in use: ('0', 8000)
2016-03-24 02:37:57 [11319] [ERROR] Retrying in 1 second.
2016-03-24 02:37:58 [11319] [ERROR] Connection in use: ('0', 8000)
2016-03-24 02:37:58 [11319] [ERROR] Retrying in 1 second.
2016-03-24 02:37:59 [11326] [INFO] Starting gunicorn 17.5

Error: Already running on PID 11326 (or pid file '/home/tayfen/develop/stepic/web_apps/web/gunicorn.pid' is stale)

2016-03-24 02:37:59 [11319] [ERROR] Connection in use: ('0', 8000)
2016-03-24 02:37:59 [11319] [ERROR] Retrying in 1 second.
2016-03-24 02:38:00 [11319] [ERROR] Can't connect to ('0', 8000)
2016-03-23 23:38:01 [11305] [DEBUG] POST /ask/
Not Found: /ask/
2016-03-23 23:38:01 [11305] [INFO] Parent changed, shutting down: <Worker 11305>
2016-03-23 23:38:01 [11305] [INFO] Worker exiting (pid: 11305)
2016-03-24 02:38:11 [11333] [INFO] Starting gunicorn 17.5
2016-03-24 02:38:11 [11333] [DEBUG] Arbiter booted
2016-03-24 02:38:11 [11333] [INFO] Listening at: http://0.0.0.0:8000 (11333)
2016-03-24 02:38:11 [11333] [INFO] Using worker: sync
2016-03-24 02:38:11 [11338] [INFO] Booting worker with pid: 11338
2016-03-23 23:38:14 [11338] [DEBUG] POST /ask/
2016-03-23 23:38:14 [11338] [DEBUG] GET /question/
Not Found: /question/
2016-03-24 02:38:51 [11347] [INFO] Starting gunicorn 17.5
2016-03-24 02:38:51 [11347] [ERROR] Connection in use: ('0', 8000)
2016-03-24 02:38:51 [11347] [ERROR] Retrying in 1 second.
2016-03-24 02:38:52 [11347] [ERROR] Connection in use: ('0', 8000)
2016-03-24 02:38:52 [11347] [ERROR] Retrying in 1 second.
2016-03-24 02:38:53 [11347] [ERROR] Connection in use: ('0', 8000)
2016-03-24 02:38:53 [11347] [ERROR] Retrying in 1 second.
2016-03-24 02:38:54 [11347] [ERROR] Connection in use: ('0', 8000)
2016-03-24 02:38:54 [11347] [ERROR] Retrying in 1 second.
2016-03-24 02:38:55 [11347] [ERROR] Connection in use: ('0', 8000)
2016-03-24 02:38:55 [11347] [ERROR] Retrying in 1 second.
2016-03-24 02:38:55 [11355] [INFO] Starting gunicorn 17.5

Error: Already running on PID 11355 (or pid file '/home/tayfen/develop/stepic/web_apps/web/gunicorn.pid' is stale)

2016-03-24 02:38:56 [11347] [ERROR] Can't connect to ('0', 8000)
2016-03-23 23:38:59 [11338] [INFO] Parent changed, shutting down: <Worker 11338>
2016-03-23 23:38:59 [11338] [INFO] Worker exiting (pid: 11338)
2016-03-24 02:39:01 [11363] [INFO] Starting gunicorn 17.5
2016-03-24 02:39:01 [11363] [DEBUG] Arbiter booted
2016-03-24 02:39:01 [11363] [INFO] Listening at: http://0.0.0.0:8000 (11363)
2016-03-24 02:39:01 [11363] [INFO] Using worker: sync
2016-03-24 02:39:01 [11368] [INFO] Booting worker with pid: 11368
2016-03-23 23:39:08 [11368] [DEBUG] POST /ask/
2016-03-23 23:39:08 [11368] [DEBUG] GET /question/1/
/usr/local/lib/python2.7/dist-packages/django/template/utils.py:37: RemovedInDjango110Warning: You haven't defined a TEMPLATES setting. You must do so before upgrading to Django 1.10. Otherwise Django will be unable to load templates.
  "unable to load templates.", RemovedInDjango110Warning)

2016-03-23 23:52:07 [11368] [DEBUG] GET /ask/
2016-03-23 23:52:15 [11368] [DEBUG] GET /ask/
2016-03-23 23:52:16 [11368] [DEBUG] GET /ask/
2016-03-23 23:53:51 [11368] [DEBUG] GET /ask/21312
2016-03-23 23:53:54 [11368] [DEBUG] GET /ask/21312
2016-03-23 23:54:01 [11368] [DEBUG] GET /ask/
2016-03-24 03:14:55 [11433] [INFO] Starting gunicorn 17.5
2016-03-24 03:14:55 [11433] [ERROR] Connection in use: ('0', 8000)
2016-03-24 03:14:55 [11433] [ERROR] Retrying in 1 second.
2016-03-24 03:14:56 [11433] [ERROR] Connection in use: ('0', 8000)
2016-03-24 03:14:56 [11433] [ERROR] Retrying in 1 second.
2016-03-24 03:14:57 [11433] [ERROR] Connection in use: ('0', 8000)
2016-03-24 03:14:57 [11433] [ERROR] Retrying in 1 second.
2016-03-24 03:14:58 [11433] [ERROR] Connection in use: ('0', 8000)
2016-03-24 03:14:58 [11433] [ERROR] Retrying in 1 second.
2016-03-24 03:14:59 [11433] [ERROR] Connection in use: ('0', 8000)
2016-03-24 03:14:59 [11433] [ERROR] Retrying in 1 second.
2016-03-24 03:15:00 [11441] [INFO] Starting gunicorn 17.5

Error: Already running on PID 11441 (or pid file '/home/tayfen/develop/stepic/web_apps/web/gunicorn.pid' is stale)

2016-03-24 03:15:00 [11433] [ERROR] Can't connect to ('0', 8000)
2016-03-24 00:15:02 [11368] [INFO] Parent changed, shutting down: <Worker 11368>
2016-03-24 00:15:02 [11368] [INFO] Worker exiting (pid: 11368)
2016-03-24 03:15:08 [11449] [INFO] Starting gunicorn 17.5
2016-03-24 03:15:08 [11449] [DEBUG] Arbiter booted
2016-03-24 03:15:08 [11449] [INFO] Listening at: http://0.0.0.0:8000 (11449)
2016-03-24 03:15:08 [11449] [INFO] Using worker: sync
2016-03-24 03:15:08 [11454] [INFO] Booting worker with pid: 11454
2016-03-24 00:15:23 [11454] [DEBUG] GET /ask
Not Found: /ask
2016-03-24 00:15:23 [11454] [DEBUG] GET /ask/
/usr/local/lib/python2.7/dist-packages/django/template/utils.py:37: RemovedInDjango110Warning: You haven't defined a TEMPLATES setting. You must do so before upgrading to Django 1.10. Otherwise Django will be unable to load templates.
  "unable to load templates.", RemovedInDjango110Warning)

2016-03-24 00:15:58 [11454] [DEBUG] POST /ask/
Internal Server Error: /ask/
Traceback (most recent call last):
  File "/usr/local/lib/python2.7/dist-packages/django/core/handlers/base.py", line 149, in get_response
    response = self.process_exception_by_middleware(e, request)
  File "/usr/local/lib/python2.7/dist-packages/django/core/handlers/base.py", line 147, in get_response
    response = wrapped_callback(request, *callback_args, **callback_kwargs)
  File "/home/tayfen/develop/stepic/web_apps/web/ask/qa/views.py", line 66, in ask
    if form.is_valid():
  File "/usr/local/lib/python2.7/dist-packages/django/forms/forms.py", line 161, in is_valid
    return self.is_bound and not self.errors
  File "/usr/local/lib/python2.7/dist-packages/django/forms/forms.py", line 153, in errors
    self.full_clean()
  File "/usr/local/lib/python2.7/dist-packages/django/forms/forms.py", line 363, in full_clean
    self._clean_form()
  File "/usr/local/lib/python2.7/dist-packages/django/forms/forms.py", line 390, in _clean_form
    cleaned_data = self.clean()
  File "/home/tayfen/develop/stepic/web_apps/web/ask/qa/forms.py", line 11, in clean
    if not text.is_valid():
AttributeError: 'unicode' object has no attribute 'is_valid'
2016-03-24 00:17:16 [11454] [DEBUG] POST /ask/
Internal Server Error: /ask/
Traceback (most recent call last):
  File "/usr/local/lib/python2.7/dist-packages/django/core/handlers/base.py", line 149, in get_response
    response = self.process_exception_by_middleware(e, request)
  File "/usr/local/lib/python2.7/dist-packages/django/core/handlers/base.py", line 147, in get_response
    response = wrapped_callback(request, *callback_args, **callback_kwargs)
  File "/home/tayfen/develop/stepic/web_apps/web/ask/qa/views.py", line 66, in ask
    if form.is_valid():
  File "/usr/local/lib/python2.7/dist-packages/django/forms/forms.py", line 161, in is_valid
    return self.is_bound and not self.errors
  File "/usr/local/lib/python2.7/dist-packages/django/forms/forms.py", line 153, in errors
    self.full_clean()
  File "/usr/local/lib/python2.7/dist-packages/django/forms/forms.py", line 363, in full_clean
    self._clean_form()
  File "/usr/local/lib/python2.7/dist-packages/django/forms/forms.py", line 390, in _clean_form
    cleaned_data = self.clean()
  File "/home/tayfen/develop/stepic/web_apps/web/ask/qa/forms.py", line 11, in clean
    if not text.is_valid():
AttributeError: 'unicode' object has no attribute 'is_valid'
2016-03-24 03:19:25 [11470] [INFO] Starting gunicorn 17.5

Error: Already running on PID 11470 (or pid file '/home/tayfen/develop/stepic/web_apps/web/gunicorn.pid' is stale)

2016-03-24 03:19:50 [11482] [INFO] Starting gunicorn 17.5
2016-03-24 03:19:50 [11482] [ERROR] Connection in use: ('0', 8000)
2016-03-24 03:19:50 [11482] [ERROR] Retrying in 1 second.
2016-03-24 03:19:51 [11482] [ERROR] Connection in use: ('0', 8000)
2016-03-24 03:19:51 [11482] [ERROR] Retrying in 1 second.
2016-03-24 03:19:52 [11482] [ERROR] Connection in use: ('0', 8000)
2016-03-24 03:19:52 [11482] [ERROR] Retrying in 1 second.
2016-03-24 03:19:53 [11482] [ERROR] Connection in use: ('0', 8000)
2016-03-24 03:19:53 [11482] [ERROR] Retrying in 1 second.
2016-03-24 03:19:54 [11482] [ERROR] Connection in use: ('0', 8000)
2016-03-24 03:19:54 [11482] [ERROR] Retrying in 1 second.
2016-03-24 03:19:55 [11482] [ERROR] Can't connect to ('0', 8000)
2016-03-24 03:19:58 [11494] [INFO] Starting gunicorn 17.5
2016-03-24 03:19:58 [11494] [ERROR] Connection in use: ('0', 8000)
2016-03-24 03:19:58 [11494] [ERROR] Retrying in 1 second.
2016-03-24 03:19:59 [11494] [ERROR] Connection in use: ('0', 8000)
2016-03-24 03:19:59 [11494] [ERROR] Retrying in 1 second.
2016-03-24 03:20:00 [11494] [ERROR] Connection in use: ('0', 8000)
2016-03-24 03:20:00 [11494] [ERROR] Retrying in 1 second.
2016-03-24 00:20:01 [11454] [INFO] Parent changed, shutting down: <Worker 11454>
2016-03-24 00:20:01 [11454] [INFO] Worker exiting (pid: 11454)
2016-03-24 03:20:01 [11494] [DEBUG] Arbiter booted
2016-03-24 03:20:01 [11494] [INFO] Listening at: http://0.0.0.0:8000 (11494)
2016-03-24 03:20:01 [11494] [INFO] Using worker: sync
2016-03-24 03:20:01 [11501] [INFO] Booting worker with pid: 11501
2016-03-24 00:20:11 [11501] [DEBUG] POST /ask/
2016-03-24 00:20:11 [11501] [DEBUG] GET /question/86
Not Found: /question/86
2016-03-24 00:20:11 [11501] [DEBUG] GET /question/86/
/usr/local/lib/python2.7/dist-packages/django/template/utils.py:37: RemovedInDjango110Warning: You haven't defined a TEMPLATES setting. You must do so before upgrading to Django 1.10. Otherwise Django will be unable to load templates.
  "unable to load templates.", RemovedInDjango110Warning)

2016-03-24 04:16:56 [11494] [INFO] Handling signal: term
Exception SystemExit:  in <module 'threading' from '/usr/lib/python2.7/threading.pyc'> ignored
Error in atexit._run_exitfuncs:
Exception SystemExit: 0 in <module 'threading' from '/usr/lib/python2.7/threading.pyc'> ignored
2016-03-24 04:16:59 [11494] [INFO] Shutting down: Master
2016-03-26 23:07:30 [6833] [INFO] Starting gunicorn 17.5
2016-03-26 23:07:30 [6833] [DEBUG] Arbiter booted
2016-03-26 23:07:30 [6833] [INFO] Listening at: http://0.0.0.0:8000 (6833)
2016-03-26 23:07:30 [6833] [INFO] Using worker: sync
2016-03-26 23:07:30 [6838] [INFO] Booting worker with pid: 6838
2016-03-26 20:09:38 [6838] [DEBUG] GET /
/usr/local/lib/python2.7/dist-packages/django/template/utils.py:37: RemovedInDjango110Warning: You haven't defined a TEMPLATES setting. You must do so before upgrading to Django 1.10. Otherwise Django will be unable to load templates.
  "unable to load templates.", RemovedInDjango110Warning)

2016-03-26 20:25:45 [6838] [DEBUG] GET /
2016-03-26 20:25:46 [6838] [DEBUG] GET /favicon.ico
Not Found: /favicon.ico
2016-03-26 20:27:18 [6838] [DEBUG] GET /ask/
2016-03-26 20:27:28 [6838] [DEBUG] POST /ask/
2016-03-26 20:27:29 [6838] [DEBUG] GET /question/87
Not Found: /question/87
2016-03-26 20:27:29 [6838] [DEBUG] GET /question/87/
2016-03-26 20:28:43 [6838] [DEBUG] GET /question/1/
2016-03-26 20:28:44 [6838] [DEBUG] GET /favicon.ico
Not Found: /favicon.ico
2016-03-26 20:29:03 [6838] [DEBUG] GET /question/12/
2016-03-26 20:29:36 [6838] [DEBUG] GET /answer
Not Found: /answer
2016-03-26 20:29:36 [6838] [DEBUG] GET /answer/
Not Found: /answer/
2016-03-26 20:31:18 [6838] [DEBUG] GET /question/87/
2016-03-26 20:31:19 [6838] [DEBUG] GET /question/87/
2016-03-26 20:31:20 [6838] [DEBUG] GET /question/87/
2016-03-26 20:43:44 [6838] [DEBUG] GET /ask/
2016-03-27 00:02:11 [7525] [INFO] Starting gunicorn 17.5
2016-03-27 00:02:11 [7525] [DEBUG] Arbiter booted
2016-03-27 00:02:11 [7525] [INFO] Listening at: http://0.0.0.0:8000 (7525)
2016-03-27 00:02:11 [7525] [INFO] Using worker: sync
2016-03-27 00:02:11 [7530] [INFO] Booting worker with pid: 7530
2016-03-27 00:02:11 [7530] [ERROR] Exception in worker process:
Traceback (most recent call last):
  File "/usr/lib/python2.7/dist-packages/gunicorn/arbiter.py", line 473, in spawn_worker
    worker.init_process()
  File "/usr/lib/python2.7/dist-packages/gunicorn/workers/base.py", line 100, in init_process
    self.wsgi = self.app.wsgi()
  File "/usr/lib/python2.7/dist-packages/gunicorn/app/base.py", line 115, in wsgi
    self.callable = self.load()
  File "/usr/lib/python2.7/dist-packages/gunicorn/app/wsgiapp.py", line 33, in load
    return util.import_app(self.app_uri)
  File "/usr/lib/python2.7/dist-packages/gunicorn/util.py", line 362, in import_app
    __import__(module)
ImportError: No module named ask.wsgi
Traceback (most recent call last):
  File "/usr/lib/python2.7/dist-packages/gunicorn/arbiter.py", line 473, in spawn_worker
    worker.init_process()
  File "/usr/lib/python2.7/dist-packages/gunicorn/workers/base.py", line 100, in init_process
    self.wsgi = self.app.wsgi()
  File "/usr/lib/python2.7/dist-packages/gunicorn/app/base.py", line 115, in wsgi
    self.callable = self.load()
  File "/usr/lib/python2.7/dist-packages/gunicorn/app/wsgiapp.py", line 33, in load
    return util.import_app(self.app_uri)
  File "/usr/lib/python2.7/dist-packages/gunicorn/util.py", line 362, in import_app
    __import__(module)
ImportError: No module named ask.wsgi
2016-03-27 00:02:11 [7530] [INFO] Worker exiting (pid: 7530)
2016-03-27 00:02:11 [7525] [INFO] Shutting down: Master
2016-03-27 00:02:11 [7525] [INFO] Reason: Worker failed to boot.
2016-03-27 00:02:53 [7544] [INFO] Starting gunicorn 17.5
2016-03-27 00:02:53 [7544] [DEBUG] Arbiter booted
2016-03-27 00:02:53 [7544] [INFO] Listening at: http://0.0.0.0:8000 (7544)
2016-03-27 00:02:53 [7544] [INFO] Using worker: sync
2016-03-27 00:02:53 [7549] [INFO] Booting worker with pid: 7549
2016-03-26 21:03:31 [7549] [DEBUG] GET /ask/
Internal Server Error: /ask/
Traceback (most recent call last):
  File "/usr/local/lib/python2.7/dist-packages/django/core/handlers/base.py", line 134, in get_response
    resolver_match = resolver.resolve(request.path_info)
  File "/usr/local/lib/python2.7/dist-packages/django/core/urlresolvers.py", line 374, in resolve
    for pattern in self.url_patterns:
  File "/usr/local/lib/python2.7/dist-packages/django/utils/functional.py", line 33, in __get__
    res = instance.__dict__[self.name] = self.func(instance)
  File "/usr/local/lib/python2.7/dist-packages/django/core/urlresolvers.py", line 417, in url_patterns
    patterns = getattr(self.urlconf_module, "urlpatterns", self.urlconf_module)
  File "/usr/local/lib/python2.7/dist-packages/django/utils/functional.py", line 33, in __get__
    res = instance.__dict__[self.name] = self.func(instance)
  File "/usr/local/lib/python2.7/dist-packages/django/core/urlresolvers.py", line 410, in urlconf_module
    return import_module(self.urlconf_name)
  File "/usr/lib/python2.7/importlib/__init__.py", line 37, in import_module
    __import__(name)
  File "/home/tayfen/develop/stepic/web_apps/web/ask/ask/urls.py", line 4, in <module>
    from qa.views import *
  File "/home/tayfen/develop/stepic/web_apps/web/ask/qa/views.py", line 39, in <module>
    @csrf_protect
NameError: name 'csrf_protect' is not defined
2016-03-26 21:03:32 [7549] [DEBUG] GET /favicon.ico
Internal Server Error: /favicon.ico
Traceback (most recent call last):
  File "/usr/local/lib/python2.7/dist-packages/django/core/handlers/base.py", line 134, in get_response
    resolver_match = resolver.resolve(request.path_info)
  File "/usr/local/lib/python2.7/dist-packages/django/core/urlresolvers.py", line 374, in resolve
    for pattern in self.url_patterns:
  File "/usr/local/lib/python2.7/dist-packages/django/utils/functional.py", line 33, in __get__
    res = instance.__dict__[self.name] = self.func(instance)
  File "/usr/local/lib/python2.7/dist-packages/django/core/urlresolvers.py", line 417, in url_patterns
    patterns = getattr(self.urlconf_module, "urlpatterns", self.urlconf_module)
  File "/usr/local/lib/python2.7/dist-packages/django/utils/functional.py", line 33, in __get__
    res = instance.__dict__[self.name] = self.func(instance)
  File "/usr/local/lib/python2.7/dist-packages/django/core/urlresolvers.py", line 410, in urlconf_module
    return import_module(self.urlconf_name)
  File "/usr/lib/python2.7/importlib/__init__.py", line 37, in import_module
    __import__(name)
  File "/home/tayfen/develop/stepic/web_apps/web/ask/ask/urls.py", line 4, in <module>
    from qa.views import *
  File "/home/tayfen/develop/stepic/web_apps/web/ask/qa/views.py", line 39, in <module>
    @csrf_protect
NameError: name 'csrf_protect' is not defined
2016-03-27 00:04:22 [7588] [INFO] Starting gunicorn 17.5

Error: Already running on PID 7588 (or pid file '/home/tayfen/develop/stepic/web_apps/web/gunicorn.pid' is stale)

2016-03-26 21:04:28 [7549] [DEBUG] GET /ask/
Internal Server Error: /ask/
Traceback (most recent call last):
  File "/usr/local/lib/python2.7/dist-packages/django/core/handlers/base.py", line 134, in get_response
    resolver_match = resolver.resolve(request.path_info)
  File "/usr/local/lib/python2.7/dist-packages/django/core/urlresolvers.py", line 374, in resolve
    for pattern in self.url_patterns:
  File "/usr/local/lib/python2.7/dist-packages/django/utils/functional.py", line 33, in __get__
    res = instance.__dict__[self.name] = self.func(instance)
  File "/usr/local/lib/python2.7/dist-packages/django/core/urlresolvers.py", line 417, in url_patterns
    patterns = getattr(self.urlconf_module, "urlpatterns", self.urlconf_module)
  File "/usr/local/lib/python2.7/dist-packages/django/utils/functional.py", line 33, in __get__
    res = instance.__dict__[self.name] = self.func(instance)
  File "/usr/local/lib/python2.7/dist-packages/django/core/urlresolvers.py", line 410, in urlconf_module
    return import_module(self.urlconf_name)
  File "/usr/lib/python2.7/importlib/__init__.py", line 37, in import_module
    __import__(name)
  File "/home/tayfen/develop/stepic/web_apps/web/ask/ask/urls.py", line 4, in <module>
    from qa.views import *
  File "/home/tayfen/develop/stepic/web_apps/web/ask/qa/views.py", line 39, in <module>
    @csrf_protect
NameError: name 'csrf_protect' is not defined
2016-03-26 21:04:28 [7549] [DEBUG] GET /favicon.ico
Internal Server Error: /favicon.ico
Traceback (most recent call last):
  File "/usr/local/lib/python2.7/dist-packages/django/core/handlers/base.py", line 134, in get_response
    resolver_match = resolver.resolve(request.path_info)
  File "/usr/local/lib/python2.7/dist-packages/django/core/urlresolvers.py", line 374, in resolve
    for pattern in self.url_patterns:
  File "/usr/local/lib/python2.7/dist-packages/django/utils/functional.py", line 33, in __get__
    res = instance.__dict__[self.name] = self.func(instance)
  File "/usr/local/lib/python2.7/dist-packages/django/core/urlresolvers.py", line 417, in url_patterns
    patterns = getattr(self.urlconf_module, "urlpatterns", self.urlconf_module)
  File "/usr/local/lib/python2.7/dist-packages/django/utils/functional.py", line 33, in __get__
    res = instance.__dict__[self.name] = self.func(instance)
  File "/usr/local/lib/python2.7/dist-packages/django/core/urlresolvers.py", line 410, in urlconf_module
    return import_module(self.urlconf_name)
  File "/usr/lib/python2.7/importlib/__init__.py", line 37, in import_module
    __import__(name)
  File "/home/tayfen/develop/stepic/web_apps/web/ask/ask/urls.py", line 4, in <module>
    from qa.views import *
  File "/home/tayfen/develop/stepic/web_apps/web/ask/qa/views.py", line 39, in <module>
    @csrf_protect
NameError: name 'csrf_protect' is not defined
2016-03-26 21:04:30 [7549] [DEBUG] GET /ask/
Internal Server Error: /ask/
Traceback (most recent call last):
  File "/usr/local/lib/python2.7/dist-packages/django/core/handlers/base.py", line 134, in get_response
    resolver_match = resolver.resolve(request.path_info)
  File "/usr/local/lib/python2.7/dist-packages/django/core/urlresolvers.py", line 374, in resolve
    for pattern in self.url_patterns:
  File "/usr/local/lib/python2.7/dist-packages/django/utils/functional.py", line 33, in __get__
    res = instance.__dict__[self.name] = self.func(instance)
  File "/usr/local/lib/python2.7/dist-packages/django/core/urlresolvers.py", line 417, in url_patterns
    patterns = getattr(self.urlconf_module, "urlpatterns", self.urlconf_module)
  File "/usr/local/lib/python2.7/dist-packages/django/utils/functional.py", line 33, in __get__
    res = instance.__dict__[self.name] = self.func(instance)
  File "/usr/local/lib/python2.7/dist-packages/django/core/urlresolvers.py", line 410, in urlconf_module
    return import_module(self.urlconf_name)
  File "/usr/lib/python2.7/importlib/__init__.py", line 37, in import_module
    __import__(name)
  File "/home/tayfen/develop/stepic/web_apps/web/ask/ask/urls.py", line 4, in <module>
    from qa.views import *
  File "/home/tayfen/develop/stepic/web_apps/web/ask/qa/views.py", line 39, in <module>
    @csrf_protect
NameError: name 'csrf_protect' is not defined
2016-03-26 21:04:30 [7549] [DEBUG] GET /favicon.ico
Internal Server Error: /favicon.ico
Traceback (most recent call last):
  File "/usr/local/lib/python2.7/dist-packages/django/core/handlers/base.py", line 134, in get_response
    resolver_match = resolver.resolve(request.path_info)
  File "/usr/local/lib/python2.7/dist-packages/django/core/urlresolvers.py", line 374, in resolve
    for pattern in self.url_patterns:
  File "/usr/local/lib/python2.7/dist-packages/django/utils/functional.py", line 33, in __get__
    res = instance.__dict__[self.name] = self.func(instance)
  File "/usr/local/lib/python2.7/dist-packages/django/core/urlresolvers.py", line 417, in url_patterns
    patterns = getattr(self.urlconf_module, "urlpatterns", self.urlconf_module)
  File "/usr/local/lib/python2.7/dist-packages/django/utils/functional.py", line 33, in __get__
    res = instance.__dict__[self.name] = self.func(instance)
  File "/usr/local/lib/python2.7/dist-packages/django/core/urlresolvers.py", line 410, in urlconf_module
    return import_module(self.urlconf_name)
  File "/usr/lib/python2.7/importlib/__init__.py", line 37, in import_module
    __import__(name)
  File "/home/tayfen/develop/stepic/web_apps/web/ask/ask/urls.py", line 4, in <module>
    from qa.views import *
  File "/home/tayfen/develop/stepic/web_apps/web/ask/qa/views.py", line 39, in <module>
    @csrf_protect
NameError: name 'csrf_protect' is not defined
2016-03-26 21:04:32 [7549] [DEBUG] GET /ask/
Internal Server Error: /ask/
Traceback (most recent call last):
  File "/usr/local/lib/python2.7/dist-packages/django/core/handlers/base.py", line 134, in get_response
    resolver_match = resolver.resolve(request.path_info)
  File "/usr/local/lib/python2.7/dist-packages/django/core/urlresolvers.py", line 374, in resolve
    for pattern in self.url_patterns:
  File "/usr/local/lib/python2.7/dist-packages/django/utils/functional.py", line 33, in __get__
    res = instance.__dict__[self.name] = self.func(instance)
  File "/usr/local/lib/python2.7/dist-packages/django/core/urlresolvers.py", line 417, in url_patterns
    patterns = getattr(self.urlconf_module, "urlpatterns", self.urlconf_module)
  File "/usr/local/lib/python2.7/dist-packages/django/utils/functional.py", line 33, in __get__
    res = instance.__dict__[self.name] = self.func(instance)
  File "/usr/local/lib/python2.7/dist-packages/django/core/urlresolvers.py", line 410, in urlconf_module
    return import_module(self.urlconf_name)
  File "/usr/lib/python2.7/importlib/__init__.py", line 37, in import_module
    __import__(name)
  File "/home/tayfen/develop/stepic/web_apps/web/ask/ask/urls.py", line 4, in <module>
    from qa.views import *
  File "/home/tayfen/develop/stepic/web_apps/web/ask/qa/views.py", line 39, in <module>
    @csrf_protect
NameError: name 'csrf_protect' is not defined
2016-03-26 21:04:32 [7549] [DEBUG] GET /favicon.ico
Internal Server Error: /favicon.ico
Traceback (most recent call last):
  File "/usr/local/lib/python2.7/dist-packages/django/core/handlers/base.py", line 134, in get_response
    resolver_match = resolver.resolve(request.path_info)
  File "/usr/local/lib/python2.7/dist-packages/django/core/urlresolvers.py", line 374, in resolve
    for pattern in self.url_patterns:
  File "/usr/local/lib/python2.7/dist-packages/django/utils/functional.py", line 33, in __get__
    res = instance.__dict__[self.name] = self.func(instance)
  File "/usr/local/lib/python2.7/dist-packages/django/core/urlresolvers.py", line 417, in url_patterns
    patterns = getattr(self.urlconf_module, "urlpatterns", self.urlconf_module)
  File "/usr/local/lib/python2.7/dist-packages/django/utils/functional.py", line 33, in __get__
    res = instance.__dict__[self.name] = self.func(instance)
  File "/usr/local/lib/python2.7/dist-packages/django/core/urlresolvers.py", line 410, in urlconf_module
    return import_module(self.urlconf_name)
  File "/usr/lib/python2.7/importlib/__init__.py", line 37, in import_module
    __import__(name)
  File "/home/tayfen/develop/stepic/web_apps/web/ask/ask/urls.py", line 4, in <module>
    from qa.views import *
  File "/home/tayfen/develop/stepic/web_apps/web/ask/qa/views.py", line 39, in <module>
    @csrf_protect
NameError: name 'csrf_protect' is not defined
2016-03-26 21:04:37 [7549] [DEBUG] GET /ask/
Internal Server Error: /ask/
Traceback (most recent call last):
  File "/usr/local/lib/python2.7/dist-packages/django/core/handlers/base.py", line 134, in get_response
    resolver_match = resolver.resolve(request.path_info)
  File "/usr/local/lib/python2.7/dist-packages/django/core/urlresolvers.py", line 374, in resolve
    for pattern in self.url_patterns:
  File "/usr/local/lib/python2.7/dist-packages/django/utils/functional.py", line 33, in __get__
    res = instance.__dict__[self.name] = self.func(instance)
  File "/usr/local/lib/python2.7/dist-packages/django/core/urlresolvers.py", line 417, in url_patterns
    patterns = getattr(self.urlconf_module, "urlpatterns", self.urlconf_module)
  File "/usr/local/lib/python2.7/dist-packages/django/utils/functional.py", line 33, in __get__
    res = instance.__dict__[self.name] = self.func(instance)
  File "/usr/local/lib/python2.7/dist-packages/django/core/urlresolvers.py", line 410, in urlconf_module
    return import_module(self.urlconf_name)
  File "/usr/lib/python2.7/importlib/__init__.py", line 37, in import_module
    __import__(name)
  File "/home/tayfen/develop/stepic/web_apps/web/ask/ask/urls.py", line 4, in <module>
    from qa.views import *
  File "/home/tayfen/develop/stepic/web_apps/web/ask/qa/views.py", line 39, in <module>
    @csrf_protect
NameError: name 'csrf_protect' is not defined
2016-03-26 21:04:38 [7549] [DEBUG] GET /favicon.ico
Internal Server Error: /favicon.ico
Traceback (most recent call last):
  File "/usr/local/lib/python2.7/dist-packages/django/core/handlers/base.py", line 134, in get_response
    resolver_match = resolver.resolve(request.path_info)
  File "/usr/local/lib/python2.7/dist-packages/django/core/urlresolvers.py", line 374, in resolve
    for pattern in self.url_patterns:
  File "/usr/local/lib/python2.7/dist-packages/django/utils/functional.py", line 33, in __get__
    res = instance.__dict__[self.name] = self.func(instance)
  File "/usr/local/lib/python2.7/dist-packages/django/core/urlresolvers.py", line 417, in url_patterns
    patterns = getattr(self.urlconf_module, "urlpatterns", self.urlconf_module)
  File "/usr/local/lib/python2.7/dist-packages/django/utils/functional.py", line 33, in __get__
    res = instance.__dict__[self.name] = self.func(instance)
  File "/usr/local/lib/python2.7/dist-packages/django/core/urlresolvers.py", line 410, in urlconf_module
    return import_module(self.urlconf_name)
  File "/usr/lib/python2.7/importlib/__init__.py", line 37, in import_module
    __import__(name)
  File "/home/tayfen/develop/stepic/web_apps/web/ask/ask/urls.py", line 4, in <module>
    from qa.views import *
  File "/home/tayfen/develop/stepic/web_apps/web/ask/qa/views.py", line 39, in <module>
    @csrf_protect
NameError: name 'csrf_protect' is not defined
2016-03-26 21:04:38 [7549] [DEBUG] GET /ask/
Internal Server Error: /ask/
Traceback (most recent call last):
  File "/usr/local/lib/python2.7/dist-packages/django/core/handlers/base.py", line 134, in get_response
    resolver_match = resolver.resolve(request.path_info)
  File "/usr/local/lib/python2.7/dist-packages/django/core/urlresolvers.py", line 374, in resolve
    for pattern in self.url_patterns:
  File "/usr/local/lib/python2.7/dist-packages/django/utils/functional.py", line 33, in __get__
    res = instance.__dict__[self.name] = self.func(instance)
  File "/usr/local/lib/python2.7/dist-packages/django/core/urlresolvers.py", line 417, in url_patterns
    patterns = getattr(self.urlconf_module, "urlpatterns", self.urlconf_module)
  File "/usr/local/lib/python2.7/dist-packages/django/utils/functional.py", line 33, in __get__
    res = instance.__dict__[self.name] = self.func(instance)
  File "/usr/local/lib/python2.7/dist-packages/django/core/urlresolvers.py", line 410, in urlconf_module
    return import_module(self.urlconf_name)
  File "/usr/lib/python2.7/importlib/__init__.py", line 37, in import_module
    __import__(name)
  File "/home/tayfen/develop/stepic/web_apps/web/ask/ask/urls.py", line 4, in <module>
    from qa.views import *
  File "/home/tayfen/develop/stepic/web_apps/web/ask/qa/views.py", line 39, in <module>
    @csrf_protect
NameError: name 'csrf_protect' is not defined
2016-03-26 21:04:38 [7549] [DEBUG] GET /favicon.ico
Internal Server Error: /favicon.ico
Traceback (most recent call last):
  File "/usr/local/lib/python2.7/dist-packages/django/core/handlers/base.py", line 134, in get_response
    resolver_match = resolver.resolve(request.path_info)
  File "/usr/local/lib/python2.7/dist-packages/django/core/urlresolvers.py", line 374, in resolve
    for pattern in self.url_patterns:
  File "/usr/local/lib/python2.7/dist-packages/django/utils/functional.py", line 33, in __get__
    res = instance.__dict__[self.name] = self.func(instance)
  File "/usr/local/lib/python2.7/dist-packages/django/core/urlresolvers.py", line 417, in url_patterns
    patterns = getattr(self.urlconf_module, "urlpatterns", self.urlconf_module)
  File "/usr/local/lib/python2.7/dist-packages/django/utils/functional.py", line 33, in __get__
    res = instance.__dict__[self.name] = self.func(instance)
  File "/usr/local/lib/python2.7/dist-packages/django/core/urlresolvers.py", line 410, in urlconf_module
    return import_module(self.urlconf_name)
  File "/usr/lib/python2.7/importlib/__init__.py", line 37, in import_module
    __import__(name)
  File "/home/tayfen/develop/stepic/web_apps/web/ask/ask/urls.py", line 4, in <module>
    from qa.views import *
  File "/home/tayfen/develop/stepic/web_apps/web/ask/qa/views.py", line 39, in <module>
    @csrf_protect
NameError: name 'csrf_protect' is not defined
2016-03-27 00:05:10 [7613] [INFO] Starting gunicorn 17.5
2016-03-27 00:05:10 [7613] [DEBUG] Arbiter booted
2016-03-27 00:05:10 [7613] [INFO] Listening at: http://0.0.0.0:8000 (7613)
2016-03-27 00:05:10 [7613] [INFO] Using worker: sync
2016-03-27 00:05:10 [7618] [INFO] Booting worker with pid: 7618
2016-03-26 21:05:12 [7618] [DEBUG] GET /ask/
Internal Server Error: /ask/
Traceback (most recent call last):
  File "/usr/local/lib/python2.7/dist-packages/django/core/handlers/base.py", line 134, in get_response
    resolver_match = resolver.resolve(request.path_info)
  File "/usr/local/lib/python2.7/dist-packages/django/core/urlresolvers.py", line 374, in resolve
    for pattern in self.url_patterns:
  File "/usr/local/lib/python2.7/dist-packages/django/utils/functional.py", line 33, in __get__
    res = instance.__dict__[self.name] = self.func(instance)
  File "/usr/local/lib/python2.7/dist-packages/django/core/urlresolvers.py", line 417, in url_patterns
    patterns = getattr(self.urlconf_module, "urlpatterns", self.urlconf_module)
  File "/usr/local/lib/python2.7/dist-packages/django/utils/functional.py", line 33, in __get__
    res = instance.__dict__[self.name] = self.func(instance)
  File "/usr/local/lib/python2.7/dist-packages/django/core/urlresolvers.py", line 410, in urlconf_module
    return import_module(self.urlconf_name)
  File "/usr/lib/python2.7/importlib/__init__.py", line 37, in import_module
    __import__(name)
  File "/home/tayfen/develop/stepic/web_apps/web/ask/ask/urls.py", line 4, in <module>
    from qa.views import *
  File "/home/tayfen/develop/stepic/web_apps/web/ask/qa/views.py", line 39, in <module>
    @csrf_protect
NameError: name 'csrf_protect' is not defined
2016-03-26 21:05:12 [7618] [DEBUG] GET /favicon.ico
Internal Server Error: /favicon.ico
Traceback (most recent call last):
  File "/usr/local/lib/python2.7/dist-packages/django/core/handlers/base.py", line 134, in get_response
    resolver_match = resolver.resolve(request.path_info)
  File "/usr/local/lib/python2.7/dist-packages/django/core/urlresolvers.py", line 374, in resolve
    for pattern in self.url_patterns:
  File "/usr/local/lib/python2.7/dist-packages/django/utils/functional.py", line 33, in __get__
    res = instance.__dict__[self.name] = self.func(instance)
  File "/usr/local/lib/python2.7/dist-packages/django/core/urlresolvers.py", line 417, in url_patterns
    patterns = getattr(self.urlconf_module, "urlpatterns", self.urlconf_module)
  File "/usr/local/lib/python2.7/dist-packages/django/utils/functional.py", line 33, in __get__
    res = instance.__dict__[self.name] = self.func(instance)
  File "/usr/local/lib/python2.7/dist-packages/django/core/urlresolvers.py", line 410, in urlconf_module
    return import_module(self.urlconf_name)
  File "/usr/lib/python2.7/importlib/__init__.py", line 37, in import_module
    __import__(name)
  File "/home/tayfen/develop/stepic/web_apps/web/ask/ask/urls.py", line 4, in <module>
    from qa.views import *
  File "/home/tayfen/develop/stepic/web_apps/web/ask/qa/views.py", line 39, in <module>
    @csrf_protect
NameError: name 'csrf_protect' is not defined
2016-03-26 21:05:12 [7618] [DEBUG] GET /ask/
Internal Server Error: /ask/
Traceback (most recent call last):
  File "/usr/local/lib/python2.7/dist-packages/django/core/handlers/base.py", line 134, in get_response
    resolver_match = resolver.resolve(request.path_info)
  File "/usr/local/lib/python2.7/dist-packages/django/core/urlresolvers.py", line 374, in resolve
    for pattern in self.url_patterns:
  File "/usr/local/lib/python2.7/dist-packages/django/utils/functional.py", line 33, in __get__
    res = instance.__dict__[self.name] = self.func(instance)
  File "/usr/local/lib/python2.7/dist-packages/django/core/urlresolvers.py", line 417, in url_patterns
    patterns = getattr(self.urlconf_module, "urlpatterns", self.urlconf_module)
  File "/usr/local/lib/python2.7/dist-packages/django/utils/functional.py", line 33, in __get__
    res = instance.__dict__[self.name] = self.func(instance)
  File "/usr/local/lib/python2.7/dist-packages/django/core/urlresolvers.py", line 410, in urlconf_module
    return import_module(self.urlconf_name)
  File "/usr/lib/python2.7/importlib/__init__.py", line 37, in import_module
    __import__(name)
  File "/home/tayfen/develop/stepic/web_apps/web/ask/ask/urls.py", line 4, in <module>
    from qa.views import *
  File "/home/tayfen/develop/stepic/web_apps/web/ask/qa/views.py", line 39, in <module>
    @csrf_protect
NameError: name 'csrf_protect' is not defined
2016-03-26 21:05:13 [7618] [DEBUG] GET /favicon.ico
Internal Server Error: /favicon.ico
Traceback (most recent call last):
  File "/usr/local/lib/python2.7/dist-packages/django/core/handlers/base.py", line 134, in get_response
    resolver_match = resolver.resolve(request.path_info)
  File "/usr/local/lib/python2.7/dist-packages/django/core/urlresolvers.py", line 374, in resolve
    for pattern in self.url_patterns:
  File "/usr/local/lib/python2.7/dist-packages/django/utils/functional.py", line 33, in __get__
    res = instance.__dict__[self.name] = self.func(instance)
  File "/usr/local/lib/python2.7/dist-packages/django/core/urlresolvers.py", line 417, in url_patterns
    patterns = getattr(self.urlconf_module, "urlpatterns", self.urlconf_module)
  File "/usr/local/lib/python2.7/dist-packages/django/utils/functional.py", line 33, in __get__
    res = instance.__dict__[self.name] = self.func(instance)
  File "/usr/local/lib/python2.7/dist-packages/django/core/urlresolvers.py", line 410, in urlconf_module
    return import_module(self.urlconf_name)
  File "/usr/lib/python2.7/importlib/__init__.py", line 37, in import_module
    __import__(name)
  File "/home/tayfen/develop/stepic/web_apps/web/ask/ask/urls.py", line 4, in <module>
    from qa.views import *
  File "/home/tayfen/develop/stepic/web_apps/web/ask/qa/views.py", line 39, in <module>
    @csrf_protect
NameError: name 'csrf_protect' is not defined
2016-03-26 21:05:13 [7618] [DEBUG] GET /ask/
Internal Server Error: /ask/
Traceback (most recent call last):
  File "/usr/local/lib/python2.7/dist-packages/django/core/handlers/base.py", line 134, in get_response
    resolver_match = resolver.resolve(request.path_info)
  File "/usr/local/lib/python2.7/dist-packages/django/core/urlresolvers.py", line 374, in resolve
    for pattern in self.url_patterns:
  File "/usr/local/lib/python2.7/dist-packages/django/utils/functional.py", line 33, in __get__
    res = instance.__dict__[self.name] = self.func(instance)
  File "/usr/local/lib/python2.7/dist-packages/django/core/urlresolvers.py", line 417, in url_patterns
    patterns = getattr(self.urlconf_module, "urlpatterns", self.urlconf_module)
  File "/usr/local/lib/python2.7/dist-packages/django/utils/functional.py", line 33, in __get__
    res = instance.__dict__[self.name] = self.func(instance)
  File "/usr/local/lib/python2.7/dist-packages/django/core/urlresolvers.py", line 410, in urlconf_module
    return import_module(self.urlconf_name)
  File "/usr/lib/python2.7/importlib/__init__.py", line 37, in import_module
    __import__(name)
  File "/home/tayfen/develop/stepic/web_apps/web/ask/ask/urls.py", line 4, in <module>
    from qa.views import *
  File "/home/tayfen/develop/stepic/web_apps/web/ask/qa/views.py", line 39, in <module>
    @csrf_protect
NameError: name 'csrf_protect' is not defined
2016-03-26 21:05:13 [7618] [DEBUG] GET /favicon.ico
Internal Server Error: /favicon.ico
Traceback (most recent call last):
  File "/usr/local/lib/python2.7/dist-packages/django/core/handlers/base.py", line 134, in get_response
    resolver_match = resolver.resolve(request.path_info)
  File "/usr/local/lib/python2.7/dist-packages/django/core/urlresolvers.py", line 374, in resolve
    for pattern in self.url_patterns:
  File "/usr/local/lib/python2.7/dist-packages/django/utils/functional.py", line 33, in __get__
    res = instance.__dict__[self.name] = self.func(instance)
  File "/usr/local/lib/python2.7/dist-packages/django/core/urlresolvers.py", line 417, in url_patterns
    patterns = getattr(self.urlconf_module, "urlpatterns", self.urlconf_module)
  File "/usr/local/lib/python2.7/dist-packages/django/utils/functional.py", line 33, in __get__
    res = instance.__dict__[self.name] = self.func(instance)
  File "/usr/local/lib/python2.7/dist-packages/django/core/urlresolvers.py", line 410, in urlconf_module
    return import_module(self.urlconf_name)
  File "/usr/lib/python2.7/importlib/__init__.py", line 37, in import_module
    __import__(name)
  File "/home/tayfen/develop/stepic/web_apps/web/ask/ask/urls.py", line 4, in <module>
    from qa.views import *
  File "/home/tayfen/develop/stepic/web_apps/web/ask/qa/views.py", line 39, in <module>
    @csrf_protect
NameError: name 'csrf_protect' is not defined
2016-03-26 21:05:13 [7618] [DEBUG] GET /ask/
Internal Server Error: /ask/
Traceback (most recent call last):
  File "/usr/local/lib/python2.7/dist-packages/django/core/handlers/base.py", line 134, in get_response
    resolver_match = resolver.resolve(request.path_info)
  File "/usr/local/lib/python2.7/dist-packages/django/core/urlresolvers.py", line 374, in resolve
    for pattern in self.url_patterns:
  File "/usr/local/lib/python2.7/dist-packages/django/utils/functional.py", line 33, in __get__
    res = instance.__dict__[self.name] = self.func(instance)
  File "/usr/local/lib/python2.7/dist-packages/django/core/urlresolvers.py", line 417, in url_patterns
    patterns = getattr(self.urlconf_module, "urlpatterns", self.urlconf_module)
  File "/usr/local/lib/python2.7/dist-packages/django/utils/functional.py", line 33, in __get__
    res = instance.__dict__[self.name] = self.func(instance)
  File "/usr/local/lib/python2.7/dist-packages/django/core/urlresolvers.py", line 410, in urlconf_module
    return import_module(self.urlconf_name)
  File "/usr/lib/python2.7/importlib/__init__.py", line 37, in import_module
    __import__(name)
  File "/home/tayfen/develop/stepic/web_apps/web/ask/ask/urls.py", line 4, in <module>
    from qa.views import *
  File "/home/tayfen/develop/stepic/web_apps/web/ask/qa/views.py", line 39, in <module>
    @csrf_protect
NameError: name 'csrf_protect' is not defined
2016-03-26 21:05:14 [7618] [DEBUG] Ignoring EPIPE
2016-03-26 21:05:14 [7618] [DEBUG] GET /ask/
Internal Server Error: /ask/
Traceback (most recent call last):
  File "/usr/local/lib/python2.7/dist-packages/django/core/handlers/base.py", line 134, in get_response
    resolver_match = resolver.resolve(request.path_info)
  File "/usr/local/lib/python2.7/dist-packages/django/core/urlresolvers.py", line 374, in resolve
    for pattern in self.url_patterns:
  File "/usr/local/lib/python2.7/dist-packages/django/utils/functional.py", line 33, in __get__
    res = instance.__dict__[self.name] = self.func(instance)
  File "/usr/local/lib/python2.7/dist-packages/django/core/urlresolvers.py", line 417, in url_patterns
    patterns = getattr(self.urlconf_module, "urlpatterns", self.urlconf_module)
  File "/usr/local/lib/python2.7/dist-packages/django/utils/functional.py", line 33, in __get__
    res = instance.__dict__[self.name] = self.func(instance)
  File "/usr/local/lib/python2.7/dist-packages/django/core/urlresolvers.py", line 410, in urlconf_module
    return import_module(self.urlconf_name)
  File "/usr/lib/python2.7/importlib/__init__.py", line 37, in import_module
    __import__(name)
  File "/home/tayfen/develop/stepic/web_apps/web/ask/ask/urls.py", line 4, in <module>
    from qa.views import *
  File "/home/tayfen/develop/stepic/web_apps/web/ask/qa/views.py", line 39, in <module>
    @csrf_protect
NameError: name 'csrf_protect' is not defined
2016-03-26 21:05:14 [7618] [DEBUG] Ignoring EPIPE
2016-03-26 21:05:14 [7618] [DEBUG] GET /ask/
Internal Server Error: /ask/
Traceback (most recent call last):
  File "/usr/local/lib/python2.7/dist-packages/django/core/handlers/base.py", line 134, in get_response
    resolver_match = resolver.resolve(request.path_info)
  File "/usr/local/lib/python2.7/dist-packages/django/core/urlresolvers.py", line 374, in resolve
    for pattern in self.url_patterns:
  File "/usr/local/lib/python2.7/dist-packages/django/utils/functional.py", line 33, in __get__
    res = instance.__dict__[self.name] = self.func(instance)
  File "/usr/local/lib/python2.7/dist-packages/django/core/urlresolvers.py", line 417, in url_patterns
    patterns = getattr(self.urlconf_module, "urlpatterns", self.urlconf_module)
  File "/usr/local/lib/python2.7/dist-packages/django/utils/functional.py", line 33, in __get__
    res = instance.__dict__[self.name] = self.func(instance)
  File "/usr/local/lib/python2.7/dist-packages/django/core/urlresolvers.py", line 410, in urlconf_module
    return import_module(self.urlconf_name)
  File "/usr/lib/python2.7/importlib/__init__.py", line 37, in import_module
    __import__(name)
  File "/home/tayfen/develop/stepic/web_apps/web/ask/ask/urls.py", line 4, in <module>
    from qa.views import *
  File "/home/tayfen/develop/stepic/web_apps/web/ask/qa/views.py", line 39, in <module>
    @csrf_protect
NameError: name 'csrf_protect' is not defined
2016-03-26 21:05:14 [7618] [DEBUG] GET /favicon.ico
Internal Server Error: /favicon.ico
Traceback (most recent call last):
  File "/usr/local/lib/python2.7/dist-packages/django/core/handlers/base.py", line 134, in get_response
    resolver_match = resolver.resolve(request.path_info)
  File "/usr/local/lib/python2.7/dist-packages/django/core/urlresolvers.py", line 374, in resolve
    for pattern in self.url_patterns:
  File "/usr/local/lib/python2.7/dist-packages/django/utils/functional.py", line 33, in __get__
    res = instance.__dict__[self.name] = self.func(instance)
  File "/usr/local/lib/python2.7/dist-packages/django/core/urlresolvers.py", line 417, in url_patterns
    patterns = getattr(self.urlconf_module, "urlpatterns", self.urlconf_module)
  File "/usr/local/lib/python2.7/dist-packages/django/utils/functional.py", line 33, in __get__
    res = instance.__dict__[self.name] = self.func(instance)
  File "/usr/local/lib/python2.7/dist-packages/django/core/urlresolvers.py", line 410, in urlconf_module
    return import_module(self.urlconf_name)
  File "/usr/lib/python2.7/importlib/__init__.py", line 37, in import_module
    __import__(name)
  File "/home/tayfen/develop/stepic/web_apps/web/ask/ask/urls.py", line 4, in <module>
    from qa.views import *
  File "/home/tayfen/develop/stepic/web_apps/web/ask/qa/views.py", line 39, in <module>
    @csrf_protect
NameError: name 'csrf_protect' is not defined
2016-03-26 21:05:14 [7618] [DEBUG] GET /ask/
Internal Server Error: /ask/
Traceback (most recent call last):
  File "/usr/local/lib/python2.7/dist-packages/django/core/handlers/base.py", line 134, in get_response
    resolver_match = resolver.resolve(request.path_info)
  File "/usr/local/lib/python2.7/dist-packages/django/core/urlresolvers.py", line 374, in resolve
    for pattern in self.url_patterns:
  File "/usr/local/lib/python2.7/dist-packages/django/utils/functional.py", line 33, in __get__
    res = instance.__dict__[self.name] = self.func(instance)
  File "/usr/local/lib/python2.7/dist-packages/django/core/urlresolvers.py", line 417, in url_patterns
    patterns = getattr(self.urlconf_module, "urlpatterns", self.urlconf_module)
  File "/usr/local/lib/python2.7/dist-packages/django/utils/functional.py", line 33, in __get__
    res = instance.__dict__[self.name] = self.func(instance)
  File "/usr/local/lib/python2.7/dist-packages/django/core/urlresolvers.py", line 410, in urlconf_module
    return import_module(self.urlconf_name)
  File "/usr/lib/python2.7/importlib/__init__.py", line 37, in import_module
    __import__(name)
  File "/home/tayfen/develop/stepic/web_apps/web/ask/ask/urls.py", line 4, in <module>
    from qa.views import *
  File "/home/tayfen/develop/stepic/web_apps/web/ask/qa/views.py", line 39, in <module>
    @csrf_protect
NameError: name 'csrf_protect' is not defined
2016-03-26 21:05:14 [7618] [DEBUG] Ignoring EPIPE
2016-03-26 21:05:14 [7618] [DEBUG] GET /ask/
Internal Server Error: /ask/
Traceback (most recent call last):
  File "/usr/local/lib/python2.7/dist-packages/django/core/handlers/base.py", line 134, in get_response
    resolver_match = resolver.resolve(request.path_info)
  File "/usr/local/lib/python2.7/dist-packages/django/core/urlresolvers.py", line 374, in resolve
    for pattern in self.url_patterns:
  File "/usr/local/lib/python2.7/dist-packages/django/utils/functional.py", line 33, in __get__
    res = instance.__dict__[self.name] = self.func(instance)
  File "/usr/local/lib/python2.7/dist-packages/django/core/urlresolvers.py", line 417, in url_patterns
    patterns = getattr(self.urlconf_module, "urlpatterns", self.urlconf_module)
  File "/usr/local/lib/python2.7/dist-packages/django/utils/functional.py", line 33, in __get__
    res = instance.__dict__[self.name] = self.func(instance)
  File "/usr/local/lib/python2.7/dist-packages/django/core/urlresolvers.py", line 410, in urlconf_module
    return import_module(self.urlconf_name)
  File "/usr/lib/python2.7/importlib/__init__.py", line 37, in import_module
    __import__(name)
  File "/home/tayfen/develop/stepic/web_apps/web/ask/ask/urls.py", line 4, in <module>
    from qa.views import *
  File "/home/tayfen/develop/stepic/web_apps/web/ask/qa/views.py", line 39, in <module>
    @csrf_protect
NameError: name 'csrf_protect' is not defined
2016-03-26 21:05:14 [7618] [DEBUG] GET /favicon.ico
Internal Server Error: /favicon.ico
Traceback (most recent call last):
  File "/usr/local/lib/python2.7/dist-packages/django/core/handlers/base.py", line 134, in get_response
    resolver_match = resolver.resolve(request.path_info)
  File "/usr/local/lib/python2.7/dist-packages/django/core/urlresolvers.py", line 374, in resolve
    for pattern in self.url_patterns:
  File "/usr/local/lib/python2.7/dist-packages/django/utils/functional.py", line 33, in __get__
    res = instance.__dict__[self.name] = self.func(instance)
  File "/usr/local/lib/python2.7/dist-packages/django/core/urlresolvers.py", line 417, in url_patterns
    patterns = getattr(self.urlconf_module, "urlpatterns", self.urlconf_module)
  File "/usr/local/lib/python2.7/dist-packages/django/utils/functional.py", line 33, in __get__
    res = instance.__dict__[self.name] = self.func(instance)
  File "/usr/local/lib/python2.7/dist-packages/django/core/urlresolvers.py", line 410, in urlconf_module
    return import_module(self.urlconf_name)
  File "/usr/lib/python2.7/importlib/__init__.py", line 37, in import_module
    __import__(name)
  File "/home/tayfen/develop/stepic/web_apps/web/ask/ask/urls.py", line 4, in <module>
    from qa.views import *
  File "/home/tayfen/develop/stepic/web_apps/web/ask/qa/views.py", line 39, in <module>
    @csrf_protect
NameError: name 'csrf_protect' is not defined
2016-03-26 21:05:14 [7618] [DEBUG] GET /ask/
Internal Server Error: /ask/
Traceback (most recent call last):
  File "/usr/local/lib/python2.7/dist-packages/django/core/handlers/base.py", line 134, in get_response
    resolver_match = resolver.resolve(request.path_info)
  File "/usr/local/lib/python2.7/dist-packages/django/core/urlresolvers.py", line 374, in resolve
    for pattern in self.url_patterns:
  File "/usr/local/lib/python2.7/dist-packages/django/utils/functional.py", line 33, in __get__
    res = instance.__dict__[self.name] = self.func(instance)
  File "/usr/local/lib/python2.7/dist-packages/django/core/urlresolvers.py", line 417, in url_patterns
    patterns = getattr(self.urlconf_module, "urlpatterns", self.urlconf_module)
  File "/usr/local/lib/python2.7/dist-packages/django/utils/functional.py", line 33, in __get__
    res = instance.__dict__[self.name] = self.func(instance)
  File "/usr/local/lib/python2.7/dist-packages/django/core/urlresolvers.py", line 410, in urlconf_module
    return import_module(self.urlconf_name)
  File "/usr/lib/python2.7/importlib/__init__.py", line 37, in import_module
    __import__(name)
  File "/home/tayfen/develop/stepic/web_apps/web/ask/ask/urls.py", line 4, in <module>
    from qa.views import *
  File "/home/tayfen/develop/stepic/web_apps/web/ask/qa/views.py", line 39, in <module>
    @csrf_protect
NameError: name 'csrf_protect' is not defined
2016-03-26 21:05:15 [7618] [DEBUG] Ignoring EPIPE
2016-03-26 21:05:15 [7618] [DEBUG] GET /ask/
Internal Server Error: /ask/
Traceback (most recent call last):
  File "/usr/local/lib/python2.7/dist-packages/django/core/handlers/base.py", line 134, in get_response
    resolver_match = resolver.resolve(request.path_info)
  File "/usr/local/lib/python2.7/dist-packages/django/core/urlresolvers.py", line 374, in resolve
    for pattern in self.url_patterns:
  File "/usr/local/lib/python2.7/dist-packages/django/utils/functional.py", line 33, in __get__
    res = instance.__dict__[self.name] = self.func(instance)
  File "/usr/local/lib/python2.7/dist-packages/django/core/urlresolvers.py", line 417, in url_patterns
    patterns = getattr(self.urlconf_module, "urlpatterns", self.urlconf_module)
  File "/usr/local/lib/python2.7/dist-packages/django/utils/functional.py", line 33, in __get__
    res = instance.__dict__[self.name] = self.func(instance)
  File "/usr/local/lib/python2.7/dist-packages/django/core/urlresolvers.py", line 410, in urlconf_module
    return import_module(self.urlconf_name)
  File "/usr/lib/python2.7/importlib/__init__.py", line 37, in import_module
    __import__(name)
  File "/home/tayfen/develop/stepic/web_apps/web/ask/ask/urls.py", line 4, in <module>
    from qa.views import *
  File "/home/tayfen/develop/stepic/web_apps/web/ask/qa/views.py", line 39, in <module>
    @csrf_protect
NameError: name 'csrf_protect' is not defined
2016-03-26 21:05:15 [7618] [DEBUG] Ignoring EPIPE
2016-03-26 21:05:15 [7618] [DEBUG] GET /ask/
Internal Server Error: /ask/
Traceback (most recent call last):
  File "/usr/local/lib/python2.7/dist-packages/django/core/handlers/base.py", line 134, in get_response
    resolver_match = resolver.resolve(request.path_info)
  File "/usr/local/lib/python2.7/dist-packages/django/core/urlresolvers.py", line 374, in resolve
    for pattern in self.url_patterns:
  File "/usr/local/lib/python2.7/dist-packages/django/utils/functional.py", line 33, in __get__
    res = instance.__dict__[self.name] = self.func(instance)
  File "/usr/local/lib/python2.7/dist-packages/django/core/urlresolvers.py", line 417, in url_patterns
    patterns = getattr(self.urlconf_module, "urlpatterns", self.urlconf_module)
  File "/usr/local/lib/python2.7/dist-packages/django/utils/functional.py", line 33, in __get__
    res = instance.__dict__[self.name] = self.func(instance)
  File "/usr/local/lib/python2.7/dist-packages/django/core/urlresolvers.py", line 410, in urlconf_module
    return import_module(self.urlconf_name)
  File "/usr/lib/python2.7/importlib/__init__.py", line 37, in import_module
    __import__(name)
  File "/home/tayfen/develop/stepic/web_apps/web/ask/ask/urls.py", line 4, in <module>
    from qa.views import *
  File "/home/tayfen/develop/stepic/web_apps/web/ask/qa/views.py", line 39, in <module>
    @csrf_protect
NameError: name 'csrf_protect' is not defined
2016-03-26 21:05:15 [7618] [DEBUG] GET /ask/
Internal Server Error: /ask/
Traceback (most recent call last):
  File "/usr/local/lib/python2.7/dist-packages/django/core/handlers/base.py", line 134, in get_response
    resolver_match = resolver.resolve(request.path_info)
  File "/usr/local/lib/python2.7/dist-packages/django/core/urlresolvers.py", line 374, in resolve
    for pattern in self.url_patterns:
  File "/usr/local/lib/python2.7/dist-packages/django/utils/functional.py", line 33, in __get__
    res = instance.__dict__[self.name] = self.func(instance)
  File "/usr/local/lib/python2.7/dist-packages/django/core/urlresolvers.py", line 417, in url_patterns
    patterns = getattr(self.urlconf_module, "urlpatterns", self.urlconf_module)
  File "/usr/local/lib/python2.7/dist-packages/django/utils/functional.py", line 33, in __get__
    res = instance.__dict__[self.name] = self.func(instance)
  File "/usr/local/lib/python2.7/dist-packages/django/core/urlresolvers.py", line 410, in urlconf_module
    return import_module(self.urlconf_name)
  File "/usr/lib/python2.7/importlib/__init__.py", line 37, in import_module
    __import__(name)
  File "/home/tayfen/develop/stepic/web_apps/web/ask/ask/urls.py", line 4, in <module>
    from qa.views import *
  File "/home/tayfen/develop/stepic/web_apps/web/ask/qa/views.py", line 39, in <module>
    @csrf_protect
NameError: name 'csrf_protect' is not defined
2016-03-26 21:05:15 [7618] [DEBUG] GET /favicon.ico
Internal Server Error: /favicon.ico
Traceback (most recent call last):
  File "/usr/local/lib/python2.7/dist-packages/django/core/handlers/base.py", line 134, in get_response
    resolver_match = resolver.resolve(request.path_info)
  File "/usr/local/lib/python2.7/dist-packages/django/core/urlresolvers.py", line 374, in resolve
    for pattern in self.url_patterns:
  File "/usr/local/lib/python2.7/dist-packages/django/utils/functional.py", line 33, in __get__
    res = instance.__dict__[self.name] = self.func(instance)
  File "/usr/local/lib/python2.7/dist-packages/django/core/urlresolvers.py", line 417, in url_patterns
    patterns = getattr(self.urlconf_module, "urlpatterns", self.urlconf_module)
  File "/usr/local/lib/python2.7/dist-packages/django/utils/functional.py", line 33, in __get__
    res = instance.__dict__[self.name] = self.func(instance)
  File "/usr/local/lib/python2.7/dist-packages/django/core/urlresolvers.py", line 410, in urlconf_module
    return import_module(self.urlconf_name)
  File "/usr/lib/python2.7/importlib/__init__.py", line 37, in import_module
    __import__(name)
  File "/home/tayfen/develop/stepic/web_apps/web/ask/ask/urls.py", line 4, in <module>
    from qa.views import *
  File "/home/tayfen/develop/stepic/web_apps/web/ask/qa/views.py", line 39, in <module>
    @csrf_protect
NameError: name 'csrf_protect' is not defined
2016-03-26 21:05:17 [7618] [DEBUG] GET /ask/
Internal Server Error: /ask/
Traceback (most recent call last):
  File "/usr/local/lib/python2.7/dist-packages/django/core/handlers/base.py", line 134, in get_response
    resolver_match = resolver.resolve(request.path_info)
  File "/usr/local/lib/python2.7/dist-packages/django/core/urlresolvers.py", line 374, in resolve
    for pattern in self.url_patterns:
  File "/usr/local/lib/python2.7/dist-packages/django/utils/functional.py", line 33, in __get__
    res = instance.__dict__[self.name] = self.func(instance)
  File "/usr/local/lib/python2.7/dist-packages/django/core/urlresolvers.py", line 417, in url_patterns
    patterns = getattr(self.urlconf_module, "urlpatterns", self.urlconf_module)
  File "/usr/local/lib/python2.7/dist-packages/django/utils/functional.py", line 33, in __get__
    res = instance.__dict__[self.name] = self.func(instance)
  File "/usr/local/lib/python2.7/dist-packages/django/core/urlresolvers.py", line 410, in urlconf_module
    return import_module(self.urlconf_name)
  File "/usr/lib/python2.7/importlib/__init__.py", line 37, in import_module
    __import__(name)
  File "/home/tayfen/develop/stepic/web_apps/web/ask/ask/urls.py", line 4, in <module>
    from qa.views import *
  File "/home/tayfen/develop/stepic/web_apps/web/ask/qa/views.py", line 39, in <module>
    @csrf_protect
NameError: name 'csrf_protect' is not defined
2016-03-26 21:05:17 [7618] [DEBUG] GET /favicon.ico
Internal Server Error: /favicon.ico
Traceback (most recent call last):
  File "/usr/local/lib/python2.7/dist-packages/django/core/handlers/base.py", line 134, in get_response
    resolver_match = resolver.resolve(request.path_info)
  File "/usr/local/lib/python2.7/dist-packages/django/core/urlresolvers.py", line 374, in resolve
    for pattern in self.url_patterns:
  File "/usr/local/lib/python2.7/dist-packages/django/utils/functional.py", line 33, in __get__
    res = instance.__dict__[self.name] = self.func(instance)
  File "/usr/local/lib/python2.7/dist-packages/django/core/urlresolvers.py", line 417, in url_patterns
    patterns = getattr(self.urlconf_module, "urlpatterns", self.urlconf_module)
  File "/usr/local/lib/python2.7/dist-packages/django/utils/functional.py", line 33, in __get__
    res = instance.__dict__[self.name] = self.func(instance)
  File "/usr/local/lib/python2.7/dist-packages/django/core/urlresolvers.py", line 410, in urlconf_module
    return import_module(self.urlconf_name)
  File "/usr/lib/python2.7/importlib/__init__.py", line 37, in import_module
    __import__(name)
  File "/home/tayfen/develop/stepic/web_apps/web/ask/ask/urls.py", line 4, in <module>
    from qa.views import *
  File "/home/tayfen/develop/stepic/web_apps/web/ask/qa/views.py", line 39, in <module>
    @csrf_protect
NameError: name 'csrf_protect' is not defined
2016-03-26 21:05:17 [7618] [DEBUG] GET /ask/
Internal Server Error: /ask/
Traceback (most recent call last):
  File "/usr/local/lib/python2.7/dist-packages/django/core/handlers/base.py", line 134, in get_response
    resolver_match = resolver.resolve(request.path_info)
  File "/usr/local/lib/python2.7/dist-packages/django/core/urlresolvers.py", line 374, in resolve
    for pattern in self.url_patterns:
  File "/usr/local/lib/python2.7/dist-packages/django/utils/functional.py", line 33, in __get__
    res = instance.__dict__[self.name] = self.func(instance)
  File "/usr/local/lib/python2.7/dist-packages/django/core/urlresolvers.py", line 417, in url_patterns
    patterns = getattr(self.urlconf_module, "urlpatterns", self.urlconf_module)
  File "/usr/local/lib/python2.7/dist-packages/django/utils/functional.py", line 33, in __get__
    res = instance.__dict__[self.name] = self.func(instance)
  File "/usr/local/lib/python2.7/dist-packages/django/core/urlresolvers.py", line 410, in urlconf_module
    return import_module(self.urlconf_name)
  File "/usr/lib/python2.7/importlib/__init__.py", line 37, in import_module
    __import__(name)
  File "/home/tayfen/develop/stepic/web_apps/web/ask/ask/urls.py", line 4, in <module>
    from qa.views import *
  File "/home/tayfen/develop/stepic/web_apps/web/ask/qa/views.py", line 39, in <module>
    @csrf_protect
NameError: name 'csrf_protect' is not defined
2016-03-26 21:05:18 [7618] [DEBUG] GET /favicon.ico
Internal Server Error: /favicon.ico
Traceback (most recent call last):
  File "/usr/local/lib/python2.7/dist-packages/django/core/handlers/base.py", line 134, in get_response
    resolver_match = resolver.resolve(request.path_info)
  File "/usr/local/lib/python2.7/dist-packages/django/core/urlresolvers.py", line 374, in resolve
    for pattern in self.url_patterns:
  File "/usr/local/lib/python2.7/dist-packages/django/utils/functional.py", line 33, in __get__
    res = instance.__dict__[self.name] = self.func(instance)
  File "/usr/local/lib/python2.7/dist-packages/django/core/urlresolvers.py", line 417, in url_patterns
    patterns = getattr(self.urlconf_module, "urlpatterns", self.urlconf_module)
  File "/usr/local/lib/python2.7/dist-packages/django/utils/functional.py", line 33, in __get__
    res = instance.__dict__[self.name] = self.func(instance)
  File "/usr/local/lib/python2.7/dist-packages/django/core/urlresolvers.py", line 410, in urlconf_module
    return import_module(self.urlconf_name)
  File "/usr/lib/python2.7/importlib/__init__.py", line 37, in import_module
    __import__(name)
  File "/home/tayfen/develop/stepic/web_apps/web/ask/ask/urls.py", line 4, in <module>
    from qa.views import *
  File "/home/tayfen/develop/stepic/web_apps/web/ask/qa/views.py", line 39, in <module>
    @csrf_protect
NameError: name 'csrf_protect' is not defined
2016-03-26 21:05:18 [7618] [DEBUG] GET /ask/
Internal Server Error: /ask/
Traceback (most recent call last):
  File "/usr/local/lib/python2.7/dist-packages/django/core/handlers/base.py", line 134, in get_response
    resolver_match = resolver.resolve(request.path_info)
  File "/usr/local/lib/python2.7/dist-packages/django/core/urlresolvers.py", line 374, in resolve
    for pattern in self.url_patterns:
  File "/usr/local/lib/python2.7/dist-packages/django/utils/functional.py", line 33, in __get__
    res = instance.__dict__[self.name] = self.func(instance)
  File "/usr/local/lib/python2.7/dist-packages/django/core/urlresolvers.py", line 417, in url_patterns
    patterns = getattr(self.urlconf_module, "urlpatterns", self.urlconf_module)
  File "/usr/local/lib/python2.7/dist-packages/django/utils/functional.py", line 33, in __get__
    res = instance.__dict__[self.name] = self.func(instance)
  File "/usr/local/lib/python2.7/dist-packages/django/core/urlresolvers.py", line 410, in urlconf_module
    return import_module(self.urlconf_name)
  File "/usr/lib/python2.7/importlib/__init__.py", line 37, in import_module
    __import__(name)
  File "/home/tayfen/develop/stepic/web_apps/web/ask/ask/urls.py", line 4, in <module>
    from qa.views import *
  File "/home/tayfen/develop/stepic/web_apps/web/ask/qa/views.py", line 39, in <module>
    @csrf_protect
NameError: name 'csrf_protect' is not defined
2016-03-26 21:05:18 [7618] [DEBUG] GET /favicon.ico
Internal Server Error: /favicon.ico
Traceback (most recent call last):
  File "/usr/local/lib/python2.7/dist-packages/django/core/handlers/base.py", line 134, in get_response
    resolver_match = resolver.resolve(request.path_info)
  File "/usr/local/lib/python2.7/dist-packages/django/core/urlresolvers.py", line 374, in resolve
    for pattern in self.url_patterns:
  File "/usr/local/lib/python2.7/dist-packages/django/utils/functional.py", line 33, in __get__
    res = instance.__dict__[self.name] = self.func(instance)
  File "/usr/local/lib/python2.7/dist-packages/django/core/urlresolvers.py", line 417, in url_patterns
    patterns = getattr(self.urlconf_module, "urlpatterns", self.urlconf_module)
  File "/usr/local/lib/python2.7/dist-packages/django/utils/functional.py", line 33, in __get__
    res = instance.__dict__[self.name] = self.func(instance)
  File "/usr/local/lib/python2.7/dist-packages/django/core/urlresolvers.py", line 410, in urlconf_module
    return import_module(self.urlconf_name)
  File "/usr/lib/python2.7/importlib/__init__.py", line 37, in import_module
    __import__(name)
  File "/home/tayfen/develop/stepic/web_apps/web/ask/ask/urls.py", line 4, in <module>
    from qa.views import *
  File "/home/tayfen/develop/stepic/web_apps/web/ask/qa/views.py", line 39, in <module>
    @csrf_protect
NameError: name 'csrf_protect' is not defined
2016-03-26 21:05:18 [7618] [DEBUG] GET /ask/
Internal Server Error: /ask/
Traceback (most recent call last):
  File "/usr/local/lib/python2.7/dist-packages/django/core/handlers/base.py", line 134, in get_response
    resolver_match = resolver.resolve(request.path_info)
  File "/usr/local/lib/python2.7/dist-packages/django/core/urlresolvers.py", line 374, in resolve
    for pattern in self.url_patterns:
  File "/usr/local/lib/python2.7/dist-packages/django/utils/functional.py", line 33, in __get__
    res = instance.__dict__[self.name] = self.func(instance)
  File "/usr/local/lib/python2.7/dist-packages/django/core/urlresolvers.py", line 417, in url_patterns
    patterns = getattr(self.urlconf_module, "urlpatterns", self.urlconf_module)
  File "/usr/local/lib/python2.7/dist-packages/django/utils/functional.py", line 33, in __get__
    res = instance.__dict__[self.name] = self.func(instance)
  File "/usr/local/lib/python2.7/dist-packages/django/core/urlresolvers.py", line 410, in urlconf_module
    return import_module(self.urlconf_name)
  File "/usr/lib/python2.7/importlib/__init__.py", line 37, in import_module
    __import__(name)
  File "/home/tayfen/develop/stepic/web_apps/web/ask/ask/urls.py", line 4, in <module>
    from qa.views import *
  File "/home/tayfen/develop/stepic/web_apps/web/ask/qa/views.py", line 39, in <module>
    @csrf_protect
NameError: name 'csrf_protect' is not defined
2016-03-26 21:05:18 [7618] [DEBUG] Ignoring EPIPE
2016-03-26 21:05:18 [7618] [DEBUG] GET /ask/
Internal Server Error: /ask/
Traceback (most recent call last):
  File "/usr/local/lib/python2.7/dist-packages/django/core/handlers/base.py", line 134, in get_response
    resolver_match = resolver.resolve(request.path_info)
  File "/usr/local/lib/python2.7/dist-packages/django/core/urlresolvers.py", line 374, in resolve
    for pattern in self.url_patterns:
  File "/usr/local/lib/python2.7/dist-packages/django/utils/functional.py", line 33, in __get__
    res = instance.__dict__[self.name] = self.func(instance)
  File "/usr/local/lib/python2.7/dist-packages/django/core/urlresolvers.py", line 417, in url_patterns
    patterns = getattr(self.urlconf_module, "urlpatterns", self.urlconf_module)
  File "/usr/local/lib/python2.7/dist-packages/django/utils/functional.py", line 33, in __get__
    res = instance.__dict__[self.name] = self.func(instance)
  File "/usr/local/lib/python2.7/dist-packages/django/core/urlresolvers.py", line 410, in urlconf_module
    return import_module(self.urlconf_name)
  File "/usr/lib/python2.7/importlib/__init__.py", line 37, in import_module
    __import__(name)
  File "/home/tayfen/develop/stepic/web_apps/web/ask/ask/urls.py", line 4, in <module>
    from qa.views import *
  File "/home/tayfen/develop/stepic/web_apps/web/ask/qa/views.py", line 39, in <module>
    @csrf_protect
NameError: name 'csrf_protect' is not defined
2016-03-26 21:05:18 [7618] [DEBUG] Ignoring EPIPE
2016-03-26 21:05:18 [7618] [DEBUG] GET /ask/
Internal Server Error: /ask/
Traceback (most recent call last):
  File "/usr/local/lib/python2.7/dist-packages/django/core/handlers/base.py", line 134, in get_response
    resolver_match = resolver.resolve(request.path_info)
  File "/usr/local/lib/python2.7/dist-packages/django/core/urlresolvers.py", line 374, in resolve
    for pattern in self.url_patterns:
  File "/usr/local/lib/python2.7/dist-packages/django/utils/functional.py", line 33, in __get__
    res = instance.__dict__[self.name] = self.func(instance)
  File "/usr/local/lib/python2.7/dist-packages/django/core/urlresolvers.py", line 417, in url_patterns
    patterns = getattr(self.urlconf_module, "urlpatterns", self.urlconf_module)
  File "/usr/local/lib/python2.7/dist-packages/django/utils/functional.py", line 33, in __get__
    res = instance.__dict__[self.name] = self.func(instance)
  File "/usr/local/lib/python2.7/dist-packages/django/core/urlresolvers.py", line 410, in urlconf_module
    return import_module(self.urlconf_name)
  File "/usr/lib/python2.7/importlib/__init__.py", line 37, in import_module
    __import__(name)
  File "/home/tayfen/develop/stepic/web_apps/web/ask/ask/urls.py", line 4, in <module>
    from qa.views import *
  File "/home/tayfen/develop/stepic/web_apps/web/ask/qa/views.py", line 39, in <module>
    @csrf_protect
NameError: name 'csrf_protect' is not defined
2016-03-26 21:05:19 [7618] [DEBUG] GET /favicon.ico
Internal Server Error: /favicon.ico
Traceback (most recent call last):
  File "/usr/local/lib/python2.7/dist-packages/django/core/handlers/base.py", line 134, in get_response
    resolver_match = resolver.resolve(request.path_info)
  File "/usr/local/lib/python2.7/dist-packages/django/core/urlresolvers.py", line 374, in resolve
    for pattern in self.url_patterns:
  File "/usr/local/lib/python2.7/dist-packages/django/utils/functional.py", line 33, in __get__
    res = instance.__dict__[self.name] = self.func(instance)
  File "/usr/local/lib/python2.7/dist-packages/django/core/urlresolvers.py", line 417, in url_patterns
    patterns = getattr(self.urlconf_module, "urlpatterns", self.urlconf_module)
  File "/usr/local/lib/python2.7/dist-packages/django/utils/functional.py", line 33, in __get__
    res = instance.__dict__[self.name] = self.func(instance)
  File "/usr/local/lib/python2.7/dist-packages/django/core/urlresolvers.py", line 410, in urlconf_module
    return import_module(self.urlconf_name)
  File "/usr/lib/python2.7/importlib/__init__.py", line 37, in import_module
    __import__(name)
  File "/home/tayfen/develop/stepic/web_apps/web/ask/ask/urls.py", line 4, in <module>
    from qa.views import *
  File "/home/tayfen/develop/stepic/web_apps/web/ask/qa/views.py", line 39, in <module>
    @csrf_protect
NameError: name 'csrf_protect' is not defined
2016-03-26 21:05:19 [7618] [DEBUG] GET /ask/
Internal Server Error: /ask/
Traceback (most recent call last):
  File "/usr/local/lib/python2.7/dist-packages/django/core/handlers/base.py", line 134, in get_response
    resolver_match = resolver.resolve(request.path_info)
  File "/usr/local/lib/python2.7/dist-packages/django/core/urlresolvers.py", line 374, in resolve
    for pattern in self.url_patterns:
  File "/usr/local/lib/python2.7/dist-packages/django/utils/functional.py", line 33, in __get__
    res = instance.__dict__[self.name] = self.func(instance)
  File "/usr/local/lib/python2.7/dist-packages/django/core/urlresolvers.py", line 417, in url_patterns
    patterns = getattr(self.urlconf_module, "urlpatterns", self.urlconf_module)
  File "/usr/local/lib/python2.7/dist-packages/django/utils/functional.py", line 33, in __get__
    res = instance.__dict__[self.name] = self.func(instance)
  File "/usr/local/lib/python2.7/dist-packages/django/core/urlresolvers.py", line 410, in urlconf_module
    return import_module(self.urlconf_name)
  File "/usr/lib/python2.7/importlib/__init__.py", line 37, in import_module
    __import__(name)
  File "/home/tayfen/develop/stepic/web_apps/web/ask/ask/urls.py", line 4, in <module>
    from qa.views import *
  File "/home/tayfen/develop/stepic/web_apps/web/ask/qa/views.py", line 39, in <module>
    @csrf_protect
NameError: name 'csrf_protect' is not defined
2016-03-26 21:05:19 [7618] [DEBUG] GET /favicon.ico
Internal Server Error: /favicon.ico
Traceback (most recent call last):
  File "/usr/local/lib/python2.7/dist-packages/django/core/handlers/base.py", line 134, in get_response
    resolver_match = resolver.resolve(request.path_info)
  File "/usr/local/lib/python2.7/dist-packages/django/core/urlresolvers.py", line 374, in resolve
    for pattern in self.url_patterns:
  File "/usr/local/lib/python2.7/dist-packages/django/utils/functional.py", line 33, in __get__
    res = instance.__dict__[self.name] = self.func(instance)
  File "/usr/local/lib/python2.7/dist-packages/django/core/urlresolvers.py", line 417, in url_patterns
    patterns = getattr(self.urlconf_module, "urlpatterns", self.urlconf_module)
  File "/usr/local/lib/python2.7/dist-packages/django/utils/functional.py", line 33, in __get__
    res = instance.__dict__[self.name] = self.func(instance)
  File "/usr/local/lib/python2.7/dist-packages/django/core/urlresolvers.py", line 410, in urlconf_module
    return import_module(self.urlconf_name)
  File "/usr/lib/python2.7/importlib/__init__.py", line 37, in import_module
    __import__(name)
  File "/home/tayfen/develop/stepic/web_apps/web/ask/ask/urls.py", line 4, in <module>
    from qa.views import *
  File "/home/tayfen/develop/stepic/web_apps/web/ask/qa/views.py", line 39, in <module>
    @csrf_protect
NameError: name 'csrf_protect' is not defined
2016-03-26 21:05:19 [7618] [DEBUG] GET /ask/
Internal Server Error: /ask/
Traceback (most recent call last):
  File "/usr/local/lib/python2.7/dist-packages/django/core/handlers/base.py", line 134, in get_response
    resolver_match = resolver.resolve(request.path_info)
  File "/usr/local/lib/python2.7/dist-packages/django/core/urlresolvers.py", line 374, in resolve
    for pattern in self.url_patterns:
  File "/usr/local/lib/python2.7/dist-packages/django/utils/functional.py", line 33, in __get__
    res = instance.__dict__[self.name] = self.func(instance)
  File "/usr/local/lib/python2.7/dist-packages/django/core/urlresolvers.py", line 417, in url_patterns
    patterns = getattr(self.urlconf_module, "urlpatterns", self.urlconf_module)
  File "/usr/local/lib/python2.7/dist-packages/django/utils/functional.py", line 33, in __get__
    res = instance.__dict__[self.name] = self.func(instance)
  File "/usr/local/lib/python2.7/dist-packages/django/core/urlresolvers.py", line 410, in urlconf_module
    return import_module(self.urlconf_name)
  File "/usr/lib/python2.7/importlib/__init__.py", line 37, in import_module
    __import__(name)
  File "/home/tayfen/develop/stepic/web_apps/web/ask/ask/urls.py", line 4, in <module>
    from qa.views import *
  File "/home/tayfen/develop/stepic/web_apps/web/ask/qa/views.py", line 39, in <module>
    @csrf_protect
NameError: name 'csrf_protect' is not defined
2016-03-26 21:05:19 [7618] [DEBUG] Ignoring EPIPE
2016-03-26 21:05:19 [7618] [DEBUG] GET /ask/
Internal Server Error: /ask/
Traceback (most recent call last):
  File "/usr/local/lib/python2.7/dist-packages/django/core/handlers/base.py", line 134, in get_response
    resolver_match = resolver.resolve(request.path_info)
  File "/usr/local/lib/python2.7/dist-packages/django/core/urlresolvers.py", line 374, in resolve
    for pattern in self.url_patterns:
  File "/usr/local/lib/python2.7/dist-packages/django/utils/functional.py", line 33, in __get__
    res = instance.__dict__[self.name] = self.func(instance)
  File "/usr/local/lib/python2.7/dist-packages/django/core/urlresolvers.py", line 417, in url_patterns
    patterns = getattr(self.urlconf_module, "urlpatterns", self.urlconf_module)
  File "/usr/local/lib/python2.7/dist-packages/django/utils/functional.py", line 33, in __get__
    res = instance.__dict__[self.name] = self.func(instance)
  File "/usr/local/lib/python2.7/dist-packages/django/core/urlresolvers.py", line 410, in urlconf_module
    return import_module(self.urlconf_name)
  File "/usr/lib/python2.7/importlib/__init__.py", line 37, in import_module
    __import__(name)
  File "/home/tayfen/develop/stepic/web_apps/web/ask/ask/urls.py", line 4, in <module>
    from qa.views import *
  File "/home/tayfen/develop/stepic/web_apps/web/ask/qa/views.py", line 39, in <module>
    @csrf_protect
NameError: name 'csrf_protect' is not defined
2016-03-26 21:05:19 [7618] [DEBUG] Ignoring EPIPE
2016-03-26 21:05:19 [7618] [DEBUG] GET /ask/
Internal Server Error: /ask/
Traceback (most recent call last):
  File "/usr/local/lib/python2.7/dist-packages/django/core/handlers/base.py", line 134, in get_response
    resolver_match = resolver.resolve(request.path_info)
  File "/usr/local/lib/python2.7/dist-packages/django/core/urlresolvers.py", line 374, in resolve
    for pattern in self.url_patterns:
  File "/usr/local/lib/python2.7/dist-packages/django/utils/functional.py", line 33, in __get__
    res = instance.__dict__[self.name] = self.func(instance)
  File "/usr/local/lib/python2.7/dist-packages/django/core/urlresolvers.py", line 417, in url_patterns
    patterns = getattr(self.urlconf_module, "urlpatterns", self.urlconf_module)
  File "/usr/local/lib/python2.7/dist-packages/django/utils/functional.py", line 33, in __get__
    res = instance.__dict__[self.name] = self.func(instance)
  File "/usr/local/lib/python2.7/dist-packages/django/core/urlresolvers.py", line 410, in urlconf_module
    return import_module(self.urlconf_name)
  File "/usr/lib/python2.7/importlib/__init__.py", line 37, in import_module
    __import__(name)
  File "/home/tayfen/develop/stepic/web_apps/web/ask/ask/urls.py", line 4, in <module>
    from qa.views import *
  File "/home/tayfen/develop/stepic/web_apps/web/ask/qa/views.py", line 39, in <module>
    @csrf_protect
NameError: name 'csrf_protect' is not defined
2016-03-26 21:05:20 [7618] [DEBUG] GET /favicon.ico
Internal Server Error: /favicon.ico
Traceback (most recent call last):
  File "/usr/local/lib/python2.7/dist-packages/django/core/handlers/base.py", line 134, in get_response
    resolver_match = resolver.resolve(request.path_info)
  File "/usr/local/lib/python2.7/dist-packages/django/core/urlresolvers.py", line 374, in resolve
    for pattern in self.url_patterns:
  File "/usr/local/lib/python2.7/dist-packages/django/utils/functional.py", line 33, in __get__
    res = instance.__dict__[self.name] = self.func(instance)
  File "/usr/local/lib/python2.7/dist-packages/django/core/urlresolvers.py", line 417, in url_patterns
    patterns = getattr(self.urlconf_module, "urlpatterns", self.urlconf_module)
  File "/usr/local/lib/python2.7/dist-packages/django/utils/functional.py", line 33, in __get__
    res = instance.__dict__[self.name] = self.func(instance)
  File "/usr/local/lib/python2.7/dist-packages/django/core/urlresolvers.py", line 410, in urlconf_module
    return import_module(self.urlconf_name)
  File "/usr/lib/python2.7/importlib/__init__.py", line 37, in import_module
    __import__(name)
  File "/home/tayfen/develop/stepic/web_apps/web/ask/ask/urls.py", line 4, in <module>
    from qa.views import *
  File "/home/tayfen/develop/stepic/web_apps/web/ask/qa/views.py", line 39, in <module>
    @csrf_protect
NameError: name 'csrf_protect' is not defined
2016-03-26 21:05:20 [7618] [DEBUG] GET /ask/
Internal Server Error: /ask/
Traceback (most recent call last):
  File "/usr/local/lib/python2.7/dist-packages/django/core/handlers/base.py", line 134, in get_response
    resolver_match = resolver.resolve(request.path_info)
  File "/usr/local/lib/python2.7/dist-packages/django/core/urlresolvers.py", line 374, in resolve
    for pattern in self.url_patterns:
  File "/usr/local/lib/python2.7/dist-packages/django/utils/functional.py", line 33, in __get__
    res = instance.__dict__[self.name] = self.func(instance)
  File "/usr/local/lib/python2.7/dist-packages/django/core/urlresolvers.py", line 417, in url_patterns
    patterns = getattr(self.urlconf_module, "urlpatterns", self.urlconf_module)
  File "/usr/local/lib/python2.7/dist-packages/django/utils/functional.py", line 33, in __get__
    res = instance.__dict__[self.name] = self.func(instance)
  File "/usr/local/lib/python2.7/dist-packages/django/core/urlresolvers.py", line 410, in urlconf_module
    return import_module(self.urlconf_name)
  File "/usr/lib/python2.7/importlib/__init__.py", line 37, in import_module
    __import__(name)
  File "/home/tayfen/develop/stepic/web_apps/web/ask/ask/urls.py", line 4, in <module>
    from qa.views import *
  File "/home/tayfen/develop/stepic/web_apps/web/ask/qa/views.py", line 39, in <module>
    @csrf_protect
NameError: name 'csrf_protect' is not defined
2016-03-26 21:05:20 [7618] [DEBUG] Ignoring EPIPE
2016-03-26 21:05:20 [7618] [DEBUG] GET /ask/
Internal Server Error: /ask/
Traceback (most recent call last):
  File "/usr/local/lib/python2.7/dist-packages/django/core/handlers/base.py", line 134, in get_response
    resolver_match = resolver.resolve(request.path_info)
  File "/usr/local/lib/python2.7/dist-packages/django/core/urlresolvers.py", line 374, in resolve
    for pattern in self.url_patterns:
  File "/usr/local/lib/python2.7/dist-packages/django/utils/functional.py", line 33, in __get__
    res = instance.__dict__[self.name] = self.func(instance)
  File "/usr/local/lib/python2.7/dist-packages/django/core/urlresolvers.py", line 417, in url_patterns
    patterns = getattr(self.urlconf_module, "urlpatterns", self.urlconf_module)
  File "/usr/local/lib/python2.7/dist-packages/django/utils/functional.py", line 33, in __get__
    res = instance.__dict__[self.name] = self.func(instance)
  File "/usr/local/lib/python2.7/dist-packages/django/core/urlresolvers.py", line 410, in urlconf_module
    return import_module(self.urlconf_name)
  File "/usr/lib/python2.7/importlib/__init__.py", line 37, in import_module
    __import__(name)
  File "/home/tayfen/develop/stepic/web_apps/web/ask/ask/urls.py", line 4, in <module>
    from qa.views import *
  File "/home/tayfen/develop/stepic/web_apps/web/ask/qa/views.py", line 39, in <module>
    @csrf_protect
NameError: name 'csrf_protect' is not defined
2016-03-26 21:05:20 [7618] [DEBUG] Ignoring EPIPE
2016-03-26 21:05:20 [7618] [DEBUG] GET /ask/
Internal Server Error: /ask/
Traceback (most recent call last):
  File "/usr/local/lib/python2.7/dist-packages/django/core/handlers/base.py", line 134, in get_response
    resolver_match = resolver.resolve(request.path_info)
  File "/usr/local/lib/python2.7/dist-packages/django/core/urlresolvers.py", line 374, in resolve
    for pattern in self.url_patterns:
  File "/usr/local/lib/python2.7/dist-packages/django/utils/functional.py", line 33, in __get__
    res = instance.__dict__[self.name] = self.func(instance)
  File "/usr/local/lib/python2.7/dist-packages/django/core/urlresolvers.py", line 417, in url_patterns
    patterns = getattr(self.urlconf_module, "urlpatterns", self.urlconf_module)
  File "/usr/local/lib/python2.7/dist-packages/django/utils/functional.py", line 33, in __get__
    res = instance.__dict__[self.name] = self.func(instance)
  File "/usr/local/lib/python2.7/dist-packages/django/core/urlresolvers.py", line 410, in urlconf_module
    return import_module(self.urlconf_name)
  File "/usr/lib/python2.7/importlib/__init__.py", line 37, in import_module
    __import__(name)
  File "/home/tayfen/develop/stepic/web_apps/web/ask/ask/urls.py", line 4, in <module>
    from qa.views import *
  File "/home/tayfen/develop/stepic/web_apps/web/ask/qa/views.py", line 39, in <module>
    @csrf_protect
NameError: name 'csrf_protect' is not defined
2016-03-26 21:05:20 [7618] [DEBUG] GET /favicon.ico
Internal Server Error: /favicon.ico
Traceback (most recent call last):
  File "/usr/local/lib/python2.7/dist-packages/django/core/handlers/base.py", line 134, in get_response
    resolver_match = resolver.resolve(request.path_info)
  File "/usr/local/lib/python2.7/dist-packages/django/core/urlresolvers.py", line 374, in resolve
    for pattern in self.url_patterns:
  File "/usr/local/lib/python2.7/dist-packages/django/utils/functional.py", line 33, in __get__
    res = instance.__dict__[self.name] = self.func(instance)
  File "/usr/local/lib/python2.7/dist-packages/django/core/urlresolvers.py", line 417, in url_patterns
    patterns = getattr(self.urlconf_module, "urlpatterns", self.urlconf_module)
  File "/usr/local/lib/python2.7/dist-packages/django/utils/functional.py", line 33, in __get__
    res = instance.__dict__[self.name] = self.func(instance)
  File "/usr/local/lib/python2.7/dist-packages/django/core/urlresolvers.py", line 410, in urlconf_module
    return import_module(self.urlconf_name)
  File "/usr/lib/python2.7/importlib/__init__.py", line 37, in import_module
    __import__(name)
  File "/home/tayfen/develop/stepic/web_apps/web/ask/ask/urls.py", line 4, in <module>
    from qa.views import *
  File "/home/tayfen/develop/stepic/web_apps/web/ask/qa/views.py", line 39, in <module>
    @csrf_protect
NameError: name 'csrf_protect' is not defined
2016-03-26 21:05:20 [7618] [DEBUG] GET /ask/
Internal Server Error: /ask/
Traceback (most recent call last):
  File "/usr/local/lib/python2.7/dist-packages/django/core/handlers/base.py", line 134, in get_response
    resolver_match = resolver.resolve(request.path_info)
  File "/usr/local/lib/python2.7/dist-packages/django/core/urlresolvers.py", line 374, in resolve
    for pattern in self.url_patterns:
  File "/usr/local/lib/python2.7/dist-packages/django/utils/functional.py", line 33, in __get__
    res = instance.__dict__[self.name] = self.func(instance)
  File "/usr/local/lib/python2.7/dist-packages/django/core/urlresolvers.py", line 417, in url_patterns
    patterns = getattr(self.urlconf_module, "urlpatterns", self.urlconf_module)
  File "/usr/local/lib/python2.7/dist-packages/django/utils/functional.py", line 33, in __get__
    res = instance.__dict__[self.name] = self.func(instance)
  File "/usr/local/lib/python2.7/dist-packages/django/core/urlresolvers.py", line 410, in urlconf_module
    return import_module(self.urlconf_name)
  File "/usr/lib/python2.7/importlib/__init__.py", line 37, in import_module
    __import__(name)
  File "/home/tayfen/develop/stepic/web_apps/web/ask/ask/urls.py", line 4, in <module>
    from qa.views import *
  File "/home/tayfen/develop/stepic/web_apps/web/ask/qa/views.py", line 39, in <module>
    @csrf_protect
NameError: name 'csrf_protect' is not defined
2016-03-26 21:05:21 [7618] [DEBUG] GET /favicon.ico
Internal Server Error: /favicon.ico
Traceback (most recent call last):
  File "/usr/local/lib/python2.7/dist-packages/django/core/handlers/base.py", line 134, in get_response
    resolver_match = resolver.resolve(request.path_info)
  File "/usr/local/lib/python2.7/dist-packages/django/core/urlresolvers.py", line 374, in resolve
    for pattern in self.url_patterns:
  File "/usr/local/lib/python2.7/dist-packages/django/utils/functional.py", line 33, in __get__
    res = instance.__dict__[self.name] = self.func(instance)
  File "/usr/local/lib/python2.7/dist-packages/django/core/urlresolvers.py", line 417, in url_patterns
    patterns = getattr(self.urlconf_module, "urlpatterns", self.urlconf_module)
  File "/usr/local/lib/python2.7/dist-packages/django/utils/functional.py", line 33, in __get__
    res = instance.__dict__[self.name] = self.func(instance)
  File "/usr/local/lib/python2.7/dist-packages/django/core/urlresolvers.py", line 410, in urlconf_module
    return import_module(self.urlconf_name)
  File "/usr/lib/python2.7/importlib/__init__.py", line 37, in import_module
    __import__(name)
  File "/home/tayfen/develop/stepic/web_apps/web/ask/ask/urls.py", line 4, in <module>
    from qa.views import *
  File "/home/tayfen/develop/stepic/web_apps/web/ask/qa/views.py", line 39, in <module>
    @csrf_protect
NameError: name 'csrf_protect' is not defined
2016-03-26 21:05:21 [7618] [DEBUG] GET /ask/
Internal Server Error: /ask/
Traceback (most recent call last):
  File "/usr/local/lib/python2.7/dist-packages/django/core/handlers/base.py", line 134, in get_response
    resolver_match = resolver.resolve(request.path_info)
  File "/usr/local/lib/python2.7/dist-packages/django/core/urlresolvers.py", line 374, in resolve
    for pattern in self.url_patterns:
  File "/usr/local/lib/python2.7/dist-packages/django/utils/functional.py", line 33, in __get__
    res = instance.__dict__[self.name] = self.func(instance)
  File "/usr/local/lib/python2.7/dist-packages/django/core/urlresolvers.py", line 417, in url_patterns
    patterns = getattr(self.urlconf_module, "urlpatterns", self.urlconf_module)
  File "/usr/local/lib/python2.7/dist-packages/django/utils/functional.py", line 33, in __get__
    res = instance.__dict__[self.name] = self.func(instance)
  File "/usr/local/lib/python2.7/dist-packages/django/core/urlresolvers.py", line 410, in urlconf_module
    return import_module(self.urlconf_name)
  File "/usr/lib/python2.7/importlib/__init__.py", line 37, in import_module
    __import__(name)
  File "/home/tayfen/develop/stepic/web_apps/web/ask/ask/urls.py", line 4, in <module>
    from qa.views import *
  File "/home/tayfen/develop/stepic/web_apps/web/ask/qa/views.py", line 39, in <module>
    @csrf_protect
NameError: name 'csrf_protect' is not defined
2016-03-26 21:05:21 [7618] [DEBUG] Ignoring EPIPE
2016-03-26 21:05:21 [7618] [DEBUG] GET /ask/
Internal Server Error: /ask/
Traceback (most recent call last):
  File "/usr/local/lib/python2.7/dist-packages/django/core/handlers/base.py", line 134, in get_response
    resolver_match = resolver.resolve(request.path_info)
  File "/usr/local/lib/python2.7/dist-packages/django/core/urlresolvers.py", line 374, in resolve
    for pattern in self.url_patterns:
  File "/usr/local/lib/python2.7/dist-packages/django/utils/functional.py", line 33, in __get__
    res = instance.__dict__[self.name] = self.func(instance)
  File "/usr/local/lib/python2.7/dist-packages/django/core/urlresolvers.py", line 417, in url_patterns
    patterns = getattr(self.urlconf_module, "urlpatterns", self.urlconf_module)
  File "/usr/local/lib/python2.7/dist-packages/django/utils/functional.py", line 33, in __get__
    res = instance.__dict__[self.name] = self.func(instance)
  File "/usr/local/lib/python2.7/dist-packages/django/core/urlresolvers.py", line 410, in urlconf_module
    return import_module(self.urlconf_name)
  File "/usr/lib/python2.7/importlib/__init__.py", line 37, in import_module
    __import__(name)
  File "/home/tayfen/develop/stepic/web_apps/web/ask/ask/urls.py", line 4, in <module>
    from qa.views import *
  File "/home/tayfen/develop/stepic/web_apps/web/ask/qa/views.py", line 39, in <module>
    @csrf_protect
NameError: name 'csrf_protect' is not defined
2016-03-26 21:05:21 [7618] [DEBUG] GET /favicon.ico
Internal Server Error: /favicon.ico
Traceback (most recent call last):
  File "/usr/local/lib/python2.7/dist-packages/django/core/handlers/base.py", line 134, in get_response
    resolver_match = resolver.resolve(request.path_info)
  File "/usr/local/lib/python2.7/dist-packages/django/core/urlresolvers.py", line 374, in resolve
    for pattern in self.url_patterns:
  File "/usr/local/lib/python2.7/dist-packages/django/utils/functional.py", line 33, in __get__
    res = instance.__dict__[self.name] = self.func(instance)
  File "/usr/local/lib/python2.7/dist-packages/django/core/urlresolvers.py", line 417, in url_patterns
    patterns = getattr(self.urlconf_module, "urlpatterns", self.urlconf_module)
  File "/usr/local/lib/python2.7/dist-packages/django/utils/functional.py", line 33, in __get__
    res = instance.__dict__[self.name] = self.func(instance)
  File "/usr/local/lib/python2.7/dist-packages/django/core/urlresolvers.py", line 410, in urlconf_module
    return import_module(self.urlconf_name)
  File "/usr/lib/python2.7/importlib/__init__.py", line 37, in import_module
    __import__(name)
  File "/home/tayfen/develop/stepic/web_apps/web/ask/ask/urls.py", line 4, in <module>
    from qa.views import *
  File "/home/tayfen/develop/stepic/web_apps/web/ask/qa/views.py", line 39, in <module>
    @csrf_protect
NameError: name 'csrf_protect' is not defined
2016-03-26 21:05:22 [7618] [DEBUG] GET /ask/
Internal Server Error: /ask/
Traceback (most recent call last):
  File "/usr/local/lib/python2.7/dist-packages/django/core/handlers/base.py", line 134, in get_response
    resolver_match = resolver.resolve(request.path_info)
  File "/usr/local/lib/python2.7/dist-packages/django/core/urlresolvers.py", line 374, in resolve
    for pattern in self.url_patterns:
  File "/usr/local/lib/python2.7/dist-packages/django/utils/functional.py", line 33, in __get__
    res = instance.__dict__[self.name] = self.func(instance)
  File "/usr/local/lib/python2.7/dist-packages/django/core/urlresolvers.py", line 417, in url_patterns
    patterns = getattr(self.urlconf_module, "urlpatterns", self.urlconf_module)
  File "/usr/local/lib/python2.7/dist-packages/django/utils/functional.py", line 33, in __get__
    res = instance.__dict__[self.name] = self.func(instance)
  File "/usr/local/lib/python2.7/dist-packages/django/core/urlresolvers.py", line 410, in urlconf_module
    return import_module(self.urlconf_name)
  File "/usr/lib/python2.7/importlib/__init__.py", line 37, in import_module
    __import__(name)
  File "/home/tayfen/develop/stepic/web_apps/web/ask/ask/urls.py", line 4, in <module>
    from qa.views import *
  File "/home/tayfen/develop/stepic/web_apps/web/ask/qa/views.py", line 39, in <module>
    @csrf_protect
NameError: name 'csrf_protect' is not defined
2016-03-26 21:05:22 [7618] [DEBUG] GET /favicon.ico
Internal Server Error: /favicon.ico
Traceback (most recent call last):
  File "/usr/local/lib/python2.7/dist-packages/django/core/handlers/base.py", line 134, in get_response
    resolver_match = resolver.resolve(request.path_info)
  File "/usr/local/lib/python2.7/dist-packages/django/core/urlresolvers.py", line 374, in resolve
    for pattern in self.url_patterns:
  File "/usr/local/lib/python2.7/dist-packages/django/utils/functional.py", line 33, in __get__
    res = instance.__dict__[self.name] = self.func(instance)
  File "/usr/local/lib/python2.7/dist-packages/django/core/urlresolvers.py", line 417, in url_patterns
    patterns = getattr(self.urlconf_module, "urlpatterns", self.urlconf_module)
  File "/usr/local/lib/python2.7/dist-packages/django/utils/functional.py", line 33, in __get__
    res = instance.__dict__[self.name] = self.func(instance)
  File "/usr/local/lib/python2.7/dist-packages/django/core/urlresolvers.py", line 410, in urlconf_module
    return import_module(self.urlconf_name)
  File "/usr/lib/python2.7/importlib/__init__.py", line 37, in import_module
    __import__(name)
  File "/home/tayfen/develop/stepic/web_apps/web/ask/ask/urls.py", line 4, in <module>
    from qa.views import *
  File "/home/tayfen/develop/stepic/web_apps/web/ask/qa/views.py", line 39, in <module>
    @csrf_protect
NameError: name 'csrf_protect' is not defined
2016-03-27 00:07:46 [7678] [INFO] Starting gunicorn 17.5
2016-03-27 00:07:46 [7678] [DEBUG] Arbiter booted
2016-03-27 00:07:46 [7678] [INFO] Listening at: http://0.0.0.0:8000 (7678)
2016-03-27 00:07:46 [7678] [INFO] Using worker: sync
2016-03-27 00:07:46 [7683] [INFO] Booting worker with pid: 7683
2016-03-26 21:07:58 [7683] [DEBUG] GET /ask/
/usr/local/lib/python2.7/dist-packages/django/template/utils.py:37: RemovedInDjango110Warning: You haven't defined a TEMPLATES setting. You must do so before upgrading to Django 1.10. Otherwise Django will be unable to load templates.
  "unable to load templates.", RemovedInDjango110Warning)

2016-03-26 21:07:58 [7683] [DEBUG] GET /favicon.ico
Not Found: /favicon.ico
2016-03-26 21:13:01 [7683] [DEBUG] POST /ask/
2016-03-26 21:13:02 [7683] [DEBUG] GET /question/88
Not Found: /question/88
2016-03-26 21:13:02 [7683] [DEBUG] GET /question/88/
2016-03-26 21:13:28 [7683] [DEBUG] GET /ask/
2016-03-26 21:13:33 [7683] [DEBUG] POST /ask/
2016-03-26 21:13:33 [7683] [DEBUG] GET /question/89
Not Found: /question/89
2016-03-26 21:13:33 [7683] [DEBUG] GET /question/89/
2016-03-27 00:36:14 [7836] [INFO] Starting gunicorn 17.5
2016-03-27 00:36:14 [7836] [DEBUG] Arbiter booted
2016-03-27 00:36:14 [7836] [INFO] Listening at: http://0.0.0.0:8000 (7836)
2016-03-27 00:36:14 [7836] [INFO] Using worker: sync
2016-03-27 00:36:14 [7841] [INFO] Booting worker with pid: 7841
2016-03-26 21:36:23 [7841] [DEBUG] GET /question/89/
Internal Server Error: /question/89/
Traceback (most recent call last):
  File "/usr/local/lib/python2.7/dist-packages/django/core/handlers/base.py", line 149, in get_response
    response = self.process_exception_by_middleware(e, request)
  File "/usr/local/lib/python2.7/dist-packages/django/core/handlers/base.py", line 147, in get_response
    response = wrapped_callback(request, *callback_args, **callback_kwargs)
  File "/usr/local/lib/python2.7/dist-packages/django/utils/decorators.py", line 149, in _wrapped_view
    response = view_func(request, *args, **kwargs)
  File "/home/tayfen/develop/stepic/web_apps/web/ask/qa/views.py", line 45, in question
    form = AnswerForm(initial={'question': question_id})
NameError: global name 'question_id' is not defined
2016-03-27 00:37:05 [7847] [INFO] Starting gunicorn 17.5

Error: Already running on PID 7847 (or pid file '/home/tayfen/develop/stepic/web_apps/web/gunicorn.pid' is stale)

2016-03-26 21:37:09 [7841] [DEBUG] GET /question/89/
Internal Server Error: /question/89/
Traceback (most recent call last):
  File "/usr/local/lib/python2.7/dist-packages/django/core/handlers/base.py", line 149, in get_response
    response = self.process_exception_by_middleware(e, request)
  File "/usr/local/lib/python2.7/dist-packages/django/core/handlers/base.py", line 147, in get_response
    response = wrapped_callback(request, *callback_args, **callback_kwargs)
  File "/usr/local/lib/python2.7/dist-packages/django/utils/decorators.py", line 149, in _wrapped_view
    response = view_func(request, *args, **kwargs)
  File "/home/tayfen/develop/stepic/web_apps/web/ask/qa/views.py", line 45, in question
    form = AnswerForm(initial={'question': quest})
NameError: global name 'question_id' is not defined
2016-03-26 21:37:10 [7841] [DEBUG] GET /question/89/
Internal Server Error: /question/89/
Traceback (most recent call last):
  File "/usr/local/lib/python2.7/dist-packages/django/core/handlers/base.py", line 149, in get_response
    response = self.process_exception_by_middleware(e, request)
  File "/usr/local/lib/python2.7/dist-packages/django/core/handlers/base.py", line 147, in get_response
    response = wrapped_callback(request, *callback_args, **callback_kwargs)
  File "/usr/local/lib/python2.7/dist-packages/django/utils/decorators.py", line 149, in _wrapped_view
    response = view_func(request, *args, **kwargs)
  File "/home/tayfen/develop/stepic/web_apps/web/ask/qa/views.py", line 45, in question
    form = AnswerForm(initial={'question': quest})
NameError: global name 'question_id' is not defined
2016-03-26 21:37:11 [7841] [DEBUG] GET /question/89/
Internal Server Error: /question/89/
Traceback (most recent call last):
  File "/usr/local/lib/python2.7/dist-packages/django/core/handlers/base.py", line 149, in get_response
    response = self.process_exception_by_middleware(e, request)
  File "/usr/local/lib/python2.7/dist-packages/django/core/handlers/base.py", line 147, in get_response
    response = wrapped_callback(request, *callback_args, **callback_kwargs)
  File "/usr/local/lib/python2.7/dist-packages/django/utils/decorators.py", line 149, in _wrapped_view
    response = view_func(request, *args, **kwargs)
  File "/home/tayfen/develop/stepic/web_apps/web/ask/qa/views.py", line 45, in question
    form = AnswerForm(initial={'question': quest})
NameError: global name 'question_id' is not defined
2016-03-26 21:37:12 [7841] [DEBUG] GET /question/89/
Internal Server Error: /question/89/
Traceback (most recent call last):
  File "/usr/local/lib/python2.7/dist-packages/django/core/handlers/base.py", line 149, in get_response
    response = self.process_exception_by_middleware(e, request)
  File "/usr/local/lib/python2.7/dist-packages/django/core/handlers/base.py", line 147, in get_response
    response = wrapped_callback(request, *callback_args, **callback_kwargs)
  File "/usr/local/lib/python2.7/dist-packages/django/utils/decorators.py", line 149, in _wrapped_view
    response = view_func(request, *args, **kwargs)
  File "/home/tayfen/develop/stepic/web_apps/web/ask/qa/views.py", line 45, in question
    form = AnswerForm(initial={'question': quest})
NameError: global name 'question_id' is not defined
2016-03-26 21:37:27 [7841] [INFO] Parent changed, shutting down: <Worker 7841>
2016-03-26 21:37:27 [7841] [INFO] Worker exiting (pid: 7841)
2016-03-27 00:37:36 [7863] [INFO] Starting gunicorn 17.5
2016-03-27 00:37:36 [7863] [DEBUG] Arbiter booted
2016-03-27 00:37:36 [7863] [INFO] Listening at: http://0.0.0.0:8000 (7863)
2016-03-27 00:37:36 [7863] [INFO] Using worker: sync
2016-03-27 00:37:36 [7868] [INFO] Booting worker with pid: 7868
2016-03-26 21:37:39 [7868] [DEBUG] GET /question/89/
Internal Server Error: /question/89/
Traceback (most recent call last):
  File "/usr/local/lib/python2.7/dist-packages/django/core/handlers/base.py", line 149, in get_response
    response = self.process_exception_by_middleware(e, request)
  File "/usr/local/lib/python2.7/dist-packages/django/core/handlers/base.py", line 147, in get_response
    response = wrapped_callback(request, *callback_args, **callback_kwargs)
  File "/usr/local/lib/python2.7/dist-packages/django/utils/decorators.py", line 149, in _wrapped_view
    response = view_func(request, *args, **kwargs)
  File "/home/tayfen/develop/stepic/web_apps/web/ask/qa/views.py", line 46, in question
    q = get_object_or_404(Question, id=quest)
  File "/usr/local/lib/python2.7/dist-packages/django/shortcuts.py", line 155, in get_object_or_404
    return queryset.get(*args, **kwargs)
  File "/usr/local/lib/python2.7/dist-packages/django/db/models/query.py", line 381, in get
    num = len(clone)
  File "/usr/local/lib/python2.7/dist-packages/django/db/models/query.py", line 240, in __len__
    self._fetch_all()
  File "/usr/local/lib/python2.7/dist-packages/django/db/models/query.py", line 1074, in _fetch_all
    self._result_cache = list(self.iterator())
  File "/usr/local/lib/python2.7/dist-packages/django/db/models/query.py", line 52, in __iter__
    results = compiler.execute_sql()
  File "/usr/local/lib/python2.7/dist-packages/django/db/models/sql/compiler.py", line 848, in execute_sql
    cursor.execute(sql, params)
  File "/usr/local/lib/python2.7/dist-packages/django/db/backends/utils.py", line 79, in execute
    return super(CursorDebugWrapper, self).execute(sql, params)
  File "/usr/local/lib/python2.7/dist-packages/django/db/backends/utils.py", line 64, in execute
    return self.cursor.execute(sql, params)
  File "/usr/local/lib/python2.7/dist-packages/django/db/utils.py", line 95, in __exit__
    six.reraise(dj_exc_type, dj_exc_value, traceback)
  File "/usr/local/lib/python2.7/dist-packages/django/db/backends/utils.py", line 64, in execute
    return self.cursor.execute(sql, params)
  File "/usr/local/lib/python2.7/dist-packages/django/db/backends/mysql/base.py", line 112, in execute
    return self.cursor.execute(query, args)
  File "/usr/local/lib/python2.7/dist-packages/MySQLdb/cursors.py", line 205, in execute
    self.errorhandler(self, exc, value)
  File "/usr/local/lib/python2.7/dist-packages/MySQLdb/connections.py", line 36, in defaulterrorhandler
    raise errorclass, errorvalue
OperationalError: (1054, "Unknown column 'qa_question.author' in 'field list'")
2016-03-26 21:37:41 [7868] [DEBUG] GET /question/89/
Internal Server Error: /question/89/
Traceback (most recent call last):
  File "/usr/local/lib/python2.7/dist-packages/django/core/handlers/base.py", line 149, in get_response
    response = self.process_exception_by_middleware(e, request)
  File "/usr/local/lib/python2.7/dist-packages/django/core/handlers/base.py", line 147, in get_response
    response = wrapped_callback(request, *callback_args, **callback_kwargs)
  File "/usr/local/lib/python2.7/dist-packages/django/utils/decorators.py", line 149, in _wrapped_view
    response = view_func(request, *args, **kwargs)
  File "/home/tayfen/develop/stepic/web_apps/web/ask/qa/views.py", line 46, in question
    q = get_object_or_404(Question, id=quest)
  File "/usr/local/lib/python2.7/dist-packages/django/shortcuts.py", line 155, in get_object_or_404
    return queryset.get(*args, **kwargs)
  File "/usr/local/lib/python2.7/dist-packages/django/db/models/query.py", line 381, in get
    num = len(clone)
  File "/usr/local/lib/python2.7/dist-packages/django/db/models/query.py", line 240, in __len__
    self._fetch_all()
  File "/usr/local/lib/python2.7/dist-packages/django/db/models/query.py", line 1074, in _fetch_all
    self._result_cache = list(self.iterator())
  File "/usr/local/lib/python2.7/dist-packages/django/db/models/query.py", line 52, in __iter__
    results = compiler.execute_sql()
  File "/usr/local/lib/python2.7/dist-packages/django/db/models/sql/compiler.py", line 848, in execute_sql
    cursor.execute(sql, params)
  File "/usr/local/lib/python2.7/dist-packages/django/db/backends/utils.py", line 79, in execute
    return super(CursorDebugWrapper, self).execute(sql, params)
  File "/usr/local/lib/python2.7/dist-packages/django/db/backends/utils.py", line 64, in execute
    return self.cursor.execute(sql, params)
  File "/usr/local/lib/python2.7/dist-packages/django/db/utils.py", line 95, in __exit__
    six.reraise(dj_exc_type, dj_exc_value, traceback)
  File "/usr/local/lib/python2.7/dist-packages/django/db/backends/utils.py", line 64, in execute
    return self.cursor.execute(sql, params)
  File "/usr/local/lib/python2.7/dist-packages/django/db/backends/mysql/base.py", line 112, in execute
    return self.cursor.execute(query, args)
  File "/usr/local/lib/python2.7/dist-packages/MySQLdb/cursors.py", line 205, in execute
    self.errorhandler(self, exc, value)
  File "/usr/local/lib/python2.7/dist-packages/MySQLdb/connections.py", line 36, in defaulterrorhandler
    raise errorclass, errorvalue
OperationalError: (1054, "Unknown column 'qa_question.author' in 'field list'")
2016-03-26 21:39:26 [7868] [INFO] Parent changed, shutting down: <Worker 7868>
2016-03-26 21:39:26 [7868] [INFO] Worker exiting (pid: 7868)
2016-03-27 00:39:37 [7903] [INFO] Starting gunicorn 17.5
2016-03-27 00:39:37 [7903] [DEBUG] Arbiter booted
2016-03-27 00:39:37 [7903] [INFO] Listening at: http://0.0.0.0:8000 (7903)
2016-03-27 00:39:37 [7903] [INFO] Using worker: sync
2016-03-27 00:39:37 [7908] [INFO] Booting worker with pid: 7908
2016-03-26 21:39:43 [7908] [DEBUG] GET /question/89/
/usr/local/lib/python2.7/dist-packages/django/template/utils.py:37: RemovedInDjango110Warning: You haven't defined a TEMPLATES setting. You must do so before upgrading to Django 1.10. Otherwise Django will be unable to load templates.
  "unable to load templates.", RemovedInDjango110Warning)

2016-03-27 00:56:15 [8129] [INFO] Starting gunicorn 17.5
2016-03-27 00:56:15 [8129] [DEBUG] Arbiter booted
2016-03-27 00:56:15 [8129] [INFO] Listening at: http://0.0.0.0:8000 (8129)
2016-03-27 00:56:15 [8129] [INFO] Using worker: sync
2016-03-27 00:56:15 [8134] [INFO] Booting worker with pid: 8134
2016-03-27 00:56:15 [8134] [ERROR] Exception in worker process:
Traceback (most recent call last):
  File "/usr/lib/python2.7/dist-packages/gunicorn/arbiter.py", line 473, in spawn_worker
    worker.init_process()
  File "/usr/lib/python2.7/dist-packages/gunicorn/workers/base.py", line 100, in init_process
    self.wsgi = self.app.wsgi()
  File "/usr/lib/python2.7/dist-packages/gunicorn/app/base.py", line 115, in wsgi
    self.callable = self.load()
  File "/usr/lib/python2.7/dist-packages/gunicorn/app/wsgiapp.py", line 33, in load
    return util.import_app(self.app_uri)
  File "/usr/lib/python2.7/dist-packages/gunicorn/util.py", line 362, in import_app
    __import__(module)
ImportError: No module named ask.wsgi
Traceback (most recent call last):
  File "/usr/lib/python2.7/dist-packages/gunicorn/arbiter.py", line 473, in spawn_worker
    worker.init_process()
  File "/usr/lib/python2.7/dist-packages/gunicorn/workers/base.py", line 100, in init_process
    self.wsgi = self.app.wsgi()
  File "/usr/lib/python2.7/dist-packages/gunicorn/app/base.py", line 115, in wsgi
    self.callable = self.load()
  File "/usr/lib/python2.7/dist-packages/gunicorn/app/wsgiapp.py", line 33, in load
    return util.import_app(self.app_uri)
  File "/usr/lib/python2.7/dist-packages/gunicorn/util.py", line 362, in import_app
    __import__(module)
ImportError: No module named ask.wsgi
2016-03-27 00:56:15 [8134] [INFO] Worker exiting (pid: 8134)
2016-03-27 00:56:15 [8129] [INFO] Shutting down: Master
2016-03-27 00:56:15 [8129] [INFO] Reason: Worker failed to boot.
2016-03-27 00:56:31 [8142] [INFO] Starting gunicorn 17.5
2016-03-27 00:56:31 [8142] [DEBUG] Arbiter booted
2016-03-27 00:56:31 [8142] [INFO] Listening at: http://0.0.0.0:8000 (8142)
2016-03-27 00:56:31 [8142] [INFO] Using worker: sync
2016-03-27 00:56:31 [8147] [INFO] Booting worker with pid: 8147
2016-03-27 00:56:31 [8147] [ERROR] Exception in worker process:
Traceback (most recent call last):
  File "/usr/lib/python2.7/dist-packages/gunicorn/arbiter.py", line 473, in spawn_worker
    worker.init_process()
  File "/usr/lib/python2.7/dist-packages/gunicorn/workers/base.py", line 100, in init_process
    self.wsgi = self.app.wsgi()
  File "/usr/lib/python2.7/dist-packages/gunicorn/app/base.py", line 115, in wsgi
    self.callable = self.load()
  File "/usr/lib/python2.7/dist-packages/gunicorn/app/wsgiapp.py", line 33, in load
    return util.import_app(self.app_uri)
  File "/usr/lib/python2.7/dist-packages/gunicorn/util.py", line 362, in import_app
    __import__(module)
ImportError: No module named ask.wsgi
Traceback (most recent call last):
  File "/usr/lib/python2.7/dist-packages/gunicorn/arbiter.py", line 473, in spawn_worker
    worker.init_process()
  File "/usr/lib/python2.7/dist-packages/gunicorn/workers/base.py", line 100, in init_process
    self.wsgi = self.app.wsgi()
  File "/usr/lib/python2.7/dist-packages/gunicorn/app/base.py", line 115, in wsgi
    self.callable = self.load()
  File "/usr/lib/python2.7/dist-packages/gunicorn/app/wsgiapp.py", line 33, in load
    return util.import_app(self.app_uri)
  File "/usr/lib/python2.7/dist-packages/gunicorn/util.py", line 362, in import_app
    __import__(module)
ImportError: No module named ask.wsgi
2016-03-27 00:56:31 [8147] [INFO] Worker exiting (pid: 8147)
2016-03-27 00:56:31 [8142] [INFO] Shutting down: Master
2016-03-27 00:56:31 [8142] [INFO] Reason: Worker failed to boot.
2016-03-27 00:56:51 [8156] [INFO] Starting gunicorn 17.5
2016-03-27 00:56:51 [8156] [DEBUG] Arbiter booted
2016-03-27 00:56:51 [8156] [INFO] Listening at: http://0.0.0.0:8000 (8156)
2016-03-27 00:56:51 [8156] [INFO] Using worker: sync
2016-03-27 00:56:51 [8161] [INFO] Booting worker with pid: 8161
2016-03-26 21:56:54 [8161] [DEBUG] GET /question/89/
/usr/local/lib/python2.7/dist-packages/django/template/utils.py:37: RemovedInDjango110Warning: You haven't defined a TEMPLATES setting. You must do so before upgrading to Django 1.10. Otherwise Django will be unable to load templates.
  "unable to load templates.", RemovedInDjango110Warning)

2016-03-26 21:56:57 [8161] [DEBUG] GET /question/89/
2016-03-27 01:17:54 [8317] [INFO] Starting gunicorn 17.5
2016-03-27 01:17:54 [8317] [DEBUG] Arbiter booted
2016-03-27 01:17:54 [8317] [INFO] Listening at: http://0.0.0.0:8000 (8317)
2016-03-27 01:17:54 [8317] [INFO] Using worker: sync
2016-03-27 01:17:54 [8322] [INFO] Booting worker with pid: 8322
2016-03-26 22:18:05 [8322] [DEBUG] GET /question/89/
Internal Server Error: /question/89/
Traceback (most recent call last):
  File "/usr/local/lib/python2.7/dist-packages/django/core/handlers/base.py", line 149, in get_response
    response = self.process_exception_by_middleware(e, request)
  File "/usr/local/lib/python2.7/dist-packages/django/core/handlers/base.py", line 147, in get_response
    response = wrapped_callback(request, *callback_args, **callback_kwargs)
  File "/usr/local/lib/python2.7/dist-packages/django/utils/decorators.py", line 149, in _wrapped_view
    response = view_func(request, *args, **kwargs)
  File "/home/tayfen/develop/stepic/web_apps/web/ask/qa/views.py", line 48, in question
    answers = q.answer_set.all()
AttributeError: 'QuerySet' object has no attribute 'answer_set'
2016-03-26 22:28:21 [8322] [INFO] Parent changed, shutting down: <Worker 8322>
2016-03-26 22:28:21 [8322] [INFO] Worker exiting (pid: 8322)
2016-03-27 01:28:28 [8523] [INFO] Starting gunicorn 17.5
2016-03-27 01:28:28 [8523] [DEBUG] Arbiter booted
2016-03-27 01:28:28 [8523] [INFO] Listening at: http://0.0.0.0:8000 (8523)
2016-03-27 01:28:28 [8523] [INFO] Using worker: sync
2016-03-27 01:28:28 [8528] [INFO] Booting worker with pid: 8528
2016-03-26 22:28:43 [8528] [DEBUG] GET /question/89/
Internal Server Error: /question/89/
Traceback (most recent call last):
  File "/usr/local/lib/python2.7/dist-packages/django/core/handlers/base.py", line 149, in get_response
    response = self.process_exception_by_middleware(e, request)
  File "/usr/local/lib/python2.7/dist-packages/django/core/handlers/base.py", line 147, in get_response
    response = wrapped_callback(request, *callback_args, **callback_kwargs)
  File "/usr/local/lib/python2.7/dist-packages/django/utils/decorators.py", line 149, in _wrapped_view
    response = view_func(request, *args, **kwargs)
  File "/home/tayfen/develop/stepic/web_apps/web/ask/qa/views.py", line 47, in question
    q = Question.objects.get(id=quest)
  File "/usr/local/lib/python2.7/dist-packages/django/db/models/manager.py", line 122, in manager_method
    return getattr(self.get_queryset(), name)(*args, **kwargs)
  File "/usr/local/lib/python2.7/dist-packages/django/db/models/query.py", line 381, in get
    num = len(clone)
  File "/usr/local/lib/python2.7/dist-packages/django/db/models/query.py", line 240, in __len__
    self._fetch_all()
  File "/usr/local/lib/python2.7/dist-packages/django/db/models/query.py", line 1074, in _fetch_all
    self._result_cache = list(self.iterator())
  File "/usr/local/lib/python2.7/dist-packages/django/db/models/query.py", line 52, in __iter__
    results = compiler.execute_sql()
  File "/usr/local/lib/python2.7/dist-packages/django/db/models/sql/compiler.py", line 848, in execute_sql
    cursor.execute(sql, params)
  File "/usr/local/lib/python2.7/dist-packages/django/db/backends/utils.py", line 79, in execute
    return super(CursorDebugWrapper, self).execute(sql, params)
  File "/usr/local/lib/python2.7/dist-packages/django/db/backends/utils.py", line 64, in execute
    return self.cursor.execute(sql, params)
  File "/usr/local/lib/python2.7/dist-packages/django/db/utils.py", line 95, in __exit__
    six.reraise(dj_exc_type, dj_exc_value, traceback)
  File "/usr/local/lib/python2.7/dist-packages/django/db/backends/utils.py", line 64, in execute
    return self.cursor.execute(sql, params)
  File "/usr/local/lib/python2.7/dist-packages/django/db/backends/mysql/base.py", line 112, in execute
    return self.cursor.execute(query, args)
  File "/usr/local/lib/python2.7/dist-packages/MySQLdb/cursors.py", line 205, in execute
    self.errorhandler(self, exc, value)
  File "/usr/local/lib/python2.7/dist-packages/MySQLdb/connections.py", line 36, in defaulterrorhandler
    raise errorclass, errorvalue
OperationalError: (1054, "Unknown column 'qa_question.author_id' in 'field list'")
2016-03-27 01:29:32 [8557] [INFO] Starting gunicorn 17.5
2016-03-27 01:29:32 [8557] [DEBUG] Arbiter booted
2016-03-27 01:29:32 [8557] [INFO] Listening at: http://0.0.0.0:8000 (8557)
2016-03-27 01:29:32 [8557] [INFO] Using worker: sync
2016-03-27 01:29:32 [8562] [INFO] Booting worker with pid: 8562
2016-03-26 22:29:36 [8562] [DEBUG] GET /question/89/
/usr/local/lib/python2.7/dist-packages/django/template/utils.py:37: RemovedInDjango110Warning: You haven't defined a TEMPLATES setting. You must do so before upgrading to Django 1.10. Otherwise Django will be unable to load templates.
  "unable to load templates.", RemovedInDjango110Warning)

2016-03-26 22:53:22 [8562] [INFO] Parent changed, shutting down: <Worker 8562>
2016-03-26 22:53:22 [8562] [INFO] Worker exiting (pid: 8562)
2016-03-27 01:53:29 [8662] [INFO] Starting gunicorn 17.5
2016-03-27 01:53:29 [8662] [DEBUG] Arbiter booted
2016-03-27 01:53:29 [8662] [INFO] Listening at: http://0.0.0.0:8000 (8662)
2016-03-27 01:53:29 [8662] [INFO] Using worker: sync
2016-03-27 01:53:29 [8667] [INFO] Booting worker with pid: 8667
2016-03-26 22:53:38 [8667] [DEBUG] GET /question/89/
/usr/local/lib/python2.7/dist-packages/django/template/utils.py:37: RemovedInDjango110Warning: You haven't defined a TEMPLATES setting. You must do so before upgrading to Django 1.10. Otherwise Django will be unable to load templates.
  "unable to load templates.", RemovedInDjango110Warning)

2016-03-26 22:53:40 [8667] [DEBUG] GET /question/89/
2016-03-26 22:57:05 [8667] [DEBUG] GET /ask/
Internal Server Error: /ask/
Traceback (most recent call last):
  File "/usr/local/lib/python2.7/dist-packages/django/core/handlers/base.py", line 158, in get_response
    % (callback.__module__, view_name))
ValueError: The view qa.views.ask didn't return an HttpResponse object. It returned None instead.
2016-03-26 22:58:24 [8667] [DEBUG] GET /ask/
Internal Server Error: /ask/
Traceback (most recent call last):
  File "/usr/local/lib/python2.7/dist-packages/django/core/handlers/base.py", line 158, in get_response
    % (callback.__module__, view_name))
ValueError: The view qa.views.ask didn't return an HttpResponse object. It returned None instead.
2016-03-26 22:58:24 [8667] [DEBUG] GET /favicon.ico
Not Found: /favicon.ico
2016-03-26 22:58:25 [8667] [DEBUG] GET /ask/
Internal Server Error: /ask/
Traceback (most recent call last):
  File "/usr/local/lib/python2.7/dist-packages/django/core/handlers/base.py", line 158, in get_response
    % (callback.__module__, view_name))
ValueError: The view qa.views.ask didn't return an HttpResponse object. It returned None instead.
2016-03-26 22:58:25 [8667] [DEBUG] GET /favicon.ico
Not Found: /favicon.ico
2016-03-26 22:58:26 [8667] [DEBUG] GET /ask/
Internal Server Error: /ask/
Traceback (most recent call last):
  File "/usr/local/lib/python2.7/dist-packages/django/core/handlers/base.py", line 158, in get_response
    % (callback.__module__, view_name))
ValueError: The view qa.views.ask didn't return an HttpResponse object. It returned None instead.
2016-03-26 22:58:26 [8667] [DEBUG] GET /favicon.ico
Not Found: /favicon.ico
2016-03-27 01:58:42 [8713] [INFO] Starting gunicorn 17.5
2016-03-27 01:58:42 [8713] [DEBUG] Arbiter booted
2016-03-27 01:58:42 [8713] [INFO] Listening at: http://0.0.0.0:8000 (8713)
2016-03-27 01:58:42 [8713] [INFO] Using worker: sync
2016-03-27 01:58:42 [8718] [INFO] Booting worker with pid: 8718
2016-03-26 22:58:45 [8718] [DEBUG] GET /ask/
/usr/local/lib/python2.7/dist-packages/django/template/utils.py:37: RemovedInDjango110Warning: You haven't defined a TEMPLATES setting. You must do so before upgrading to Django 1.10. Otherwise Django will be unable to load templates.
  "unable to load templates.", RemovedInDjango110Warning)

2016-03-26 23:27:42 [8718] [INFO] Worker exiting (pid: 8718)
2016-03-27 02:27:43 [8713] [INFO] Handling signal: term
2016-03-27 02:27:44 [8713] [INFO] Shutting down: Master
2016-03-27 15:00:27 [6514] [INFO] Starting gunicorn 17.5
2016-03-27 15:00:27 [6514] [DEBUG] Arbiter booted
2016-03-27 15:00:27 [6514] [INFO] Listening at: http://0.0.0.0:8000 (6514)
2016-03-27 15:00:27 [6514] [INFO] Using worker: sync
2016-03-27 15:00:27 [6519] [INFO] Booting worker with pid: 6519
2016-03-27 12:01:55 [6519] [DEBUG] GET /
/usr/local/lib/python2.7/dist-packages/django/template/utils.py:37: RemovedInDjango110Warning: You haven't defined a TEMPLATES setting. You must do so before upgrading to Django 1.10. Otherwise Django will be unable to load templates.
  "unable to load templates.", RemovedInDjango110Warning)

2016-03-27 12:02:06 [6519] [DEBUG] GET /signup/
2016-03-27 15:04:12 [6550] [INFO] Starting gunicorn 17.5
2016-03-27 15:04:12 [6550] [DEBUG] Arbiter booted
2016-03-27 15:04:12 [6550] [INFO] Listening at: http://0.0.0.0:8000 (6550)
2016-03-27 15:04:12 [6550] [INFO] Using worker: sync
2016-03-27 15:04:12 [6555] [INFO] Booting worker with pid: 6555
2016-03-27 12:04:15 [6555] [DEBUG] GET /
/usr/local/lib/python2.7/dist-packages/django/template/utils.py:37: RemovedInDjango110Warning: You haven't defined a TEMPLATES setting. You must do so before upgrading to Django 1.10. Otherwise Django will be unable to load templates.
  "unable to load templates.", RemovedInDjango110Warning)

2016-03-27 12:04:19 [6555] [DEBUG] GET /signup/
2016-03-27 12:04:42 [6555] [DEBUG] GET /ask/
2016-03-27 12:04:54 [6555] [DEBUG] GET /question/1/
2016-03-27 12:05:02 [6555] [DEBUG] GET /signup/
2016-03-27 12:05:21 [6555] [DEBUG] GET /ask/
2016-03-27 12:05:21 [6555] [DEBUG] GET /favicon.ico
Not Found: /favicon.ico
2016-03-27 12:05:28 [6555] [DEBUG] GET /signup/
2016-03-27 12:06:39 [6555] [DEBUG] GET /signup/
2016-03-27 12:06:40 [6555] [DEBUG] GET /signup/
2016-03-27 12:06:40 [6555] [DEBUG] GET /signup/
2016-03-27 12:06:41 [6555] [DEBUG] GET /signup/
2016-03-27 12:06:42 [6555] [DEBUG] GET /signup/
2016-03-27 12:06:43 [6555] [DEBUG] GET /signup/
2016-03-27 15:07:11 [6648] [INFO] Starting gunicorn 17.5
2016-03-27 15:07:11 [6648] [DEBUG] Arbiter booted
2016-03-27 15:07:11 [6648] [INFO] Listening at: http://0.0.0.0:8000 (6648)
2016-03-27 15:07:11 [6648] [INFO] Using worker: sync
2016-03-27 15:07:11 [6653] [INFO] Booting worker with pid: 6653
2016-03-27 12:07:14 [6653] [DEBUG] GET /signup/
Internal Server Error: /signup/
Traceback (most recent call last):
  File "/usr/local/lib/python2.7/dist-packages/django/core/handlers/base.py", line 149, in get_response
    response = self.process_exception_by_middleware(e, request)
  File "/usr/local/lib/python2.7/dist-packages/django/core/handlers/base.py", line 147, in get_response
    response = wrapped_callback(request, *callback_args, **callback_kwargs)
  File "/usr/local/lib/python2.7/dist-packages/django/utils/decorators.py", line 149, in _wrapped_view
    response = view_func(request, *args, **kwargs)
  File "/home/tayfen/develop/stepic/web_apps/web/ask/qa/views.py", line 97, in signup
    form = SignForm()
NameError: global name 'SignForm' is not defined
2016-03-27 12:07:44 [6653] [DEBUG] GET /signup/
Internal Server Error: /signup/
Traceback (most recent call last):
  File "/usr/local/lib/python2.7/dist-packages/django/core/handlers/base.py", line 149, in get_response
    response = self.process_exception_by_middleware(e, request)
  File "/usr/local/lib/python2.7/dist-packages/django/core/handlers/base.py", line 147, in get_response
    response = wrapped_callback(request, *callback_args, **callback_kwargs)
  File "/usr/local/lib/python2.7/dist-packages/django/utils/decorators.py", line 149, in _wrapped_view
    response = view_func(request, *args, **kwargs)
  File "/home/tayfen/develop/stepic/web_apps/web/ask/qa/views.py", line 97, in signup
    form = SignForm()
NameError: global name 'SignForm' is not defined
2016-03-27 12:07:45 [6653] [DEBUG] GET /signup/
Internal Server Error: /signup/
Traceback (most recent call last):
  File "/usr/local/lib/python2.7/dist-packages/django/core/handlers/base.py", line 149, in get_response
    response = self.process_exception_by_middleware(e, request)
  File "/usr/local/lib/python2.7/dist-packages/django/core/handlers/base.py", line 147, in get_response
    response = wrapped_callback(request, *callback_args, **callback_kwargs)
  File "/usr/local/lib/python2.7/dist-packages/django/utils/decorators.py", line 149, in _wrapped_view
    response = view_func(request, *args, **kwargs)
  File "/home/tayfen/develop/stepic/web_apps/web/ask/qa/views.py", line 97, in signup
    form = SignForm()
NameError: global name 'SignForm' is not defined
2016-03-27 12:07:46 [6653] [DEBUG] GET /signup/
Internal Server Error: /signup/
Traceback (most recent call last):
  File "/usr/local/lib/python2.7/dist-packages/django/core/handlers/base.py", line 149, in get_response
    response = self.process_exception_by_middleware(e, request)
  File "/usr/local/lib/python2.7/dist-packages/django/core/handlers/base.py", line 147, in get_response
    response = wrapped_callback(request, *callback_args, **callback_kwargs)
  File "/usr/local/lib/python2.7/dist-packages/django/utils/decorators.py", line 149, in _wrapped_view
    response = view_func(request, *args, **kwargs)
  File "/home/tayfen/develop/stepic/web_apps/web/ask/qa/views.py", line 97, in signup
    form = SignForm()
NameError: global name 'SignForm' is not defined
2016-03-27 12:07:46 [6653] [DEBUG] GET /signup/
Internal Server Error: /signup/
Traceback (most recent call last):
  File "/usr/local/lib/python2.7/dist-packages/django/core/handlers/base.py", line 149, in get_response
    response = self.process_exception_by_middleware(e, request)
  File "/usr/local/lib/python2.7/dist-packages/django/core/handlers/base.py", line 147, in get_response
    response = wrapped_callback(request, *callback_args, **callback_kwargs)
  File "/usr/local/lib/python2.7/dist-packages/django/utils/decorators.py", line 149, in _wrapped_view
    response = view_func(request, *args, **kwargs)
  File "/home/tayfen/develop/stepic/web_apps/web/ask/qa/views.py", line 97, in signup
    form = SignForm()
NameError: global name 'SignForm' is not defined
2016-03-27 12:08:17 [6653] [INFO] Parent changed, shutting down: <Worker 6653>
2016-03-27 12:08:17 [6653] [INFO] Worker exiting (pid: 6653)
2016-03-27 15:08:36 [6673] [INFO] Starting gunicorn 17.5
2016-03-27 15:08:36 [6673] [DEBUG] Arbiter booted
2016-03-27 15:08:36 [6673] [INFO] Listening at: http://0.0.0.0:8000 (6673)
2016-03-27 15:08:36 [6673] [INFO] Using worker: sync
2016-03-27 15:08:36 [6678] [INFO] Booting worker with pid: 6678
2016-03-27 12:08:39 [6678] [DEBUG] GET /signup/
/usr/local/lib/python2.7/dist-packages/django/template/utils.py:37: RemovedInDjango110Warning: You haven't defined a TEMPLATES setting. You must do so before upgrading to Django 1.10. Otherwise Django will be unable to load templates.
  "unable to load templates.", RemovedInDjango110Warning)

2016-03-27 12:09:15 [6678] [DEBUG] POST /signup/
2016-03-27 12:09:15 [6678] [DEBUG] GET /
2016-03-27 15:25:01 [6711] [INFO] Starting gunicorn 17.5
2016-03-27 15:25:01 [6711] [DEBUG] Arbiter booted
2016-03-27 15:25:01 [6711] [INFO] Listening at: http://0.0.0.0:8000 (6711)
2016-03-27 15:25:01 [6711] [INFO] Using worker: sync
2016-03-27 15:25:01 [6716] [INFO] Booting worker with pid: 6716
2016-03-27 15:26:34 [6730] [INFO] Starting gunicorn 17.5
2016-03-27 15:26:34 [6730] [DEBUG] Arbiter booted
2016-03-27 15:26:34 [6730] [INFO] Listening at: http://0.0.0.0:8000 (6730)
2016-03-27 15:26:34 [6730] [INFO] Using worker: sync
2016-03-27 15:26:34 [6735] [INFO] Booting worker with pid: 6735
2016-03-27 12:26:40 [6735] [DEBUG] GET /
/usr/local/lib/python2.7/dist-packages/django/template/utils.py:37: RemovedInDjango110Warning: You haven't defined a TEMPLATES setting. You must do so before upgrading to Django 1.10. Otherwise Django will be unable to load templates.
  "unable to load templates.", RemovedInDjango110Warning)

2016-03-27 12:26:47 [6735] [DEBUG] GET /signup/
2016-03-27 12:27:10 [6735] [DEBUG] POST /signup/
Internal Server Error: /signup/
Traceback (most recent call last):
  File "/usr/local/lib/python2.7/dist-packages/django/core/handlers/base.py", line 149, in get_response
    response = self.process_exception_by_middleware(e, request)
  File "/usr/local/lib/python2.7/dist-packages/django/core/handlers/base.py", line 147, in get_response
    response = wrapped_callback(request, *callback_args, **callback_kwargs)
  File "/usr/local/lib/python2.7/dist-packages/django/utils/decorators.py", line 149, in _wrapped_view
    response = view_func(request, *args, **kwargs)
  File "/home/tayfen/develop/stepic/web_apps/web/ask/qa/views.py", line 104, in signup
    post = form.save()
  File "/home/tayfen/develop/stepic/web_apps/web/ask/qa/forms.py", line 16, in save
    user.save()
  File "/usr/local/lib/python2.7/dist-packages/django/contrib/auth/base_user.py", line 74, in save
    super(AbstractBaseUser, self).save(*args, **kwargs)
  File "/usr/local/lib/python2.7/dist-packages/django/db/models/base.py", line 700, in save
    force_update=force_update, update_fields=update_fields)
  File "/usr/local/lib/python2.7/dist-packages/django/db/models/base.py", line 728, in save_base
    updated = self._save_table(raw, cls, force_insert, force_update, using, update_fields)
  File "/usr/local/lib/python2.7/dist-packages/django/db/models/base.py", line 812, in _save_table
    result = self._do_insert(cls._base_manager, using, fields, update_pk, raw)
  File "/usr/local/lib/python2.7/dist-packages/django/db/models/base.py", line 851, in _do_insert
    using=using, raw=raw)
  File "/usr/local/lib/python2.7/dist-packages/django/db/models/manager.py", line 122, in manager_method
    return getattr(self.get_queryset(), name)(*args, **kwargs)
  File "/usr/local/lib/python2.7/dist-packages/django/db/models/query.py", line 1039, in _insert
    return query.get_compiler(using=using).execute_sql(return_id)
  File "/usr/local/lib/python2.7/dist-packages/django/db/models/sql/compiler.py", line 1060, in execute_sql
    cursor.execute(sql, params)
  File "/usr/local/lib/python2.7/dist-packages/django/db/backends/utils.py", line 79, in execute
    return super(CursorDebugWrapper, self).execute(sql, params)
  File "/usr/local/lib/python2.7/dist-packages/django/db/backends/utils.py", line 64, in execute
    return self.cursor.execute(sql, params)
  File "/usr/local/lib/python2.7/dist-packages/django/db/utils.py", line 95, in __exit__
    six.reraise(dj_exc_type, dj_exc_value, traceback)
  File "/usr/local/lib/python2.7/dist-packages/django/db/backends/utils.py", line 64, in execute
    return self.cursor.execute(sql, params)
  File "/usr/local/lib/python2.7/dist-packages/django/db/backends/mysql/base.py", line 112, in execute
    return self.cursor.execute(query, args)
  File "/usr/local/lib/python2.7/dist-packages/MySQLdb/cursors.py", line 205, in execute
    self.errorhandler(self, exc, value)
  File "/usr/local/lib/python2.7/dist-packages/MySQLdb/connections.py", line 36, in defaulterrorhandler
    raise errorclass, errorvalue
IntegrityError: (1062, "Duplicate entry 'tay' for key 'username'")
2016-03-27 12:32:07 [6735] [DEBUG] GET /signup/
2016-03-27 12:32:09 [6735] [DEBUG] POST /signup/
Internal Server Error: /signup/
Traceback (most recent call last):
  File "/usr/local/lib/python2.7/dist-packages/django/core/handlers/base.py", line 149, in get_response
    response = self.process_exception_by_middleware(e, request)
  File "/usr/local/lib/python2.7/dist-packages/django/core/handlers/base.py", line 147, in get_response
    response = wrapped_callback(request, *callback_args, **callback_kwargs)
  File "/usr/local/lib/python2.7/dist-packages/django/utils/decorators.py", line 149, in _wrapped_view
    response = view_func(request, *args, **kwargs)
  File "/home/tayfen/develop/stepic/web_apps/web/ask/qa/views.py", line 104, in signup
    post = form.save()
  File "/home/tayfen/develop/stepic/web_apps/web/ask/qa/forms.py", line 16, in save
    if !User.objects.get(username=user.username):
  File "/usr/local/lib/python2.7/dist-packages/django/contrib/auth/base_user.py", line 74, in save
    super(AbstractBaseUser, self).save(*args, **kwargs)
  File "/usr/local/lib/python2.7/dist-packages/django/db/models/base.py", line 700, in save
    force_update=force_update, update_fields=update_fields)
  File "/usr/local/lib/python2.7/dist-packages/django/db/models/base.py", line 728, in save_base
    updated = self._save_table(raw, cls, force_insert, force_update, using, update_fields)
  File "/usr/local/lib/python2.7/dist-packages/django/db/models/base.py", line 812, in _save_table
    result = self._do_insert(cls._base_manager, using, fields, update_pk, raw)
  File "/usr/local/lib/python2.7/dist-packages/django/db/models/base.py", line 851, in _do_insert
    using=using, raw=raw)
  File "/usr/local/lib/python2.7/dist-packages/django/db/models/manager.py", line 122, in manager_method
    return getattr(self.get_queryset(), name)(*args, **kwargs)
  File "/usr/local/lib/python2.7/dist-packages/django/db/models/query.py", line 1039, in _insert
    return query.get_compiler(using=using).execute_sql(return_id)
  File "/usr/local/lib/python2.7/dist-packages/django/db/models/sql/compiler.py", line 1060, in execute_sql
    cursor.execute(sql, params)
  File "/usr/local/lib/python2.7/dist-packages/django/db/backends/utils.py", line 79, in execute
    return super(CursorDebugWrapper, self).execute(sql, params)
  File "/usr/local/lib/python2.7/dist-packages/django/db/backends/utils.py", line 64, in execute
    return self.cursor.execute(sql, params)
  File "/usr/local/lib/python2.7/dist-packages/django/db/utils.py", line 95, in __exit__
    six.reraise(dj_exc_type, dj_exc_value, traceback)
  File "/usr/local/lib/python2.7/dist-packages/django/db/backends/utils.py", line 64, in execute
    return self.cursor.execute(sql, params)
  File "/usr/local/lib/python2.7/dist-packages/django/db/backends/mysql/base.py", line 112, in execute
    return self.cursor.execute(query, args)
  File "/usr/local/lib/python2.7/dist-packages/MySQLdb/cursors.py", line 205, in execute
    self.errorhandler(self, exc, value)
  File "/usr/local/lib/python2.7/dist-packages/MySQLdb/connections.py", line 36, in defaulterrorhandler
    raise errorclass, errorvalue
IntegrityError: (1062, "Duplicate entry 'tay' for key 'username'")
2016-03-27 15:32:34 [6751] [INFO] Starting gunicorn 17.5
2016-03-27 15:32:34 [6751] [DEBUG] Arbiter booted
2016-03-27 15:32:34 [6751] [INFO] Listening at: http://0.0.0.0:8000 (6751)
2016-03-27 15:32:34 [6751] [INFO] Using worker: sync
2016-03-27 15:32:34 [6756] [INFO] Booting worker with pid: 6756
2016-03-27 12:32:58 [6756] [DEBUG] GET /signup/
Internal Server Error: /signup/
Traceback (most recent call last):
  File "/usr/local/lib/python2.7/dist-packages/django/core/handlers/base.py", line 134, in get_response
    resolver_match = resolver.resolve(request.path_info)
  File "/usr/local/lib/python2.7/dist-packages/django/core/urlresolvers.py", line 374, in resolve
    for pattern in self.url_patterns:
  File "/usr/local/lib/python2.7/dist-packages/django/utils/functional.py", line 33, in __get__
    res = instance.__dict__[self.name] = self.func(instance)
  File "/usr/local/lib/python2.7/dist-packages/django/core/urlresolvers.py", line 417, in url_patterns
    patterns = getattr(self.urlconf_module, "urlpatterns", self.urlconf_module)
  File "/usr/local/lib/python2.7/dist-packages/django/utils/functional.py", line 33, in __get__
    res = instance.__dict__[self.name] = self.func(instance)
  File "/usr/local/lib/python2.7/dist-packages/django/core/urlresolvers.py", line 410, in urlconf_module
    return import_module(self.urlconf_name)
  File "/usr/lib/python2.7/importlib/__init__.py", line 37, in import_module
    __import__(name)
  File "/home/tayfen/develop/stepic/web_apps/web/ask/ask/urls.py", line 4, in <module>
    from qa.views import *
  File "/home/tayfen/develop/stepic/web_apps/web/ask/qa/views.py", line 4, in <module>
    from .forms import AnswerForm, AskForm, SignForm, LogForm
  File "/home/tayfen/develop/stepic/web_apps/web/ask/qa/forms.py", line 16
    if !User.objects.get(username=user.username):
       ^
SyntaxError: invalid syntax
2016-03-27 12:36:37 [6756] [DEBUG] GET /signup/
/usr/local/lib/python2.7/dist-packages/django/template/utils.py:37: RemovedInDjango110Warning: You haven't defined a TEMPLATES setting. You must do so before upgrading to Django 1.10. Otherwise Django will be unable to load templates.
  "unable to load templates.", RemovedInDjango110Warning)

2016-03-27 12:36:51 [6756] [DEBUG] POST /signup/
Internal Server Error: /signup/
Traceback (most recent call last):
  File "/usr/local/lib/python2.7/dist-packages/django/core/handlers/base.py", line 149, in get_response
    response = self.process_exception_by_middleware(e, request)
  File "/usr/local/lib/python2.7/dist-packages/django/core/handlers/base.py", line 147, in get_response
    response = wrapped_callback(request, *callback_args, **callback_kwargs)
  File "/usr/local/lib/python2.7/dist-packages/django/utils/decorators.py", line 149, in _wrapped_view
    response = view_func(request, *args, **kwargs)
  File "/home/tayfen/develop/stepic/web_apps/web/ask/qa/views.py", line 104, in signup
    post = form.save()
  File "/home/tayfen/develop/stepic/web_apps/web/ask/qa/forms.py", line 18, in save
    user.save()
  File "/usr/local/lib/python2.7/dist-packages/django/contrib/auth/base_user.py", line 74, in save
    super(AbstractBaseUser, self).save(*args, **kwargs)
  File "/usr/local/lib/python2.7/dist-packages/django/db/models/base.py", line 700, in save
    force_update=force_update, update_fields=update_fields)
  File "/usr/local/lib/python2.7/dist-packages/django/db/models/base.py", line 728, in save_base
    updated = self._save_table(raw, cls, force_insert, force_update, using, update_fields)
  File "/usr/local/lib/python2.7/dist-packages/django/db/models/base.py", line 812, in _save_table
    result = self._do_insert(cls._base_manager, using, fields, update_pk, raw)
  File "/usr/local/lib/python2.7/dist-packages/django/db/models/base.py", line 851, in _do_insert
    using=using, raw=raw)
  File "/usr/local/lib/python2.7/dist-packages/django/db/models/manager.py", line 122, in manager_method
    return getattr(self.get_queryset(), name)(*args, **kwargs)
  File "/usr/local/lib/python2.7/dist-packages/django/db/models/query.py", line 1039, in _insert
    return query.get_compiler(using=using).execute_sql(return_id)
  File "/usr/local/lib/python2.7/dist-packages/django/db/models/sql/compiler.py", line 1060, in execute_sql
    cursor.execute(sql, params)
  File "/usr/local/lib/python2.7/dist-packages/django/db/backends/utils.py", line 79, in execute
    return super(CursorDebugWrapper, self).execute(sql, params)
  File "/usr/local/lib/python2.7/dist-packages/django/db/backends/utils.py", line 64, in execute
    return self.cursor.execute(sql, params)
  File "/usr/local/lib/python2.7/dist-packages/django/db/utils.py", line 95, in __exit__
    six.reraise(dj_exc_type, dj_exc_value, traceback)
  File "/usr/local/lib/python2.7/dist-packages/django/db/backends/utils.py", line 64, in execute
    return self.cursor.execute(sql, params)
  File "/usr/local/lib/python2.7/dist-packages/django/db/backends/mysql/base.py", line 112, in execute
    return self.cursor.execute(query, args)
  File "/usr/local/lib/python2.7/dist-packages/MySQLdb/cursors.py", line 205, in execute
    self.errorhandler(self, exc, value)
  File "/usr/local/lib/python2.7/dist-packages/MySQLdb/connections.py", line 36, in defaulterrorhandler
    raise errorclass, errorvalue
IntegrityError: (1062, "Duplicate entry 'tay' for key 'username'")
2016-03-27 12:38:15 [6756] [DEBUG] POST /signup/
Internal Server Error: /signup/
Traceback (most recent call last):
  File "/usr/local/lib/python2.7/dist-packages/django/core/handlers/base.py", line 149, in get_response
    response = self.process_exception_by_middleware(e, request)
  File "/usr/local/lib/python2.7/dist-packages/django/core/handlers/base.py", line 147, in get_response
    response = wrapped_callback(request, *callback_args, **callback_kwargs)
  File "/usr/local/lib/python2.7/dist-packages/django/utils/decorators.py", line 149, in _wrapped_view
    response = view_func(request, *args, **kwargs)
  File "/home/tayfen/develop/stepic/web_apps/web/ask/qa/views.py", line 104, in signup
    post = form.save()
  File "/home/tayfen/develop/stepic/web_apps/web/ask/qa/forms.py", line 18, in save
    return None
  File "/usr/local/lib/python2.7/dist-packages/django/contrib/auth/base_user.py", line 74, in save
    super(AbstractBaseUser, self).save(*args, **kwargs)
  File "/usr/local/lib/python2.7/dist-packages/django/db/models/base.py", line 700, in save
    force_update=force_update, update_fields=update_fields)
  File "/usr/local/lib/python2.7/dist-packages/django/db/models/base.py", line 728, in save_base
    updated = self._save_table(raw, cls, force_insert, force_update, using, update_fields)
  File "/usr/local/lib/python2.7/dist-packages/django/db/models/base.py", line 812, in _save_table
    result = self._do_insert(cls._base_manager, using, fields, update_pk, raw)
  File "/usr/local/lib/python2.7/dist-packages/django/db/models/base.py", line 851, in _do_insert
    using=using, raw=raw)
  File "/usr/local/lib/python2.7/dist-packages/django/db/models/manager.py", line 122, in manager_method
    return getattr(self.get_queryset(), name)(*args, **kwargs)
  File "/usr/local/lib/python2.7/dist-packages/django/db/models/query.py", line 1039, in _insert
    return query.get_compiler(using=using).execute_sql(return_id)
  File "/usr/local/lib/python2.7/dist-packages/django/db/models/sql/compiler.py", line 1060, in execute_sql
    cursor.execute(sql, params)
  File "/usr/local/lib/python2.7/dist-packages/django/db/backends/utils.py", line 79, in execute
    return super(CursorDebugWrapper, self).execute(sql, params)
  File "/usr/local/lib/python2.7/dist-packages/django/db/backends/utils.py", line 64, in execute
    return self.cursor.execute(sql, params)
  File "/usr/local/lib/python2.7/dist-packages/django/db/utils.py", line 95, in __exit__
    six.reraise(dj_exc_type, dj_exc_value, traceback)
  File "/usr/local/lib/python2.7/dist-packages/django/db/backends/utils.py", line 64, in execute
    return self.cursor.execute(sql, params)
  File "/usr/local/lib/python2.7/dist-packages/django/db/backends/mysql/base.py", line 112, in execute
    return self.cursor.execute(query, args)
  File "/usr/local/lib/python2.7/dist-packages/MySQLdb/cursors.py", line 205, in execute
    self.errorhandler(self, exc, value)
  File "/usr/local/lib/python2.7/dist-packages/MySQLdb/connections.py", line 36, in defaulterrorhandler
    raise errorclass, errorvalue
IntegrityError: (1062, "Duplicate entry 'tay' for key 'username'")
2016-03-27 12:38:19 [6756] [DEBUG] GET /signup/
2016-03-27 12:38:31 [6756] [DEBUG] POST /signup/
Internal Server Error: /signup/
Traceback (most recent call last):
  File "/usr/local/lib/python2.7/dist-packages/django/core/handlers/base.py", line 149, in get_response
    response = self.process_exception_by_middleware(e, request)
  File "/usr/local/lib/python2.7/dist-packages/django/core/handlers/base.py", line 147, in get_response
    response = wrapped_callback(request, *callback_args, **callback_kwargs)
  File "/usr/local/lib/python2.7/dist-packages/django/utils/decorators.py", line 149, in _wrapped_view
    response = view_func(request, *args, **kwargs)
  File "/home/tayfen/develop/stepic/web_apps/web/ask/qa/views.py", line 104, in signup
    post = form.save()
  File "/home/tayfen/develop/stepic/web_apps/web/ask/qa/forms.py", line 18, in save
    return None
  File "/usr/local/lib/python2.7/dist-packages/django/contrib/auth/base_user.py", line 74, in save
    super(AbstractBaseUser, self).save(*args, **kwargs)
  File "/usr/local/lib/python2.7/dist-packages/django/db/models/base.py", line 700, in save
    force_update=force_update, update_fields=update_fields)
  File "/usr/local/lib/python2.7/dist-packages/django/db/models/base.py", line 728, in save_base
    updated = self._save_table(raw, cls, force_insert, force_update, using, update_fields)
  File "/usr/local/lib/python2.7/dist-packages/django/db/models/base.py", line 812, in _save_table
    result = self._do_insert(cls._base_manager, using, fields, update_pk, raw)
  File "/usr/local/lib/python2.7/dist-packages/django/db/models/base.py", line 851, in _do_insert
    using=using, raw=raw)
  File "/usr/local/lib/python2.7/dist-packages/django/db/models/manager.py", line 122, in manager_method
    return getattr(self.get_queryset(), name)(*args, **kwargs)
  File "/usr/local/lib/python2.7/dist-packages/django/db/models/query.py", line 1039, in _insert
    return query.get_compiler(using=using).execute_sql(return_id)
  File "/usr/local/lib/python2.7/dist-packages/django/db/models/sql/compiler.py", line 1060, in execute_sql
    cursor.execute(sql, params)
  File "/usr/local/lib/python2.7/dist-packages/django/db/backends/utils.py", line 79, in execute
    return super(CursorDebugWrapper, self).execute(sql, params)
  File "/usr/local/lib/python2.7/dist-packages/django/db/backends/utils.py", line 64, in execute
    return self.cursor.execute(sql, params)
  File "/usr/local/lib/python2.7/dist-packages/django/db/utils.py", line 95, in __exit__
    six.reraise(dj_exc_type, dj_exc_value, traceback)
  File "/usr/local/lib/python2.7/dist-packages/django/db/backends/utils.py", line 64, in execute
    return self.cursor.execute(sql, params)
  File "/usr/local/lib/python2.7/dist-packages/django/db/backends/mysql/base.py", line 112, in execute
    return self.cursor.execute(query, args)
  File "/usr/local/lib/python2.7/dist-packages/MySQLdb/cursors.py", line 205, in execute
    self.errorhandler(self, exc, value)
  File "/usr/local/lib/python2.7/dist-packages/MySQLdb/connections.py", line 36, in defaulterrorhandler
    raise errorclass, errorvalue
IntegrityError: (1062, "Duplicate entry 'tay' for key 'username'")
2016-03-27 15:38:53 [6776] [INFO] Starting gunicorn 17.5
2016-03-27 15:38:53 [6776] [DEBUG] Arbiter booted
2016-03-27 15:38:53 [6776] [INFO] Listening at: http://0.0.0.0:8000 (6776)
2016-03-27 15:38:53 [6776] [INFO] Using worker: sync
2016-03-27 15:38:53 [6781] [INFO] Booting worker with pid: 6781
2016-03-27 12:38:58 [6781] [DEBUG] GET /signup/
/usr/local/lib/python2.7/dist-packages/django/template/utils.py:37: RemovedInDjango110Warning: You haven't defined a TEMPLATES setting. You must do so before upgrading to Django 1.10. Otherwise Django will be unable to load templates.
  "unable to load templates.", RemovedInDjango110Warning)

2016-03-27 12:39:01 [6781] [DEBUG] POST /signup/
2016-03-27 12:39:01 [6781] [DEBUG] GET /
2016-03-27 12:39:16 [6781] [DEBUG] POST /signup/
Internal Server Error: /signup/
Traceback (most recent call last):
  File "/usr/local/lib/python2.7/dist-packages/django/core/handlers/base.py", line 149, in get_response
    response = self.process_exception_by_middleware(e, request)
  File "/usr/local/lib/python2.7/dist-packages/django/core/handlers/base.py", line 147, in get_response
    response = wrapped_callback(request, *callback_args, **callback_kwargs)
  File "/usr/local/lib/python2.7/dist-packages/django/utils/decorators.py", line 149, in _wrapped_view
    response = view_func(request, *args, **kwargs)
  File "/home/tayfen/develop/stepic/web_apps/web/ask/qa/views.py", line 107, in signup
    login(request, user)
  File "/usr/local/lib/python2.7/dist-packages/django/utils/decorators.py", line 149, in _wrapped_view
    response = view_func(request, *args, **kwargs)
TypeError: login() takes exactly 1 argument (2 given)
2016-03-27 15:41:45 [6795] [INFO] Starting gunicorn 17.5
2016-03-27 15:41:45 [6795] [DEBUG] Arbiter booted
2016-03-27 15:41:45 [6795] [INFO] Listening at: http://0.0.0.0:8000 (6795)
2016-03-27 15:41:45 [6795] [INFO] Using worker: sync
2016-03-27 15:41:45 [6800] [INFO] Booting worker with pid: 6800
2016-03-27 12:41:49 [6800] [DEBUG] POST /signup/
Internal Server Error: /signup/
Traceback (most recent call last):
  File "/usr/local/lib/python2.7/dist-packages/django/core/handlers/base.py", line 134, in get_response
    resolver_match = resolver.resolve(request.path_info)
  File "/usr/local/lib/python2.7/dist-packages/django/core/urlresolvers.py", line 374, in resolve
    for pattern in self.url_patterns:
  File "/usr/local/lib/python2.7/dist-packages/django/utils/functional.py", line 33, in __get__
    res = instance.__dict__[self.name] = self.func(instance)
  File "/usr/local/lib/python2.7/dist-packages/django/core/urlresolvers.py", line 417, in url_patterns
    patterns = getattr(self.urlconf_module, "urlpatterns", self.urlconf_module)
  File "/usr/local/lib/python2.7/dist-packages/django/utils/functional.py", line 33, in __get__
    res = instance.__dict__[self.name] = self.func(instance)
  File "/usr/local/lib/python2.7/dist-packages/django/core/urlresolvers.py", line 410, in urlconf_module
    return import_module(self.urlconf_name)
  File "/usr/lib/python2.7/importlib/__init__.py", line 37, in import_module
    __import__(name)
  File "/home/tayfen/develop/stepic/web_apps/web/ask/ask/urls.py", line 11, in <module>
    url(r"^login/.*$", _login),
NameError: name '_login' is not defined
2016-03-27 12:43:00 [6800] [DEBUG] POST /signup/
Internal Server Error: /signup/
Traceback (most recent call last):
  File "/usr/local/lib/python2.7/dist-packages/django/core/handlers/base.py", line 134, in get_response
    resolver_match = resolver.resolve(request.path_info)
  File "/usr/local/lib/python2.7/dist-packages/django/core/urlresolvers.py", line 374, in resolve
    for pattern in self.url_patterns:
  File "/usr/local/lib/python2.7/dist-packages/django/utils/functional.py", line 33, in __get__
    res = instance.__dict__[self.name] = self.func(instance)
  File "/usr/local/lib/python2.7/dist-packages/django/core/urlresolvers.py", line 417, in url_patterns
    patterns = getattr(self.urlconf_module, "urlpatterns", self.urlconf_module)
  File "/usr/local/lib/python2.7/dist-packages/django/utils/functional.py", line 33, in __get__
    res = instance.__dict__[self.name] = self.func(instance)
  File "/usr/local/lib/python2.7/dist-packages/django/core/urlresolvers.py", line 410, in urlconf_module
    return import_module(self.urlconf_name)
  File "/usr/lib/python2.7/importlib/__init__.py", line 37, in import_module
    __import__(name)
  File "/home/tayfen/develop/stepic/web_apps/web/ask/ask/urls.py", line 11, in <module>
    url(r"^login/.*$", login_user),
NameError: name 'login_user' is not defined
2016-03-27 12:43:45 [6800] [INFO] Parent changed, shutting down: <Worker 6800>
2016-03-27 12:43:45 [6800] [INFO] Worker exiting (pid: 6800)
2016-03-27 15:43:51 [6815] [INFO] Starting gunicorn 17.5
2016-03-27 15:43:51 [6815] [DEBUG] Arbiter booted
2016-03-27 15:43:51 [6815] [INFO] Listening at: http://0.0.0.0:8000 (6815)
2016-03-27 15:43:51 [6815] [INFO] Using worker: sync
2016-03-27 15:43:51 [6820] [INFO] Booting worker with pid: 6820
2016-03-27 12:43:57 [6820] [DEBUG] GET /signup/
/usr/local/lib/python2.7/dist-packages/django/template/utils.py:37: RemovedInDjango110Warning: You haven't defined a TEMPLATES setting. You must do so before upgrading to Django 1.10. Otherwise Django will be unable to load templates.
  "unable to load templates.", RemovedInDjango110Warning)

2016-03-27 12:43:58 [6820] [DEBUG] GET /signup/
2016-03-27 12:44:10 [6820] [DEBUG] POST /signup/
2016-03-27 12:44:10 [6820] [DEBUG] GET /
2016-03-27 12:44:35 [6820] [DEBUG] GET /login
Not Found: /login
2016-03-27 12:44:35 [6820] [DEBUG] GET /login/
2016-03-27 12:44:42 [6820] [DEBUG] POST /login/
Internal Server Error: /login/
Traceback (most recent call last):
  File "/usr/local/lib/python2.7/dist-packages/django/core/handlers/base.py", line 149, in get_response
    response = self.process_exception_by_middleware(e, request)
  File "/usr/local/lib/python2.7/dist-packages/django/core/handlers/base.py", line 147, in get_response
    response = wrapped_callback(request, *callback_args, **callback_kwargs)
  File "/usr/local/lib/python2.7/dist-packages/django/utils/decorators.py", line 149, in _wrapped_view
    response = view_func(request, *args, **kwargs)
  File "/home/tayfen/develop/stepic/web_apps/web/ask/qa/views.py", line 128, in login_user
    user = authenticate(username=post.username, password=post.password)
NameError: global name 'post' is not defined
2016-03-27 12:45:51 [6820] [DEBUG] POST /login/
Internal Server Error: /login/
Traceback (most recent call last):
  File "/usr/local/lib/python2.7/dist-packages/django/core/handlers/base.py", line 149, in get_response
    response = self.process_exception_by_middleware(e, request)
  File "/usr/local/lib/python2.7/dist-packages/django/core/handlers/base.py", line 147, in get_response
    response = wrapped_callback(request, *callback_args, **callback_kwargs)
  File "/usr/local/lib/python2.7/dist-packages/django/utils/decorators.py", line 149, in _wrapped_view
    response = view_func(request, *args, **kwargs)
  File "/home/tayfen/develop/stepic/web_apps/web/ask/qa/views.py", line 128, in login_user
    user = authenticate(username=form.username, password=form.password)
NameError: global name 'post' is not defined
2016-03-27 15:46:07 [6833] [INFO] Starting gunicorn 17.5
2016-03-27 15:46:07 [6833] [DEBUG] Arbiter booted
2016-03-27 15:46:07 [6833] [INFO] Listening at: http://0.0.0.0:8000 (6833)
2016-03-27 15:46:07 [6833] [INFO] Using worker: sync
2016-03-27 15:46:07 [6838] [INFO] Booting worker with pid: 6838
2016-03-27 12:46:12 [6838] [DEBUG] GET /login/
/usr/local/lib/python2.7/dist-packages/django/template/utils.py:37: RemovedInDjango110Warning: You haven't defined a TEMPLATES setting. You must do so before upgrading to Django 1.10. Otherwise Django will be unable to load templates.
  "unable to load templates.", RemovedInDjango110Warning)

2016-03-27 12:46:17 [6838] [DEBUG] POST /login/
Internal Server Error: /login/
Traceback (most recent call last):
  File "/usr/local/lib/python2.7/dist-packages/django/core/handlers/base.py", line 149, in get_response
    response = self.process_exception_by_middleware(e, request)
  File "/usr/local/lib/python2.7/dist-packages/django/core/handlers/base.py", line 147, in get_response
    response = wrapped_callback(request, *callback_args, **callback_kwargs)
  File "/usr/local/lib/python2.7/dist-packages/django/utils/decorators.py", line 149, in _wrapped_view
    response = view_func(request, *args, **kwargs)
  File "/home/tayfen/develop/stepic/web_apps/web/ask/qa/views.py", line 128, in login_user
    user = authenticate(username=form.username, password=form.password)
AttributeError: 'LogForm' object has no attribute 'username'
2016-03-27 15:48:31 [6859] [INFO] Starting gunicorn 17.5
2016-03-27 15:48:31 [6859] [DEBUG] Arbiter booted
2016-03-27 15:48:31 [6859] [INFO] Listening at: http://0.0.0.0:8000 (6859)
2016-03-27 15:48:31 [6859] [INFO] Using worker: sync
2016-03-27 15:48:31 [6864] [INFO] Booting worker with pid: 6864
2016-03-27 12:48:37 [6864] [DEBUG] GET /login/
/usr/local/lib/python2.7/dist-packages/django/template/utils.py:37: RemovedInDjango110Warning: You haven't defined a TEMPLATES setting. You must do so before upgrading to Django 1.10. Otherwise Django will be unable to load templates.
  "unable to load templates.", RemovedInDjango110Warning)

2016-03-27 12:48:42 [6864] [DEBUG] POST /login/
Internal Server Error: /login/
Traceback (most recent call last):
  File "/usr/local/lib/python2.7/dist-packages/django/core/handlers/base.py", line 149, in get_response
    response = self.process_exception_by_middleware(e, request)
  File "/usr/local/lib/python2.7/dist-packages/django/core/handlers/base.py", line 147, in get_response
    response = wrapped_callback(request, *callback_args, **callback_kwargs)
  File "/usr/local/lib/python2.7/dist-packages/django/utils/decorators.py", line 149, in _wrapped_view
    response = view_func(request, *args, **kwargs)
  File "/home/tayfen/develop/stepic/web_apps/web/ask/qa/views.py", line 128, in login_user
    post = form.save()
  File "/home/tayfen/develop/stepic/web_apps/web/ask/qa/forms.py", line 10, in save
    user = User(**self.cleaned_data)
AttributeError: 'LogForm' object has no attribute 'cleaned_data'
2016-03-27 15:55:06 [6876] [INFO] Starting gunicorn 17.5
2016-03-27 15:55:06 [6876] [DEBUG] Arbiter booted
2016-03-27 15:55:06 [6876] [INFO] Listening at: http://0.0.0.0:8000 (6876)
2016-03-27 15:55:06 [6876] [INFO] Using worker: sync
2016-03-27 15:55:06 [6881] [INFO] Booting worker with pid: 6881
2016-03-27 12:55:38 [6881] [DEBUG] GET /login/
/usr/local/lib/python2.7/dist-packages/django/template/utils.py:37: RemovedInDjango110Warning: You haven't defined a TEMPLATES setting. You must do so before upgrading to Django 1.10. Otherwise Django will be unable to load templates.
  "unable to load templates.", RemovedInDjango110Warning)

2016-03-27 12:55:39 [6881] [DEBUG] GET /login/
2016-03-27 12:55:41 [6881] [DEBUG] GET /login/
2016-03-27 12:55:50 [6881] [DEBUG] POST /login/
Internal Server Error: /login/
Traceback (most recent call last):
  File "/usr/local/lib/python2.7/dist-packages/django/core/handlers/base.py", line 149, in get_response
    response = self.process_exception_by_middleware(e, request)
  File "/usr/local/lib/python2.7/dist-packages/django/core/handlers/base.py", line 147, in get_response
    response = wrapped_callback(request, *callback_args, **callback_kwargs)
  File "/usr/local/lib/python2.7/dist-packages/django/utils/decorators.py", line 149, in _wrapped_view
    response = view_func(request, *args, **kwargs)
  File "/home/tayfen/develop/stepic/web_apps/web/ask/qa/views.py", line 128, in login_user
    post = form.save()
  File "/home/tayfen/develop/stepic/web_apps/web/ask/qa/forms.py", line 10, in save
    user = User(**self.cleaned_data)
AttributeError: 'LogForm' object has no attribute 'cleaned_data'
2016-03-27 13:00:45 [6881] [DEBUG] GET /login/
2016-03-27 13:00:51 [6881] [DEBUG] POST /login/
Internal Server Error: /login/
Traceback (most recent call last):
  File "/usr/local/lib/python2.7/dist-packages/django/core/handlers/base.py", line 149, in get_response
    response = self.process_exception_by_middleware(e, request)
  File "/usr/local/lib/python2.7/dist-packages/django/core/handlers/base.py", line 147, in get_response
    response = wrapped_callback(request, *callback_args, **callback_kwargs)
  File "/usr/local/lib/python2.7/dist-packages/django/utils/decorators.py", line 149, in _wrapped_view
    response = view_func(request, *args, **kwargs)
  File "/home/tayfen/develop/stepic/web_apps/web/ask/qa/views.py", line 128, in login_user
    post = form.save()
  File "/home/tayfen/develop/stepic/web_apps/web/ask/qa/forms.py", line 10, in save
    user = User(**self.cleaned_data)
AttributeError: 'LogForm' object has no attribute 'cleaned_data'
2016-03-27 16:01:08 [6893] [INFO] Starting gunicorn 17.5
2016-03-27 16:01:08 [6893] [DEBUG] Arbiter booted
2016-03-27 16:01:08 [6893] [INFO] Listening at: http://0.0.0.0:8000 (6893)
2016-03-27 16:01:08 [6893] [INFO] Using worker: sync
2016-03-27 16:01:08 [6898] [INFO] Booting worker with pid: 6898
2016-03-27 13:01:14 [6898] [DEBUG] GET /login/
/usr/local/lib/python2.7/dist-packages/django/template/utils.py:37: RemovedInDjango110Warning: You haven't defined a TEMPLATES setting. You must do so before upgrading to Django 1.10. Otherwise Django will be unable to load templates.
  "unable to load templates.", RemovedInDjango110Warning)

2016-03-27 13:01:20 [6898] [DEBUG] POST /login/
Internal Server Error: /login/
Traceback (most recent call last):
  File "/usr/local/lib/python2.7/dist-packages/django/core/handlers/base.py", line 149, in get_response
    response = self.process_exception_by_middleware(e, request)
  File "/usr/local/lib/python2.7/dist-packages/django/core/handlers/base.py", line 147, in get_response
    response = wrapped_callback(request, *callback_args, **callback_kwargs)
  File "/usr/local/lib/python2.7/dist-packages/django/utils/decorators.py", line 149, in _wrapped_view
    response = view_func(request, *args, **kwargs)
  File "/home/tayfen/develop/stepic/web_apps/web/ask/qa/views.py", line 130, in login_user
    if user.is_active:
AttributeError: 'NoneType' object has no attribute 'is_active'
2016-03-27 13:06:22 [6898] [DEBUG] POST /login/
Internal Server Error: /login/
Traceback (most recent call last):
  File "/usr/local/lib/python2.7/dist-packages/django/core/handlers/base.py", line 149, in get_response
    response = self.process_exception_by_middleware(e, request)
  File "/usr/local/lib/python2.7/dist-packages/django/core/handlers/base.py", line 147, in get_response
    response = wrapped_callback(request, *callback_args, **callback_kwargs)
  File "/usr/local/lib/python2.7/dist-packages/django/utils/decorators.py", line 149, in _wrapped_view
    response = view_func(request, *args, **kwargs)
  File "/home/tayfen/develop/stepic/web_apps/web/ask/qa/views.py", line 130, in login_user
    if user is not None:
AttributeError: 'NoneType' object has no attribute 'is_active'
2016-03-27 13:06:32 [6898] [DEBUG] GET /signup/
2016-03-27 13:06:50 [6898] [DEBUG] POST /signup/
Internal Server Error: /signup/
Traceback (most recent call last):
  File "/usr/local/lib/python2.7/dist-packages/django/core/handlers/base.py", line 149, in get_response
    response = self.process_exception_by_middleware(e, request)
  File "/usr/local/lib/python2.7/dist-packages/django/core/handlers/base.py", line 147, in get_response
    response = wrapped_callback(request, *callback_args, **callback_kwargs)
  File "/usr/local/lib/python2.7/dist-packages/django/utils/decorators.py", line 149, in _wrapped_view
    response = view_func(request, *args, **kwargs)
  File "/home/tayfen/develop/stepic/web_apps/web/ask/qa/views.py", line 107, in signup
    login(request, user)
  File "/usr/local/lib/python2.7/dist-packages/django/contrib/auth/__init__.py", line 97, in login
    user = request.user
AttributeError: 'WSGIRequest' object has no attribute 'user'
2016-03-27 16:07:26 [6910] [INFO] Starting gunicorn 17.5
2016-03-27 16:07:26 [6910] [DEBUG] Arbiter booted
2016-03-27 16:07:26 [6910] [INFO] Listening at: http://0.0.0.0:8000 (6910)
2016-03-27 16:07:26 [6910] [INFO] Using worker: sync
2016-03-27 16:07:26 [6915] [INFO] Booting worker with pid: 6915
2016-03-27 13:07:32 [6915] [DEBUG] GET /signup/
/usr/local/lib/python2.7/dist-packages/django/template/utils.py:37: RemovedInDjango110Warning: You haven't defined a TEMPLATES setting. You must do so before upgrading to Django 1.10. Otherwise Django will be unable to load templates.
  "unable to load templates.", RemovedInDjango110Warning)

2016-03-27 13:07:46 [6915] [DEBUG] POST /signup/
Internal Server Error: /signup/
Traceback (most recent call last):
  File "/usr/local/lib/python2.7/dist-packages/django/core/handlers/base.py", line 149, in get_response
    response = self.process_exception_by_middleware(e, request)
  File "/usr/local/lib/python2.7/dist-packages/django/core/handlers/base.py", line 147, in get_response
    response = wrapped_callback(request, *callback_args, **callback_kwargs)
  File "/usr/local/lib/python2.7/dist-packages/django/utils/decorators.py", line 149, in _wrapped_view
    response = view_func(request, *args, **kwargs)
  File "/home/tayfen/develop/stepic/web_apps/web/ask/qa/views.py", line 107, in signup
    login(request, user)
  File "/usr/local/lib/python2.7/dist-packages/django/contrib/auth/__init__.py", line 97, in login
    user = request.user
AttributeError: 'WSGIRequest' object has no attribute 'user'
2016-03-27 16:10:21 [6930] [INFO] Starting gunicorn 17.5
2016-03-27 16:10:21 [6930] [DEBUG] Arbiter booted
2016-03-27 16:10:21 [6930] [INFO] Listening at: http://0.0.0.0:8000 (6930)
2016-03-27 16:10:21 [6930] [INFO] Using worker: sync
2016-03-27 16:10:21 [6935] [INFO] Booting worker with pid: 6935
2016-03-27 13:10:27 [6935] [DEBUG] POST /signup/
2016-03-27 13:10:27 [6935] [DEBUG] GET /
/usr/local/lib/python2.7/dist-packages/django/template/utils.py:37: RemovedInDjango110Warning: You haven't defined a TEMPLATES setting. You must do so before upgrading to Django 1.10. Otherwise Django will be unable to load templates.
  "unable to load templates.", RemovedInDjango110Warning)

2016-03-27 13:10:37 [6935] [DEBUG] GET /login/
2016-03-27 13:10:43 [6935] [DEBUG] POST /login/
2016-03-27 13:10:43 [6935] [DEBUG] GET /
