[2016-03-10 11:22:34 +0000] [8238] [ERROR] Error handling request
Traceback (most recent call last):
  File "/home/tayfen/develop/stepic/web_apps/stepic_venv/local/lib/python2.7/site-packages/gunicorn/workers/sync.py", line 177, in handle_request
    resp.write(item)
  File "/home/tayfen/develop/stepic/web_apps/stepic_venv/local/lib/python2.7/site-packages/gunicorn/http/wsgi.py", line 329, in write
    raise TypeError('%r is not a byte' % arg)
TypeError: ['x=1'] is not a byte
[2016-03-10 11:22:56 +0000] [8238] [ERROR] Error handling request
Traceback (most recent call last):
  File "/home/tayfen/develop/stepic/web_apps/stepic_venv/local/lib/python2.7/site-packages/gunicorn/workers/sync.py", line 177, in handle_request
    resp.write(item)
  File "/home/tayfen/develop/stepic/web_apps/stepic_venv/local/lib/python2.7/site-packages/gunicorn/http/wsgi.py", line 329, in write
    raise TypeError('%r is not a byte' % arg)
TypeError: [''] is not a byte
[2016-03-10 11:23:06 +0000] [8238] [ERROR] Error handling request
Traceback (most recent call last):
  File "/home/tayfen/develop/stepic/web_apps/stepic_venv/local/lib/python2.7/site-packages/gunicorn/workers/sync.py", line 177, in handle_request
    resp.write(item)
  File "/home/tayfen/develop/stepic/web_apps/stepic_venv/local/lib/python2.7/site-packages/gunicorn/http/wsgi.py", line 329, in write
    raise TypeError('%r is not a byte' % arg)
TypeError: [''] is not a byte
[2016-03-10 11:26:36 +0000] [8286] [ERROR] Error handling request
Traceback (most recent call last):
  File "/home/tayfen/develop/stepic/web_apps/stepic_venv/local/lib/python2.7/site-packages/gunicorn/workers/sync.py", line 177, in handle_request
    resp.write(item)
  File "/home/tayfen/develop/stepic/web_apps/stepic_venv/local/lib/python2.7/site-packages/gunicorn/http/wsgi.py", line 329, in write
    raise TypeError('%r is not a byte' % arg)
TypeError: [''] is not a byte
[2016-03-10 11:26:47 +0000] [8286] [ERROR] Error handling request
Traceback (most recent call last):
  File "/home/tayfen/develop/stepic/web_apps/stepic_venv/local/lib/python2.7/site-packages/gunicorn/workers/sync.py", line 177, in handle_request
    resp.write(item)
  File "/home/tayfen/develop/stepic/web_apps/stepic_venv/local/lib/python2.7/site-packages/gunicorn/http/wsgi.py", line 329, in write
    raise TypeError('%r is not a byte' % arg)
TypeError: ['x=1'] is not a byte
[2016-03-10 11:31:24 +0000] [8328] [ERROR] Error handling request
Traceback (most recent call last):
  File "/home/tayfen/develop/stepic/web_apps/stepic_venv/local/lib/python2.7/site-packages/gunicorn/workers/sync.py", line 177, in handle_request
    resp.write(item)
  File "/home/tayfen/develop/stepic/web_apps/stepic_venv/local/lib/python2.7/site-packages/gunicorn/http/wsgi.py", line 329, in write
    raise TypeError('%r is not a byte' % arg)
TypeError: ['x=1'] is not a byte
[2016-03-10 11:31:43 +0000] [8328] [ERROR] Error handling request
Traceback (most recent call last):
  File "/home/tayfen/develop/stepic/web_apps/stepic_venv/local/lib/python2.7/site-packages/gunicorn/workers/sync.py", line 177, in handle_request
    resp.write(item)
  File "/home/tayfen/develop/stepic/web_apps/stepic_venv/local/lib/python2.7/site-packages/gunicorn/http/wsgi.py", line 329, in write
    raise TypeError('%r is not a byte' % arg)
TypeError: [''] is not a byte
[2016-03-23 12:01:50 +0000] [17594] [DEBUG] Current configuration:
  proxy_protocol: False
  worker_connections: 1000
  statsd_host: None
  max_requests_jitter: 0
  post_fork: <function post_fork at 0x26360c8>
  pythonpath: None
  enable_stdio_inheritance: False
  worker_class: sync
  ssl_version: 3
  suppress_ragged_eofs: True
  syslog: False
  syslog_facility: user
  when_ready: <function when_ready at 0x2633d70>
  pre_fork: <function pre_fork at 0x2633ed8>
  cert_reqs: 0
  preload_app: False
  keepalive: 2
  accesslog: /home/tayfen/develop/stepic/web_apps/web/gunicorn_ac.log
  group: 1000
  graceful_timeout: 30
  do_handshake_on_connect: False
  spew: False
  workers: 1
  proc_name: None
  sendfile: None
  pidfile: /home/tayfen/develop/stepic/web_apps/web/gunicorn.pid
  umask: 0
  on_reload: <function on_reload at 0x2633c08>
  pre_exec: <function pre_exec at 0x2636668>
  worker_tmp_dir: None
  post_worker_init: <function post_worker_init at 0x2636230>
  limit_request_fields: 100
  on_exit: <function on_exit at 0x2636cf8>
  config: /home/tayfen/develop/stepic/web_apps/web/etc/gunicorn.conf
  secure_scheme_headers: {'X-FORWARDED-PROTOCOL': 'ssl', 'X-FORWARDED-PROTO': 'https', 'X-FORWARDED-SSL': 'on'}
  proxy_allow_ips: ['127.0.0.1']
  pre_request: <function pre_request at 0x26367d0>
  post_request: <function post_request at 0x26368c0>
  user: 1000
  forwarded_allow_ips: ['127.0.0.1']
  worker_int: <function worker_int at 0x2636398>
  threads: 1
  max_requests: 1000
  limit_request_line: 4094
  access_log_format: %(h)s %(l)s %(u)s %(t)s "%(r)s" %(s)s %(b)s "%(f)s" "%(a)s"
  certfile: None
  worker_exit: <function worker_exit at 0x2636a28>
  chdir: /home/tayfen/develop/stepic/web_apps/web/ask
  paste: None
  default_proc_name: gunicorn
  errorlog: /home/tayfen/develop/stepic/web_apps/web/log/gunicorn_er.log
  loglevel: debug
  logconfig: None
  syslog_addr: udp://localhost:514
  syslog_prefix: None
  daemon: True
  ciphers: TLSv1
  on_starting: <function on_starting at 0x2633aa0>
  worker_abort: <function worker_abort at 0x2636500>
  bind: ['0:8000']
  raw_env: []
  reload: True
  check_config: False
  limit_request_field_size: 8190
  nworkers_changed: <function nworkers_changed at 0x2636b90>
  timeout: 30
  ca_certs: None
  django_settings: None
  tmp_upload_dir: None
  keyfile: None
  backlog: 2048
  logger_class: gunicorn.glogging.Logger
  statsd_prefix: 
[2016-03-23 12:01:50 +0000] [17594] [INFO] Starting gunicorn 19.4.5
[2016-03-23 12:01:50 +0000] [17594] [DEBUG] Arbiter booted
[2016-03-23 12:01:50 +0000] [17594] [INFO] Listening at: http://0.0.0.0:8000 (17594)
[2016-03-23 12:01:50 +0000] [17594] [INFO] Using worker: sync
[2016-03-23 12:01:50 +0000] [17599] [INFO] Booting worker with pid: 17599
[2016-03-23 12:01:50 +0000] [17594] [DEBUG] 1 workers
[2016-03-23 09:01:53 +0000] [17599] [DEBUG] GET /123
[2016-03-23 09:02:13 +0000] [17599] [DEBUG] GET /question/1/
[2016-03-23 09:02:20 +0000] [17599] [DEBUG] GET /question/1/
[2016-03-23 09:02:42 +0000] [17599] [DEBUG] GET /question/1321/
[2016-03-23 09:02:48 +0000] [17599] [DEBUG] GET /login/
[2016-03-23 09:02:52 +0000] [17599] [DEBUG] GET /
[2016-03-23 09:04:00 +0000] [17599] [DEBUG] GET /question/12/
[2016-03-23 09:04:28 +0000] [17599] [INFO] Worker reloading: /home/tayfen/develop/stepic/web_apps/web/ask/qa/views.py modified
[2016-03-23 09:04:28 +0000] [17599] [INFO] Worker exiting (pid: 17599)
[2016-03-23 12:04:28 +0000] [17607] [INFO] Booting worker with pid: 17607
[2016-03-23 09:04:29 +0000] [17607] [DEBUG] GET /question/12/
[2016-03-23 09:04:32 +0000] [17607] [DEBUG] GET /question/12/
[2016-03-23 09:04:32 +0000] [17607] [DEBUG] GET /question/12/
[2016-03-23 09:04:33 +0000] [17607] [DEBUG] GET /question/12/
[2016-03-23 09:04:33 +0000] [17607] [DEBUG] GET /question/12/
[2016-03-23 09:04:33 +0000] [17607] [DEBUG] GET /question/12/
[2016-03-23 09:04:34 +0000] [17607] [DEBUG] GET /question/12/
[2016-03-23 09:04:34 +0000] [17607] [DEBUG] GET /question/12/
[2016-03-23 09:04:35 +0000] [17607] [DEBUG] GET /question/12/
[2016-03-23 09:04:35 +0000] [17607] [DEBUG] GET /question/12/
[2016-03-23 09:04:35 +0000] [17607] [DEBUG] GET /question/12/
[2016-03-23 09:04:51 +0000] [17607] [INFO] Worker reloading: /home/tayfen/develop/stepic/web_apps/web/ask/qa/views.py modified
[2016-03-23 09:04:51 +0000] [17607] [INFO] Worker exiting (pid: 17607)
[2016-03-23 12:04:51 +0000] [17610] [INFO] Booting worker with pid: 17610
[2016-03-23 09:05:43 +0000] [17610] [DEBUG] GET /login/
[2016-03-23 09:05:50 +0000] [17610] [DEBUG] GET /question/12/
[2016-03-23 09:07:51 +0000] [17610] [INFO] Worker reloading: /home/tayfen/develop/stepic/web_apps/web/ask/qa/views.py modified
[2016-03-23 09:07:51 +0000] [17610] [INFO] Worker exiting (pid: 17610)
[2016-03-23 12:07:51 +0000] [17640] [INFO] Booting worker with pid: 17640
[2016-03-23 09:07:58 +0000] [17640] [DEBUG] GET /question/12/
[2016-03-23 09:08:03 +0000] [17640] [DEBUG] GET /question/1/
[2016-03-23 09:08:08 +0000] [17640] [DEBUG] GET /question/2/
[2016-03-23 09:11:07 +0000] [17640] [INFO] Worker reloading: /home/tayfen/develop/stepic/web_apps/web/ask/qa/views.py modified
[2016-03-23 09:11:07 +0000] [17640] [INFO] Worker exiting (pid: 17640)
[2016-03-23 12:11:07 +0000] [17674] [INFO] Booting worker with pid: 17674
[2016-03-23 09:11:23 +0000] [17674] [DEBUG] GET /question/2/
[2016-03-23 09:11:38 +0000] [17674] [INFO] Worker reloading: /home/tayfen/develop/stepic/web_apps/web/ask/qa/views.py modified
[2016-03-23 09:11:38 +0000] [17674] [INFO] Worker exiting (pid: 17674)
[2016-03-23 12:11:38 +0000] [17684] [INFO] Booting worker with pid: 17684
[2016-03-23 09:11:39 +0000] [17684] [DEBUG] GET /question/2/
[2016-03-23 09:11:59 +0000] [17684] [INFO] Worker reloading: /home/tayfen/develop/stepic/web_apps/web/ask/qa/views.py modified
[2016-03-23 09:11:59 +0000] [17684] [INFO] Worker exiting (pid: 17684)
[2016-03-23 12:11:59 +0000] [17687] [INFO] Booting worker with pid: 17687
[2016-03-23 09:12:11 +0000] [17687] [DEBUG] GET /question/2/
[2016-03-23 10:33:48 +0000] [17687] [INFO] Worker reloading: /home/tayfen/develop/stepic/web_apps/web/ask/qa/views.py modified
[2016-03-23 10:33:48 +0000] [17687] [INFO] Worker exiting (pid: 17687)
[2016-03-23 13:33:48 +0000] [18472] [INFO] Booting worker with pid: 18472
[2016-03-23 10:40:47 +0000] [18472] [DEBUG] GET /
[2016-03-23 10:41:03 +0000] [18472] [DEBUG] GET /
[2016-03-23 10:41:25 +0000] [18472] [DEBUG] GET /
[2016-03-23 10:42:52 +0000] [18472] [DEBUG] GET /
[2016-03-23 10:42:53 +0000] [18472] [DEBUG] GET /
[2016-03-23 10:42:55 +0000] [18472] [DEBUG] GET /
[2016-03-23 10:42:56 +0000] [18472] [DEBUG] GET /
[2016-03-23 10:42:56 +0000] [18472] [DEBUG] GET /
[2016-03-23 10:44:59 +0000] [18472] [DEBUG] GET /
[2016-03-23 10:45:01 +0000] [18472] [DEBUG] GET /
[2016-03-23 10:45:28 +0000] [18472] [DEBUG] GET /
[2016-03-23 10:48:22 +0000] [18472] [INFO] Worker reloading: /home/tayfen/develop/stepic/web_apps/web/ask/qa/views.py modified
[2016-03-23 10:48:22 +0000] [18472] [INFO] Worker exiting (pid: 18472)
[2016-03-23 13:48:22 +0000] [18624] [INFO] Booting worker with pid: 18624
[2016-03-23 10:48:34 +0000] [18624] [DEBUG] GET /
[2016-03-23 10:48:35 +0000] [18624] [DEBUG] GET /
[2016-03-23 10:52:42 +0000] [18624] [INFO] Worker reloading: /home/tayfen/develop/stepic/web_apps/web/ask/qa/views.py modified
[2016-03-23 10:52:42 +0000] [18624] [INFO] Worker exiting (pid: 18624)
[2016-03-23 13:52:42 +0000] [18712] [INFO] Booting worker with pid: 18712
[2016-03-23 10:53:01 +0000] [18712] [DEBUG] GET /
[2016-03-23 10:53:02 +0000] [18712] [DEBUG] GET /
[2016-03-23 10:53:41 +0000] [18712] [DEBUG] GET /
[2016-03-23 10:53:42 +0000] [18712] [DEBUG] GET /
[2016-03-23 10:53:56 +0000] [18712] [DEBUG] GET /
[2016-03-23 10:53:57 +0000] [18712] [DEBUG] GET /
[2016-03-23 10:55:10 +0000] [18712] [INFO] Worker reloading: /home/tayfen/develop/stepic/web_apps/web/ask/qa/views.py modified
[2016-03-23 10:55:10 +0000] [18712] [INFO] Worker exiting (pid: 18712)
[2016-03-23 13:55:10 +0000] [18749] [INFO] Booting worker with pid: 18749
[2016-03-23 10:55:14 +0000] [18749] [DEBUG] GET /
[2016-03-23 10:55:14 +0000] [18749] [DEBUG] GET /
[2016-03-23 10:58:56 +0000] [18749] [INFO] Worker reloading: /home/tayfen/develop/stepic/web_apps/web/ask/qa/views.py modified
[2016-03-23 10:58:56 +0000] [18749] [INFO] Worker exiting (pid: 18749)
[2016-03-23 13:58:56 +0000] [18785] [INFO] Booting worker with pid: 18785
[2016-03-23 10:59:00 +0000] [18785] [DEBUG] GET /
[2016-03-23 10:59:01 +0000] [18785] [DEBUG] GET /
[2016-03-23 11:00:05 +0000] [18785] [INFO] Worker reloading: /home/tayfen/develop/stepic/web_apps/web/ask/qa/views.py modified
[2016-03-23 11:00:06 +0000] [18785] [INFO] Worker exiting (pid: 18785)
[2016-03-23 14:00:06 +0000] [18793] [INFO] Booting worker with pid: 18793
[2016-03-23 11:00:08 +0000] [18793] [DEBUG] GET /
[2016-03-23 11:00:10 +0000] [18793] [DEBUG] GET /
[2016-03-23 11:01:25 +0000] [18793] [DEBUG] GET /123
[2016-03-23 11:01:29 +0000] [18793] [DEBUG] GET /
[2016-03-23 11:02:09 +0000] [18793] [INFO] Worker reloading: /home/tayfen/develop/stepic/web_apps/web/ask/qa/views.py modified
[2016-03-23 11:02:09 +0000] [18793] [INFO] Worker exiting (pid: 18793)
[2016-03-23 14:02:09 +0000] [18799] [INFO] Booting worker with pid: 18799
[2016-03-23 11:02:24 +0000] [18799] [DEBUG] GET /
[2016-03-23 11:02:40 +0000] [18799] [DEBUG] GET /
[2016-03-23 11:02:48 +0000] [18799] [DEBUG] GET /
[2016-03-23 11:02:57 +0000] [18799] [DEBUG] GET /
[2016-03-23 11:07:38 +0000] [18799] [DEBUG] GET /
[2016-03-23 11:07:39 +0000] [18799] [DEBUG] GET /favicon.ico
[2016-03-23 11:17:17 +0000] [18799] [INFO] Worker reloading: /home/tayfen/develop/stepic/web_apps/web/ask/qa/views.py modified
[2016-03-23 11:17:17 +0000] [18799] [INFO] Worker exiting (pid: 18799)
[2016-03-23 14:17:17 +0000] [18955] [INFO] Booting worker with pid: 18955
[2016-03-23 11:17:22 +0000] [18955] [DEBUG] GET /
[2016-03-23 11:17:24 +0000] [18955] [DEBUG] GET /
[2016-03-23 11:18:23 +0000] [18955] [DEBUG] GET /
[2016-03-23 11:18:34 +0000] [18955] [INFO] Worker reloading: /home/tayfen/develop/stepic/web_apps/web/ask/qa/views.py modified
[2016-03-23 11:18:34 +0000] [18955] [INFO] Worker exiting (pid: 18955)
[2016-03-23 14:18:34 +0000] [18959] [INFO] Booting worker with pid: 18959
[2016-03-23 11:18:36 +0000] [18959] [DEBUG] GET /
[2016-03-23 11:18:41 +0000] [18959] [DEBUG] GET /
[2016-03-23 11:18:45 +0000] [18959] [DEBUG] GET /
[2016-03-23 11:18:48 +0000] [18959] [DEBUG] GET /
[2016-03-23 11:19:07 +0000] [18959] [DEBUG] GET /
[2016-03-23 11:26:50 +0000] [18959] [DEBUG] GET /
[2016-03-23 11:27:15 +0000] [18959] [DEBUG] GET /
[2016-03-23 11:27:45 +0000] [18959] [INFO] Worker reloading: /home/tayfen/develop/stepic/web_apps/web/ask/qa/views.py modified
[2016-03-23 11:27:45 +0000] [18959] [INFO] Worker exiting (pid: 18959)
[2016-03-23 14:27:45 +0000] [19051] [INFO] Booting worker with pid: 19051
[2016-03-23 11:27:47 +0000] [19051] [DEBUG] GET /
[2016-03-23 11:27:47 +0000] [19051] [DEBUG] GET /favicon.ico
[2016-03-23 11:28:03 +0000] [19051] [INFO] Worker reloading: /home/tayfen/develop/stepic/web_apps/web/ask/qa/views.py modified
[2016-03-23 11:28:03 +0000] [19051] [INFO] Worker exiting (pid: 19051)
[2016-03-23 14:28:03 +0000] [19054] [INFO] Booting worker with pid: 19054
[2016-03-23 11:28:05 +0000] [19054] [DEBUG] GET /
[2016-03-23 11:28:05 +0000] [19054] [DEBUG] GET /favicon.ico
[2016-03-23 11:28:09 +0000] [19054] [DEBUG] GET /question/4/
[2016-03-23 11:30:06 +0000] [19054] [INFO] Worker reloading: /home/tayfen/develop/stepic/web_apps/web/ask/qa/views.py modified
[2016-03-23 11:30:06 +0000] [19054] [INFO] Worker exiting (pid: 19054)
[2016-03-23 14:30:06 +0000] [19065] [INFO] Booting worker with pid: 19065
[2016-03-23 11:32:27 +0000] [19065] [DEBUG] GET /
[2016-03-23 11:32:29 +0000] [19065] [DEBUG] GET /
[2016-03-23 11:32:32 +0000] [19065] [DEBUG] GET /question/8/
[2016-03-23 11:32:35 +0000] [19065] [DEBUG] GET /question/8/
[2016-03-23 11:32:35 +0000] [19065] [DEBUG] GET /favicon.ico
[2016-03-23 11:32:35 +0000] [19065] [DEBUG] GET /question/8/
[2016-03-23 11:32:35 +0000] [19065] [DEBUG] GET /favicon.ico
[2016-03-23 11:32:43 +0000] [19065] [DEBUG] GET /question/1/
[2016-03-23 11:33:18 +0000] [19065] [DEBUG] GET /question/1/
[2016-03-23 11:33:18 +0000] [19065] [DEBUG] GET /favicon.ico
[2016-03-23 11:34:12 +0000] [19065] [DEBUG] GET /question/1/
[2016-03-23 11:34:13 +0000] [19065] [DEBUG] GET /favicon.ico
[2016-03-23 11:34:50 +0000] [19065] [DEBUG] GET /question/1/
[2016-03-23 11:34:50 +0000] [19065] [DEBUG] GET /favicon.ico
[2016-03-23 11:34:51 +0000] [19065] [DEBUG] GET /question/1/
[2016-03-23 11:34:51 +0000] [19065] [DEBUG] GET /favicon.ico
[2016-03-23 11:35:09 +0000] [19065] [DEBUG] GET /question/1/
[2016-03-23 11:35:09 +0000] [19065] [DEBUG] GET /favicon.ico
[2016-03-23 11:35:10 +0000] [19065] [DEBUG] GET /question/1/
[2016-03-23 11:35:10 +0000] [19065] [DEBUG] GET /favicon.ico
[2016-03-23 11:35:10 +0000] [19065] [DEBUG] GET /question/1/
[2016-03-23 11:35:10 +0000] [19065] [DEBUG] GET /favicon.ico
[2016-03-23 11:35:21 +0000] [19065] [DEBUG] GET /question/1/
[2016-03-23 11:35:21 +0000] [19065] [DEBUG] GET /favicon.ico
[2016-03-23 11:35:48 +0000] [19065] [DEBUG] GET /question/1/
[2016-03-23 11:35:48 +0000] [19065] [DEBUG] GET /favicon.ico
[2016-03-23 11:35:49 +0000] [19065] [DEBUG] GET /question/1/
[2016-03-23 11:35:49 +0000] [19065] [DEBUG] GET /favicon.ico
[2016-03-23 11:36:55 +0000] [19065] [INFO] Worker reloading: /home/tayfen/develop/stepic/web_apps/web/ask/qa/views.py modified
[2016-03-23 11:36:55 +0000] [19065] [INFO] Worker exiting (pid: 19065)
[2016-03-23 14:36:55 +0000] [19146] [INFO] Booting worker with pid: 19146
[2016-03-23 11:37:31 +0000] [19146] [DEBUG] GET /question/1/
[2016-03-23 11:37:32 +0000] [19146] [DEBUG] GET /favicon.ico
[2016-03-23 11:37:49 +0000] [19146] [INFO] Worker reloading: /home/tayfen/develop/stepic/web_apps/web/ask/qa/views.py modified
[2016-03-23 11:37:49 +0000] [19146] [INFO] Worker exiting (pid: 19146)
[2016-03-23 14:37:49 +0000] [19156] [INFO] Booting worker with pid: 19156
[2016-03-23 11:37:51 +0000] [19156] [DEBUG] GET /question/1/
[2016-03-23 11:37:51 +0000] [19156] [DEBUG] GET /favicon.ico
[2016-03-23 11:37:52 +0000] [19156] [DEBUG] GET /question/1/
[2016-03-23 11:37:52 +0000] [19156] [DEBUG] GET /favicon.ico
[2016-03-23 11:38:00 +0000] [19156] [INFO] Worker reloading: /home/tayfen/develop/stepic/web_apps/web/ask/qa/views.py modified
[2016-03-23 11:38:00 +0000] [19156] [INFO] Worker exiting (pid: 19156)
[2016-03-23 14:38:00 +0000] [19159] [INFO] Booting worker with pid: 19159
[2016-03-23 11:42:17 +0000] [19159] [DEBUG] GET /question/1/
[2016-03-23 11:42:17 +0000] [19159] [DEBUG] GET /favicon.ico
[2016-03-23 11:42:27 +0000] [19159] [INFO] Worker reloading: /home/tayfen/develop/stepic/web_apps/web/ask/qa/views.py modified
[2016-03-23 11:42:27 +0000] [19159] [INFO] Worker exiting (pid: 19159)
[2016-03-23 14:42:27 +0000] [19198] [INFO] Booting worker with pid: 19198
[2016-03-23 11:42:30 +0000] [19198] [DEBUG] GET /question/1/
[2016-03-23 11:42:30 +0000] [19198] [DEBUG] GET /favicon.ico
[2016-03-23 11:42:31 +0000] [19198] [DEBUG] GET /question/1/
[2016-03-23 11:42:31 +0000] [19198] [DEBUG] GET /favicon.ico
[2016-03-23 12:14:39 +0000] [19198] [INFO] Worker reloading: /home/tayfen/develop/stepic/web_apps/web/ask/qa/views.py modified
[2016-03-23 12:14:39 +0000] [19198] [INFO] Worker exiting (pid: 19198)
[2016-03-23 15:14:39 +0000] [19345] [INFO] Booting worker with pid: 19345
[2016-03-23 12:17:24 +0000] [19345] [DEBUG] GET /question/1/
[2016-03-23 12:17:24 +0000] [19345] [DEBUG] GET /favicon.ico
[2016-03-23 12:17:25 +0000] [19345] [DEBUG] GET /question/1/
[2016-03-23 12:17:25 +0000] [19345] [DEBUG] GET /favicon.ico
[2016-03-23 12:18:23 +0000] [19345] [INFO] Worker reloading: /home/tayfen/develop/stepic/web_apps/web/ask/qa/views.py modified
[2016-03-23 12:18:23 +0000] [19345] [INFO] Worker exiting (pid: 19345)
[2016-03-23 15:18:23 +0000] [19391] [INFO] Booting worker with pid: 19391
[2016-03-23 12:18:28 +0000] [19391] [DEBUG] GET /question/1/
[2016-03-23 12:18:29 +0000] [19391] [DEBUG] GET /favicon.ico
[2016-03-23 12:18:29 +0000] [19391] [DEBUG] GET /question/1/
[2016-03-23 12:18:29 +0000] [19391] [DEBUG] GET /favicon.ico
[2016-03-23 12:18:40 +0000] [19391] [INFO] Worker reloading: /home/tayfen/develop/stepic/web_apps/web/ask/qa/views.py modified
[2016-03-23 12:18:40 +0000] [19391] [INFO] Worker exiting (pid: 19391)
[2016-03-23 15:18:40 +0000] [19394] [INFO] Booting worker with pid: 19394
[2016-03-23 12:18:42 +0000] [19394] [DEBUG] GET /question/1/
[2016-03-23 12:18:42 +0000] [19394] [DEBUG] GET /favicon.ico
[2016-03-23 12:18:42 +0000] [19394] [DEBUG] GET /question/1/
[2016-03-23 12:18:42 +0000] [19394] [DEBUG] GET /favicon.ico
[2016-03-23 12:19:20 +0000] [19394] [INFO] Worker reloading: /home/tayfen/develop/stepic/web_apps/web/ask/qa/views.py modified
[2016-03-23 12:19:20 +0000] [19394] [INFO] Worker exiting (pid: 19394)
[2016-03-23 15:19:20 +0000] [19400] [INFO] Booting worker with pid: 19400
[2016-03-23 12:19:22 +0000] [19400] [DEBUG] GET /question/1/
[2016-03-23 12:19:22 +0000] [19400] [DEBUG] GET /favicon.ico
[2016-03-23 12:22:09 +0000] [19400] [INFO] Worker reloading: /home/tayfen/develop/stepic/web_apps/web/ask/qa/views.py modified
[2016-03-23 12:22:09 +0000] [19400] [INFO] Worker exiting (pid: 19400)
[2016-03-23 15:22:09 +0000] [19412] [INFO] Booting worker with pid: 19412
[2016-03-23 12:22:11 +0000] [19412] [DEBUG] GET /question/1/
[2016-03-23 12:22:11 +0000] [19412] [DEBUG] GET /favicon.ico
[2016-03-23 12:22:12 +0000] [19412] [DEBUG] GET /question/1/
[2016-03-23 12:22:12 +0000] [19412] [DEBUG] GET /favicon.ico
[2016-03-23 12:22:12 +0000] [19412] [DEBUG] GET /question/1/
[2016-03-23 12:22:12 +0000] [19412] [DEBUG] GET /favicon.ico
[2016-03-23 12:22:13 +0000] [19412] [DEBUG] GET /question/1/
[2016-03-23 12:22:13 +0000] [19412] [DEBUG] GET /favicon.ico
[2016-03-23 12:22:13 +0000] [19412] [DEBUG] GET /question/1/
[2016-03-23 12:22:13 +0000] [19412] [DEBUG] GET /favicon.ico
[2016-03-23 12:22:13 +0000] [19412] [DEBUG] GET /question/1/
[2016-03-23 12:22:13 +0000] [19412] [DEBUG] GET /favicon.ico
[2016-03-23 12:22:18 +0000] [19412] [DEBUG] GET /question/1/
[2016-03-23 12:22:18 +0000] [19412] [DEBUG] GET /favicon.ico
[2016-03-23 12:22:19 +0000] [19412] [DEBUG] GET /question/1/
[2016-03-23 12:22:19 +0000] [19412] [DEBUG] GET /favicon.ico
[2016-03-23 12:22:19 +0000] [19412] [DEBUG] GET /question/1/
[2016-03-23 12:22:19 +0000] [19412] [DEBUG] GET /favicon.ico
[2016-03-23 12:22:31 +0000] [19412] [INFO] Worker reloading: /home/tayfen/develop/stepic/web_apps/web/ask/qa/views.py modified
[2016-03-23 12:22:31 +0000] [19412] [INFO] Worker exiting (pid: 19412)
[2016-03-23 15:22:31 +0000] [19417] [INFO] Booting worker with pid: 19417
[2016-03-23 12:22:32 +0000] [19417] [DEBUG] GET /question/1/
[2016-03-23 12:22:32 +0000] [19417] [DEBUG] GET /favicon.ico
[2016-03-23 12:22:39 +0000] [19417] [INFO] Worker reloading: /home/tayfen/develop/stepic/web_apps/web/ask/qa/views.py modified
[2016-03-23 12:22:39 +0000] [19417] [INFO] Worker exiting (pid: 19417)
[2016-03-23 15:22:39 +0000] [19420] [INFO] Booting worker with pid: 19420
[2016-03-23 12:22:42 +0000] [19420] [DEBUG] GET /question/1/
[2016-03-23 12:22:42 +0000] [19420] [DEBUG] GET /favicon.ico
[2016-03-23 12:22:43 +0000] [19420] [DEBUG] GET /question/1/
[2016-03-23 12:22:43 +0000] [19420] [DEBUG] GET /favicon.ico
[2016-03-23 12:23:28 +0000] [19420] [INFO] Worker reloading: /home/tayfen/develop/stepic/web_apps/web/ask/qa/views.py modified
[2016-03-23 12:23:28 +0000] [19420] [INFO] Worker exiting (pid: 19420)
[2016-03-23 15:23:28 +0000] [19426] [INFO] Booting worker with pid: 19426
[2016-03-23 12:23:31 +0000] [19426] [DEBUG] GET /question/1/
[2016-03-23 12:23:31 +0000] [19426] [DEBUG] GET /favicon.ico
[2016-03-23 12:25:35 +0000] [19426] [INFO] Worker reloading: /home/tayfen/develop/stepic/web_apps/web/ask/qa/views.py modified
[2016-03-23 12:25:36 +0000] [19426] [INFO] Worker exiting (pid: 19426)
[2016-03-23 15:25:36 +0000] [19434] [INFO] Booting worker with pid: 19434
[2016-03-23 12:26:57 +0000] [19434] [DEBUG] GET /question/1/
[2016-03-23 12:26:57 +0000] [19434] [DEBUG] GET /favicon.ico
[2016-03-23 12:27:20 +0000] [19434] [INFO] Worker reloading: /home/tayfen/develop/stepic/web_apps/web/ask/qa/views.py modified
[2016-03-23 12:27:20 +0000] [19434] [INFO] Worker exiting (pid: 19434)
[2016-03-23 15:27:20 +0000] [19439] [INFO] Booting worker with pid: 19439
[2016-03-23 12:27:21 +0000] [19439] [DEBUG] GET /question/1/
[2016-03-23 12:27:22 +0000] [19439] [DEBUG] GET /favicon.ico
[2016-03-23 12:27:34 +0000] [19439] [DEBUG] GET /question/2/
[2016-03-23 12:28:03 +0000] [19439] [DEBUG] GET /question/7/
[2016-03-23 12:28:16 +0000] [19439] [DEBUG] GET /question/6/
[2016-03-23 12:28:22 +0000] [19439] [DEBUG] GET /question/3/
[2016-03-23 12:30:32 +0000] [19439] [DEBUG] GET /question/2/
[2016-03-23 12:30:32 +0000] [19439] [DEBUG] GET /favicon.ico
[2016-03-23 12:35:48 +0000] [19439] [INFO] Worker reloading: /home/tayfen/develop/stepic/web_apps/web/ask/qa/views.py modified
[2016-03-23 12:35:48 +0000] [19439] [INFO] Worker exiting (pid: 19439)
[2016-03-23 15:35:48 +0000] [19461] [INFO] Booting worker with pid: 19461
[2016-03-23 12:35:56 +0000] [19461] [DEBUG] GET /question/2/
[2016-03-23 12:35:56 +0000] [19461] [DEBUG] GET /favicon.ico
[2016-03-23 12:35:57 +0000] [19461] [DEBUG] GET /question/2/
[2016-03-23 12:35:57 +0000] [19461] [DEBUG] GET /favicon.ico
[2016-03-23 12:36:08 +0000] [19461] [INFO] Worker reloading: /home/tayfen/develop/stepic/web_apps/web/ask/qa/views.py modified
[2016-03-23 12:36:08 +0000] [19461] [INFO] Worker exiting (pid: 19461)
[2016-03-23 15:36:08 +0000] [19464] [INFO] Booting worker with pid: 19464
[2016-03-23 12:36:13 +0000] [19464] [DEBUG] GET /question/2/
[2016-03-23 12:36:13 +0000] [19464] [DEBUG] GET /favicon.ico
[2016-03-23 12:36:14 +0000] [19464] [DEBUG] GET /question/2/
[2016-03-23 12:36:14 +0000] [19464] [DEBUG] GET /favicon.ico
[2016-03-23 12:36:46 +0000] [19464] [DEBUG] GET /question/2/
[2016-03-23 12:36:46 +0000] [19464] [DEBUG] GET /favicon.ico
[2016-03-23 12:36:47 +0000] [19464] [DEBUG] GET /question/2/
[2016-03-23 12:36:47 +0000] [19464] [DEBUG] GET /favicon.ico
[2016-03-23 12:37:36 +0000] [19464] [DEBUG] GET /question/2/
[2016-03-23 12:37:37 +0000] [19464] [DEBUG] GET /favicon.ico
[2016-03-23 12:37:37 +0000] [19464] [DEBUG] GET /question/2/
[2016-03-23 12:37:37 +0000] [19464] [DEBUG] GET /favicon.ico
[2016-03-23 12:37:37 +0000] [19464] [DEBUG] GET /question/2/
[2016-03-23 12:37:37 +0000] [19464] [DEBUG] GET /favicon.ico
[2016-03-23 12:37:38 +0000] [19464] [DEBUG] GET /question/2/
[2016-03-23 12:37:38 +0000] [19464] [DEBUG] GET /favicon.ico
[2016-03-23 12:38:21 +0000] [19464] [DEBUG] GET /question/2/
[2016-03-23 12:38:21 +0000] [19464] [DEBUG] GET /favicon.ico
[2016-03-23 12:38:33 +0000] [19464] [DEBUG] GET /
[2016-03-23 12:40:25 +0000] [19464] [INFO] Worker reloading: /home/tayfen/develop/stepic/web_apps/web/ask/qa/views.py modified
[2016-03-23 12:40:26 +0000] [19464] [INFO] Worker exiting (pid: 19464)
[2016-03-23 15:40:26 +0000] [19506] [INFO] Booting worker with pid: 19506
[2016-03-23 12:40:28 +0000] [19506] [DEBUG] GET /
[2016-03-23 12:40:28 +0000] [19506] [DEBUG] GET /favicon.ico
[2016-03-23 12:40:38 +0000] [19506] [DEBUG] GET /qa/
[2016-03-23 12:41:44 +0000] [19506] [INFO] Worker reloading: /home/tayfen/develop/stepic/web_apps/web/ask/qa/views.py modified
[2016-03-23 12:41:44 +0000] [19506] [INFO] Worker exiting (pid: 19506)
[2016-03-23 15:41:44 +0000] [19514] [INFO] Booting worker with pid: 19514
[2016-03-23 12:42:14 +0000] [19514] [DEBUG] GET /popular/
[2016-03-23 13:18:13 +0000] [19514] [INFO] Worker reloading: /home/tayfen/develop/stepic/web_apps/web/ask/qa/models.py modified
[2016-03-23 13:18:13 +0000] [19514] [INFO] Worker exiting (pid: 19514)
[2016-03-23 16:18:13 +0000] [19664] [INFO] Booting worker with pid: 19664
[2016-03-23 13:36:14 +0000] [19664] [DEBUG] GET /hit
[2016-03-23 13:36:14 +0000] [19664] [DEBUG] GET /ga.js
[2016-03-23 13:38:11 +0000] [19664] [INFO] Worker reloading: /home/tayfen/develop/stepic/web_apps/web/ask/qa/views.py modified
[2016-03-23 13:38:11 +0000] [19664] [INFO] Worker exiting (pid: 19664)
[2016-03-23 16:38:11 +0000] [19841] [INFO] Booting worker with pid: 19841
[2016-03-23 13:38:18 +0000] [19841] [DEBUG] GET /question/2/
[2016-03-23 13:40:26 +0000] [19841] [INFO] Worker reloading: /home/tayfen/develop/stepic/web_apps/web/ask/qa/views.py modified
[2016-03-23 13:40:26 +0000] [19841] [INFO] Worker exiting (pid: 19841)
[2016-03-23 16:40:26 +0000] [19848] [INFO] Booting worker with pid: 19848
[2016-03-23 13:40:27 +0000] [19848] [DEBUG] GET /question/2/
[2016-03-23 13:40:28 +0000] [19848] [DEBUG] GET /favicon.ico
[2016-03-23 13:40:28 +0000] [19848] [DEBUG] GET /question/2/
[2016-03-23 13:40:28 +0000] [19848] [DEBUG] GET /favicon.ico
[2016-03-23 13:41:41 +0000] [19848] [INFO] Worker reloading: /home/tayfen/develop/stepic/web_apps/web/ask/qa/views.py modified
[2016-03-23 13:41:41 +0000] [19848] [INFO] Worker exiting (pid: 19848)
[2016-03-23 16:41:41 +0000] [19856] [INFO] Booting worker with pid: 19856
[2016-03-23 13:41:43 +0000] [19856] [DEBUG] GET /question/2/
[2016-03-23 13:41:43 +0000] [19856] [DEBUG] GET /favicon.ico
[2016-03-23 13:41:44 +0000] [19856] [DEBUG] GET /question/2/
[2016-03-23 13:41:45 +0000] [19856] [DEBUG] GET /favicon.ico
[2016-03-23 14:24:19 +0000] [19856] [DEBUG] GET /csi
[2016-03-23 14:52:22 +0000] [19856] [INFO] Worker reloading: /home/tayfen/develop/stepic/web_apps/web/ask/qa/views.py modified
[2016-03-23 14:52:22 +0000] [19856] [INFO] Worker exiting (pid: 19856)
[2016-03-23 17:52:22 +0000] [20390] [INFO] Booting worker with pid: 20390
[2016-03-23 14:52:30 +0000] [20390] [DEBUG] GET /question/12/
[2016-03-23 14:52:59 +0000] [20390] [INFO] Worker reloading: /home/tayfen/develop/stepic/web_apps/web/ask/qa/views.py modified
[2016-03-23 14:52:59 +0000] [20390] [INFO] Worker exiting (pid: 20390)
[2016-03-23 17:52:59 +0000] [20424] [INFO] Booting worker with pid: 20424
[2016-03-23 14:53:01 +0000] [20424] [DEBUG] GET /question/12/
[2016-03-23 14:53:02 +0000] [20424] [DEBUG] GET /question/12/
[2016-03-23 14:53:40 +0000] [20424] [DEBUG] GET /question/12/
[2016-03-23 14:53:41 +0000] [20424] [DEBUG] GET /question/12/
[2016-03-23 14:54:27 +0000] [20424] [DEBUG] GET /question/12/
[2016-03-23 14:54:28 +0000] [20424] [DEBUG] GET /question/12/
[2016-03-23 14:54:33 +0000] [20424] [DEBUG] GET /question/1/
[2016-03-23 14:58:33 +0000] [20424] [INFO] Worker reloading: /home/tayfen/develop/stepic/web_apps/web/ask/ask/urls.py modified
[2016-03-23 14:58:33 +0000] [20424] [INFO] Worker exiting (pid: 20424)
[2016-03-23 17:58:33 +0000] [20474] [INFO] Booting worker with pid: 20474
[2016-03-23 15:05:39 +0000] [20474] [DEBUG] GET /ask/
[2016-03-23 15:06:16 +0000] [20474] [INFO] Worker reloading: /home/tayfen/develop/stepic/web_apps/web/ask/qa/views.py modified
[2016-03-23 15:06:16 +0000] [20474] [INFO] Worker exiting (pid: 20474)
[2016-03-23 18:06:16 +0000] [20608] [INFO] Booting worker with pid: 20608
[2016-03-23 15:06:19 +0000] [20608] [DEBUG] GET /ask/
[2016-03-23 15:07:09 +0000] [20608] [INFO] Worker reloading: /home/tayfen/develop/stepic/web_apps/web/ask/qa/views.py modified
[2016-03-23 15:07:09 +0000] [20608] [INFO] Worker exiting (pid: 20608)
[2016-03-23 18:07:09 +0000] [20619] [INFO] Booting worker with pid: 20619
[2016-03-23 15:07:11 +0000] [20619] [DEBUG] GET /ask/
[2016-03-23 15:08:17 +0000] [20619] [INFO] Worker reloading: /home/tayfen/develop/stepic/web_apps/web/ask/qa/views.py modified
[2016-03-23 15:08:17 +0000] [20619] [INFO] Worker exiting (pid: 20619)
[2016-03-23 18:08:17 +0000] [20630] [INFO] Booting worker with pid: 20630
[2016-03-23 15:08:21 +0000] [20630] [DEBUG] GET /ask/
[2016-03-23 15:09:20 +0000] [20630] [INFO] Worker reloading: /home/tayfen/develop/stepic/web_apps/web/ask/qa/views.py modified
[2016-03-23 15:09:20 +0000] [20630] [INFO] Worker exiting (pid: 20630)
[2016-03-23 18:09:20 +0000] [20641] [INFO] Booting worker with pid: 20641
[2016-03-23 15:09:22 +0000] [20641] [DEBUG] GET /ask/
[2016-03-23 15:10:36 +0000] [20641] [DEBUG] POST /
[2016-03-23 15:12:45 +0000] [20641] [DEBUG] GET /
[2016-03-23 15:15:22 +0000] [20641] [DEBUG] GET /hit.xiti
[2016-03-23 15:15:22 +0000] [20641] [DEBUG] GET /hit.xiti
[2016-03-23 15:15:22 +0000] [20641] [DEBUG] GET /hit.xiti
[2016-03-23 15:15:22 +0000] [20641] [DEBUG] GET /hit.xiti
[2016-03-23 15:15:22 +0000] [20641] [DEBUG] GET /hit.xiti
[2016-03-23 15:15:22 +0000] [20641] [DEBUG] GET /hit.xiti
[2016-03-23 15:15:22 +0000] [20641] [DEBUG] GET /hit.xiti
[2016-03-23 15:15:22 +0000] [20641] [DEBUG] GET /hit.xiti
[2016-03-23 15:15:22 +0000] [20641] [DEBUG] GET /hit.xiti
[2016-03-23 15:15:22 +0000] [20641] [DEBUG] GET /hit.xiti
[2016-03-23 15:15:22 +0000] [20641] [DEBUG] GET /hit.xiti
[2016-03-23 15:15:22 +0000] [20641] [DEBUG] GET /hit.xiti
[2016-03-23 15:15:22 +0000] [20641] [DEBUG] GET /hit.xiti
[2016-03-23 15:15:22 +0000] [20641] [DEBUG] GET /hit.xiti
[2016-03-23 15:15:22 +0000] [20641] [DEBUG] GET /hit.xiti
[2016-03-23 15:15:22 +0000] [20641] [DEBUG] GET /hit.xiti
[2016-03-23 15:15:22 +0000] [20641] [DEBUG] GET /hit.xiti
[2016-03-23 15:15:22 +0000] [20641] [DEBUG] GET /hit.xiti
[2016-03-23 15:15:22 +0000] [20641] [DEBUG] GET /hit.xiti
[2016-03-23 15:15:22 +0000] [20641] [DEBUG] GET /hit.xiti
[2016-03-23 15:15:22 +0000] [20641] [DEBUG] GET /hit.xiti
[2016-03-23 15:15:22 +0000] [20641] [DEBUG] GET /hit.xiti
[2016-03-23 15:15:22 +0000] [20641] [DEBUG] GET /hit.xiti
[2016-03-23 15:15:22 +0000] [20641] [DEBUG] GET /hit.xiti
[2016-03-23 15:15:22 +0000] [20641] [DEBUG] GET /hit.xiti
[2016-03-23 15:15:22 +0000] [20641] [DEBUG] GET /hit.xiti
[2016-03-23 15:15:22 +0000] [20641] [DEBUG] GET /hit.xiti
[2016-03-23 15:15:22 +0000] [20641] [DEBUG] GET /hit.xiti
[2016-03-23 15:15:22 +0000] [20641] [DEBUG] GET /hit.xiti
[2016-03-23 15:15:22 +0000] [20641] [DEBUG] GET /hit.xiti
[2016-03-23 15:15:22 +0000] [20641] [DEBUG] GET /hit.xiti
[2016-03-23 15:15:22 +0000] [20641] [DEBUG] GET /hit.xiti
[2016-03-23 15:15:22 +0000] [20641] [DEBUG] GET /hit.xiti
[2016-03-23 15:15:22 +0000] [20641] [DEBUG] GET /hit.xiti
[2016-03-23 15:15:22 +0000] [20641] [DEBUG] GET /hit.xiti
[2016-03-23 15:15:22 +0000] [20641] [DEBUG] GET /hit.xiti
[2016-03-23 15:15:22 +0000] [20641] [DEBUG] GET /hit.xiti
[2016-03-23 15:15:22 +0000] [20641] [DEBUG] GET /hit.xiti
[2016-03-23 15:15:22 +0000] [20641] [DEBUG] GET /hit.xiti
[2016-03-23 15:15:22 +0000] [20641] [DEBUG] GET /hit.xiti
[2016-03-23 15:15:22 +0000] [20641] [DEBUG] GET /hit.xiti
[2016-03-23 15:15:22 +0000] [20641] [DEBUG] GET /hit.xiti
[2016-03-23 15:15:22 +0000] [20641] [DEBUG] GET /hit.xiti
[2016-03-23 15:15:22 +0000] [20641] [DEBUG] GET /hit.xiti
[2016-03-23 15:15:22 +0000] [20641] [DEBUG] GET /hit.xiti
[2016-03-23 15:15:22 +0000] [20641] [DEBUG] GET /hit.xiti
[2016-03-23 15:15:22 +0000] [20641] [DEBUG] GET /hit.xiti
[2016-03-23 15:15:22 +0000] [20641] [DEBUG] GET /hit.xiti
[2016-03-23 15:15:22 +0000] [20641] [DEBUG] GET /hit.xiti
[2016-03-23 15:15:22 +0000] [20641] [DEBUG] GET /hit.xiti
[2016-03-23 15:15:22 +0000] [20641] [DEBUG] GET /hit.xiti
[2016-03-23 15:15:22 +0000] [20641] [DEBUG] GET /hit.xiti
[2016-03-23 15:15:22 +0000] [20641] [DEBUG] GET /hit.xiti
[2016-03-23 15:15:22 +0000] [20641] [DEBUG] GET /hit.xiti
[2016-03-23 15:15:22 +0000] [20641] [DEBUG] GET /hit.xiti
[2016-03-23 15:15:22 +0000] [20641] [DEBUG] GET /hit.xiti
[2016-03-23 15:15:22 +0000] [20641] [DEBUG] GET /hit.xiti
[2016-03-23 15:16:06 +0000] [20641] [DEBUG] GET /hit.xiti
[2016-03-23 15:16:16 +0000] [20641] [DEBUG] GET /hit.xiti
[2016-03-23 15:20:52 +0000] [20641] [INFO] Worker reloading: /home/tayfen/develop/stepic/web_apps/web/ask/qa/views.py modified
[2016-03-23 15:20:52 +0000] [20641] [INFO] Worker exiting (pid: 20641)
[2016-03-23 18:20:52 +0000] [20771] [INFO] Booting worker with pid: 20771
[2016-03-23 15:20:59 +0000] [20771] [DEBUG] POST /
[2016-03-23 15:22:23 +0000] [20771] [DEBUG] GET /Advertisers/9d2ba713e72d49af82df244e4478c204.jpg
[2016-03-23 15:27:00 +0000] [20771] [INFO] Worker reloading: /home/tayfen/develop/stepic/web_apps/web/ask/qa/views.py modified
[2016-03-23 15:27:00 +0000] [20771] [INFO] Worker exiting (pid: 20771)
[2016-03-23 18:27:00 +0000] [20826] [INFO] Booting worker with pid: 20826
[2016-03-23 15:27:29 +0000] [20826] [DEBUG] POST /
[2016-03-23 15:27:55 +0000] [20826] [DEBUG] POST /ask/
[2016-03-23 15:28:39 +0000] [20826] [INFO] Worker reloading: /home/tayfen/develop/stepic/web_apps/web/ask/qa/views.py modified
[2016-03-23 15:28:39 +0000] [20826] [INFO] Worker exiting (pid: 20826)
[2016-03-23 18:28:39 +0000] [20841] [INFO] Booting worker with pid: 20841
[2016-03-23 15:28:43 +0000] [20841] [DEBUG] POST /ask/
[2016-03-23 15:28:50 +0000] [20841] [INFO] Worker reloading: /home/tayfen/develop/stepic/web_apps/web/ask/qa/views.py modified
[2016-03-23 15:28:50 +0000] [20841] [INFO] Worker exiting (pid: 20841)
[2016-03-23 18:28:50 +0000] [20852] [INFO] Booting worker with pid: 20852
[2016-03-23 15:28:52 +0000] [20852] [DEBUG] POST /ask/
[2016-03-23 15:28:53 +0000] [20852] [DEBUG] POST /ask/
[2016-03-23 15:29:31 +0000] [20852] [DEBUG] GET /ask/
[2016-03-23 15:29:56 +0000] [20852] [DEBUG] POST /ask/
[2016-03-23 15:30:07 +0000] [20852] [DEBUG] POST /ask/
[2016-03-23 15:30:51 +0000] [20852] [INFO] Worker reloading: /home/tayfen/develop/stepic/web_apps/web/ask/qa/views.py modified
[2016-03-23 15:30:51 +0000] [20852] [INFO] Worker exiting (pid: 20852)
[2016-03-23 18:30:51 +0000] [20864] [INFO] Booting worker with pid: 20864
[2016-03-23 15:30:56 +0000] [20864] [DEBUG] POST /ask/
[2016-03-23 15:31:01 +0000] [20864] [DEBUG] POST /ask/
[2016-03-23 15:31:21 +0000] [20864] [DEBUG] POST /ask/
[2016-03-23 15:32:17 +0000] [20864] [INFO] Worker reloading: /home/tayfen/develop/stepic/web_apps/web/ask/qa/views.py modified
[2016-03-23 15:32:18 +0000] [20864] [INFO] Worker exiting (pid: 20864)
[2016-03-23 18:32:18 +0000] [20880] [INFO] Booting worker with pid: 20880
[2016-03-23 15:32:31 +0000] [20880] [DEBUG] POST /ask/
[2016-03-23 15:32:43 +0000] [20880] [INFO] Worker reloading: /home/tayfen/develop/stepic/web_apps/web/ask/qa/views.py modified
[2016-03-23 15:32:43 +0000] [20880] [INFO] Worker exiting (pid: 20880)
[2016-03-23 18:32:43 +0000] [20896] [INFO] Booting worker with pid: 20896
[2016-03-23 15:32:45 +0000] [20896] [DEBUG] POST /ask/
[2016-03-23 15:38:23 +0000] [20896] [INFO] Worker reloading: /home/tayfen/develop/stepic/web_apps/web/ask/qa/views.py modified
[2016-03-23 15:38:23 +0000] [20896] [INFO] Worker exiting (pid: 20896)
[2016-03-23 18:38:23 +0000] [21005] [INFO] Booting worker with pid: 21005
[2016-03-23 15:38:46 +0000] [21005] [DEBUG] GET /ask/
[2016-03-23 15:39:22 +0000] [21005] [INFO] Worker reloading: /home/tayfen/develop/stepic/web_apps/web/ask/qa/views.py modified
[2016-03-23 15:39:22 +0000] [21005] [INFO] Worker exiting (pid: 21005)
[2016-03-23 18:39:22 +0000] [21038] [INFO] Booting worker with pid: 21038
[2016-03-23 15:39:34 +0000] [21038] [DEBUG] GET /ask/
[2016-03-23 15:44:23 +0000] [21038] [INFO] Worker reloading: /home/tayfen/develop/stepic/web_apps/web/ask/qa/views.py modified
[2016-03-23 15:44:23 +0000] [21038] [INFO] Worker exiting (pid: 21038)
[2016-03-23 18:44:23 +0000] [21072] [INFO] Booting worker with pid: 21072
[2016-03-23 15:44:28 +0000] [21072] [DEBUG] GET /ask/
[2016-03-23 15:47:24 +0000] [21072] [INFO] Worker reloading: /home/tayfen/develop/stepic/web_apps/web/ask/qa/views.py modified
[2016-03-23 15:47:24 +0000] [21072] [INFO] Worker exiting (pid: 21072)
[2016-03-23 18:47:24 +0000] [21089] [INFO] Booting worker with pid: 21089
[2016-03-23 15:47:30 +0000] [21089] [DEBUG] GET /ask/
[2016-03-23 15:47:32 +0000] [21089] [DEBUG] GET /ask/
[2016-03-23 15:49:10 +0000] [21089] [INFO] Worker reloading: /home/tayfen/develop/stepic/web_apps/web/ask/qa/views.py modified
[2016-03-23 15:49:10 +0000] [21089] [INFO] Worker exiting (pid: 21089)
[2016-03-23 18:49:10 +0000] [21098] [INFO] Booting worker with pid: 21098
[2016-03-23 15:49:21 +0000] [21098] [DEBUG] GET /ask/
[2016-03-23 15:49:22 +0000] [21098] [DEBUG] GET /ask/
[2016-03-23 15:49:45 +0000] [21098] [DEBUG] GET /ask/
[2016-03-23 15:50:36 +0000] [21098] [INFO] Worker reloading: /home/tayfen/develop/stepic/web_apps/web/ask/qa/views.py modified
[2016-03-23 15:50:36 +0000] [21098] [INFO] Worker exiting (pid: 21098)
[2016-03-23 18:50:36 +0000] [21126] [INFO] Booting worker with pid: 21126
[2016-03-23 15:50:38 +0000] [21126] [DEBUG] GET /ask/
[2016-03-23 15:50:51 +0000] [21126] [DEBUG] GET /
[2016-03-23 15:50:59 +0000] [21126] [DEBUG] GET /
[2016-03-23 15:51:01 +0000] [21126] [DEBUG] GET /
[2016-03-23 15:51:01 +0000] [21126] [DEBUG] GET /
[2016-03-23 15:51:04 +0000] [21126] [DEBUG] GET /
[2016-03-23 15:51:07 +0000] [21126] [DEBUG] GET /
[2016-03-23 15:51:39 +0000] [21126] [INFO] Worker reloading: /home/tayfen/develop/stepic/web_apps/web/ask/qa/views.py modified
[2016-03-23 15:51:39 +0000] [21126] [INFO] Worker exiting (pid: 21126)
[2016-03-23 18:51:39 +0000] [21145] [INFO] Booting worker with pid: 21145
[2016-03-23 15:51:57 +0000] [21145] [DEBUG] GET /ask/
[2016-03-23 15:54:21 +0000] [21145] [INFO] Worker reloading: /home/tayfen/develop/stepic/web_apps/web/ask/qa/forms.py modified
[2016-03-23 15:54:21 +0000] [21145] [INFO] Worker exiting (pid: 21145)
[2016-03-23 18:54:21 +0000] [21160] [INFO] Booting worker with pid: 21160
[2016-03-23 15:54:54 +0000] [21160] [DEBUG] GET /ask/
[2016-03-23 15:55:10 +0000] [21160] [DEBUG] GET /ask/
[2016-03-23 15:55:52 +0000] [21160] [INFO] Worker reloading: /home/tayfen/develop/stepic/web_apps/web/ask/qa/views.py modified
[2016-03-23 15:55:52 +0000] [21160] [INFO] Worker exiting (pid: 21160)
[2016-03-23 18:55:52 +0000] [21180] [INFO] Booting worker with pid: 21180
[2016-03-23 15:55:54 +0000] [21180] [DEBUG] GET /ask/
[2016-03-23 15:57:20 +0000] [21180] [INFO] Worker reloading: /home/tayfen/develop/stepic/web_apps/web/ask/qa/forms.py modified
[2016-03-23 15:57:20 +0000] [21180] [INFO] Worker exiting (pid: 21180)
[2016-03-23 18:57:20 +0000] [21191] [INFO] Booting worker with pid: 21191
[2016-03-23 15:57:25 +0000] [21191] [DEBUG] GET /ask/
[2016-03-23 15:57:26 +0000] [21191] [DEBUG] GET /ask/
[2016-03-23 15:58:52 +0000] [21191] [INFO] Worker reloading: /home/tayfen/develop/stepic/web_apps/web/ask/qa/forms.py modified
[2016-03-23 15:58:52 +0000] [21191] [INFO] Worker exiting (pid: 21191)
[2016-03-23 18:58:52 +0000] [21202] [INFO] Booting worker with pid: 21202
[2016-03-23 15:58:54 +0000] [21202] [DEBUG] GET /ask/
[2016-03-23 15:58:54 +0000] [21202] [DEBUG] GET /ask/
[2016-03-23 15:58:55 +0000] [21202] [DEBUG] GET /ask/
[2016-03-23 15:58:56 +0000] [21202] [DEBUG] GET /ask/
[2016-03-23 15:59:21 +0000] [21202] [INFO] Worker reloading: /home/tayfen/develop/stepic/web_apps/web/ask/qa/forms.py modified
[2016-03-23 15:59:21 +0000] [21202] [INFO] Worker exiting (pid: 21202)
[2016-03-23 18:59:21 +0000] [21213] [INFO] Booting worker with pid: 21213
[2016-03-23 15:59:22 +0000] [21213] [DEBUG] GET /ask/
[2016-03-23 15:59:23 +0000] [21213] [DEBUG] GET /ask/
[2016-03-23 16:01:11 +0000] [21213] [INFO] Worker reloading: /home/tayfen/develop/stepic/web_apps/web/ask/qa/forms.py modified
[2016-03-23 16:01:11 +0000] [21213] [INFO] Worker exiting (pid: 21213)
[2016-03-23 19:01:11 +0000] [21223] [INFO] Booting worker with pid: 21223
[2016-03-23 16:08:16 +0000] [21223] [DEBUG] GET /ask/
[2016-03-23 16:08:52 +0000] [21223] [INFO] Worker reloading: /home/tayfen/develop/stepic/web_apps/web/ask/qa/forms.py modified
[2016-03-23 16:08:52 +0000] [21223] [INFO] Worker exiting (pid: 21223)
[2016-03-23 19:08:52 +0000] [21287] [INFO] Booting worker with pid: 21287
[2016-03-23 16:09:27 +0000] [21287] [DEBUG] GET /ask/
[2016-03-23 16:09:28 +0000] [21287] [DEBUG] GET /ask/
[2016-03-23 16:10:49 +0000] [21287] [INFO] Worker reloading: /home/tayfen/develop/stepic/web_apps/web/ask/qa/forms.py modified
[2016-03-23 16:10:49 +0000] [21287] [INFO] Worker exiting (pid: 21287)
[2016-03-23 19:10:49 +0000] [21448] [INFO] Booting worker with pid: 21448
[2016-03-23 16:10:50 +0000] [21448] [DEBUG] GET /ask/
[2016-03-23 16:10:51 +0000] [21448] [DEBUG] GET /ask/
[2016-03-23 16:10:52 +0000] [21448] [DEBUG] GET /ask/
[2016-03-23 16:13:34 +0000] [21448] [INFO] Worker reloading: /home/tayfen/develop/stepic/web_apps/web/ask/qa/forms.py modified
[2016-03-23 16:13:34 +0000] [21448] [INFO] Worker exiting (pid: 21448)
[2016-03-23 19:13:34 +0000] [21463] [INFO] Booting worker with pid: 21463
[2016-03-23 16:13:39 +0000] [21463] [DEBUG] GET /ask/
[2016-03-23 16:13:40 +0000] [21463] [DEBUG] GET /ask/
[2016-03-23 16:15:21 +0000] [21463] [INFO] Worker reloading: /home/tayfen/develop/stepic/web_apps/web/ask/qa/forms.py modified
[2016-03-23 16:15:22 +0000] [21463] [INFO] Worker exiting (pid: 21463)
[2016-03-23 19:15:22 +0000] [21486] [INFO] Booting worker with pid: 21486
[2016-03-23 16:15:33 +0000] [21486] [DEBUG] GET /ask/
[2016-03-23 16:15:34 +0000] [21486] [DEBUG] GET /ask/
[2016-03-23 16:19:28 +0000] [21486] [INFO] Worker reloading: /home/tayfen/develop/stepic/web_apps/web/ask/qa/forms.py modified
[2016-03-23 16:19:28 +0000] [21486] [INFO] Worker exiting (pid: 21486)
[2016-03-23 19:19:28 +0000] [21510] [INFO] Booting worker with pid: 21510
[2016-03-23 16:19:39 +0000] [21510] [INFO] Worker reloading: /home/tayfen/develop/stepic/web_apps/web/ask/qa/models.py modified
[2016-03-23 16:19:39 +0000] [21510] [INFO] Worker exiting (pid: 21510)
[2016-03-23 19:19:39 +0000] [21516] [INFO] Booting worker with pid: 21516
[2016-03-23 16:19:52 +0000] [21516] [DEBUG] GET /ask/
[2016-03-23 16:20:09 +0000] [21516] [DEBUG] GET /
[2016-03-23 16:21:04 +0000] [21516] [INFO] Worker reloading: /home/tayfen/develop/stepic/web_apps/web/ask/qa/models.py modified
[2016-03-23 16:21:04 +0000] [21516] [INFO] Worker exiting (pid: 21516)
[2016-03-23 19:21:04 +0000] [21549] [INFO] Booting worker with pid: 21549
[2016-03-23 16:22:07 +0000] [21549] [DEBUG] GET /ask/
[2016-03-23 16:34:12 +0000] [21549] [DEBUG] GET /Advertisers/0fe3b4ff308744aebcca23a25fc5e901.png
[2016-03-23 16:34:43 +0000] [21549] [DEBUG] GET /Advertisers/50210a6b139d463486e63ab346da06ea.png
[2016-03-23 16:35:20 +0000] [21549] [INFO] Worker reloading: /home/tayfen/develop/stepic/web_apps/web/ask/qa/models.py modified
[2016-03-23 16:35:20 +0000] [21549] [INFO] Worker exiting (pid: 21549)
[2016-03-23 19:35:20 +0000] [21657] [INFO] Booting worker with pid: 21657
[2016-03-23 16:35:20 +0000] [21657] [ERROR] unindent does not match any outer indentation level (models.py, line 16)
Traceback (most recent call last):
  File "/usr/local/lib/python2.7/dist-packages/gunicorn/workers/base.py", line 130, in load_wsgi
    self.wsgi = self.app.wsgi()
  File "/usr/local/lib/python2.7/dist-packages/gunicorn/app/base.py", line 67, in wsgi
    self.callable = self.load()
  File "/usr/local/lib/python2.7/dist-packages/gunicorn/app/djangoapp.py", line 106, in load
    return mod.make_wsgi_application()
  File "/usr/local/lib/python2.7/dist-packages/gunicorn/app/django_wsgi.py", line 37, in make_wsgi_application
    if get_validation_errors(s):
  File "/usr/local/lib/python2.7/dist-packages/django/core/management/validation.py", line 34, in get_validation_errors
    for (app_name, error) in get_app_errors().items():
  File "/usr/local/lib/python2.7/dist-packages/django/db/models/loading.py", line 196, in get_app_errors
    self._populate()
  File "/usr/local/lib/python2.7/dist-packages/django/db/models/loading.py", line 75, in _populate
    self.load_app(app_name, True)
  File "/usr/local/lib/python2.7/dist-packages/django/db/models/loading.py", line 99, in load_app
    models = import_module('%s.models' % app_name)
  File "/usr/local/lib/python2.7/dist-packages/django/utils/importlib.py", line 40, in import_module
    __import__(name)
  File "/home/tayfen/develop/stepic/web_apps/web/ask/qa/models.py", line 16
    def get_url(self):
                     ^
IndentationError: unindent does not match any outer indentation level
[2016-03-23 16:35:41 +0000] [21657] [DEBUG] GET /ask/
[2016-03-23 16:36:11 +0000] [21657] [INFO] Worker reloading: /home/tayfen/develop/stepic/web_apps/web/ask/qa/models.py modified
[2016-03-23 16:36:11 +0000] [21657] [INFO] Worker exiting (pid: 21657)
[2016-03-23 19:36:11 +0000] [21664] [INFO] Booting worker with pid: 21664
[2016-03-23 16:36:11 +0000] [21664] [ERROR] unindent does not match any outer indentation level (models.py, line 17)
Traceback (most recent call last):
  File "/usr/local/lib/python2.7/dist-packages/gunicorn/workers/base.py", line 130, in load_wsgi
    self.wsgi = self.app.wsgi()
  File "/usr/local/lib/python2.7/dist-packages/gunicorn/app/base.py", line 67, in wsgi
    self.callable = self.load()
  File "/usr/local/lib/python2.7/dist-packages/gunicorn/app/djangoapp.py", line 106, in load
    return mod.make_wsgi_application()
  File "/usr/local/lib/python2.7/dist-packages/gunicorn/app/django_wsgi.py", line 37, in make_wsgi_application
    if get_validation_errors(s):
  File "/usr/local/lib/python2.7/dist-packages/django/core/management/validation.py", line 34, in get_validation_errors
    for (app_name, error) in get_app_errors().items():
  File "/usr/local/lib/python2.7/dist-packages/django/db/models/loading.py", line 196, in get_app_errors
    self._populate()
  File "/usr/local/lib/python2.7/dist-packages/django/db/models/loading.py", line 75, in _populate
    self.load_app(app_name, True)
  File "/usr/local/lib/python2.7/dist-packages/django/db/models/loading.py", line 99, in load_app
    models = import_module('%s.models' % app_name)
  File "/usr/local/lib/python2.7/dist-packages/django/utils/importlib.py", line 40, in import_module
    __import__(name)
  File "/home/tayfen/develop/stepic/web_apps/web/ask/qa/models.py", line 17
    def get_url(self):
                     ^
IndentationError: unindent does not match any outer indentation level
[2016-03-23 16:36:13 +0000] [21664] [DEBUG] GET /ask/
2016-03-23 20:50:16 [4138] [INFO] Starting gunicorn 17.5
2016-03-23 20:50:16 [4138] [DEBUG] Arbiter booted
2016-03-23 20:50:16 [4138] [INFO] Listening at: http://0.0.0.0:8000 (4138)
2016-03-23 20:50:16 [4138] [INFO] Using worker: sync
2016-03-23 20:50:16 [4143] [INFO] Booting worker with pid: 4143
2016-03-23 20:50:17 [4143] [ERROR] Exception in worker process:
Traceback (most recent call last):
  File "/usr/lib/python2.7/dist-packages/gunicorn/arbiter.py", line 473, in spawn_worker
    worker.init_process()
  File "/usr/lib/python2.7/dist-packages/gunicorn/workers/base.py", line 100, in init_process
    self.wsgi = self.app.wsgi()
  File "/usr/lib/python2.7/dist-packages/gunicorn/app/base.py", line 115, in wsgi
    self.callable = self.load()
  File "/usr/lib/python2.7/dist-packages/gunicorn/app/djangoapp.py", line 101, in load
    mod = util.import_module("gunicorn.app.django_wsgi")
  File "/usr/lib/python2.7/importlib/__init__.py", line 37, in import_module
    __import__(name)
  File "/usr/lib/python2.7/dist-packages/gunicorn/app/django_wsgi.py", line 20, in <module>
    from django.core.management.validation import get_validation_errors
ImportError: No module named validation
Traceback (most recent call last):
  File "/usr/lib/python2.7/dist-packages/gunicorn/arbiter.py", line 473, in spawn_worker
    worker.init_process()
  File "/usr/lib/python2.7/dist-packages/gunicorn/workers/base.py", line 100, in init_process
    self.wsgi = self.app.wsgi()
  File "/usr/lib/python2.7/dist-packages/gunicorn/app/base.py", line 115, in wsgi
    self.callable = self.load()
  File "/usr/lib/python2.7/dist-packages/gunicorn/app/djangoapp.py", line 101, in load
    mod = util.import_module("gunicorn.app.django_wsgi")
  File "/usr/lib/python2.7/importlib/__init__.py", line 37, in import_module
    __import__(name)
  File "/usr/lib/python2.7/dist-packages/gunicorn/app/django_wsgi.py", line 20, in <module>
    from django.core.management.validation import get_validation_errors
ImportError: No module named validation
2016-03-23 20:50:17 [4143] [INFO] Worker exiting (pid: 4143)
2016-03-23 20:50:17 [4138] [INFO] Shutting down: Master
2016-03-23 20:50:17 [4138] [INFO] Reason: Worker failed to boot.
2016-03-23 20:55:27 [4205] [INFO] Starting gunicorn 17.5
2016-03-23 20:55:27 [4205] [DEBUG] Arbiter booted
2016-03-23 20:55:27 [4205] [INFO] Listening at: http://0.0.0.0:8000 (4205)
2016-03-23 20:55:27 [4205] [INFO] Using worker: sync
2016-03-23 20:55:27 [4210] [INFO] Booting worker with pid: 4210
2016-03-23 17:55:27 [4210] [ERROR] Exception in worker process:
Traceback (most recent call last):
  File "/usr/lib/python2.7/dist-packages/gunicorn/arbiter.py", line 473, in spawn_worker
    worker.init_process()
  File "/usr/lib/python2.7/dist-packages/gunicorn/workers/base.py", line 100, in init_process
    self.wsgi = self.app.wsgi()
  File "/usr/lib/python2.7/dist-packages/gunicorn/app/base.py", line 115, in wsgi
    self.callable = self.load()
  File "/usr/lib/python2.7/dist-packages/gunicorn/app/wsgiapp.py", line 33, in load
    return util.import_app(self.app_uri)
  File "/usr/lib/python2.7/dist-packages/gunicorn/util.py", line 362, in import_app
    __import__(module)
  File "/home/tayfen/develop/stepic/web_apps/web/ask/ask/wsgi.py", line 14, in <module>
    application = get_wsgi_application()
  File "/usr/local/lib/python2.7/dist-packages/django/core/wsgi.py", line 13, in get_wsgi_application
    django.setup()
  File "/usr/local/lib/python2.7/dist-packages/django/__init__.py", line 18, in setup
    apps.populate(settings.INSTALLED_APPS)
  File "/usr/local/lib/python2.7/dist-packages/django/apps/registry.py", line 108, in populate
    app_config.import_models(all_models)
  File "/usr/local/lib/python2.7/dist-packages/django/apps/config.py", line 202, in import_models
    self.models_module = import_module(models_module_name)
  File "/usr/lib/python2.7/importlib/__init__.py", line 37, in import_module
    __import__(name)
  File "/home/tayfen/develop/stepic/web_apps/web/ask/qa/models.py", line 17
    def get_url(self):
                     ^
IndentationError: unindent does not match any outer indentation level
Traceback (most recent call last):
  File "/usr/lib/python2.7/dist-packages/gunicorn/arbiter.py", line 473, in spawn_worker
    worker.init_process()
  File "/usr/lib/python2.7/dist-packages/gunicorn/workers/base.py", line 100, in init_process
    self.wsgi = self.app.wsgi()
  File "/usr/lib/python2.7/dist-packages/gunicorn/app/base.py", line 115, in wsgi
    self.callable = self.load()
  File "/usr/lib/python2.7/dist-packages/gunicorn/app/wsgiapp.py", line 33, in load
    return util.import_app(self.app_uri)
  File "/usr/lib/python2.7/dist-packages/gunicorn/util.py", line 362, in import_app
    __import__(module)
  File "/home/tayfen/develop/stepic/web_apps/web/ask/ask/wsgi.py", line 14, in <module>
    application = get_wsgi_application()
  File "/usr/local/lib/python2.7/dist-packages/django/core/wsgi.py", line 13, in get_wsgi_application
    django.setup()
  File "/usr/local/lib/python2.7/dist-packages/django/__init__.py", line 18, in setup
    apps.populate(settings.INSTALLED_APPS)
  File "/usr/local/lib/python2.7/dist-packages/django/apps/registry.py", line 108, in populate
    app_config.import_models(all_models)
  File "/usr/local/lib/python2.7/dist-packages/django/apps/config.py", line 202, in import_models
    self.models_module = import_module(models_module_name)
  File "/usr/lib/python2.7/importlib/__init__.py", line 37, in import_module
    __import__(name)
  File "/home/tayfen/develop/stepic/web_apps/web/ask/qa/models.py", line 17
    def get_url(self):
                     ^
IndentationError: unindent does not match any outer indentation level
2016-03-23 17:55:27 [4210] [INFO] Worker exiting (pid: 4210)
2016-03-23 20:55:28 [4205] [INFO] Shutting down: Master
2016-03-23 20:55:28 [4205] [INFO] Reason: Worker failed to boot.
2016-03-23 20:56:32 [4216] [INFO] Starting gunicorn 17.5
2016-03-23 20:56:32 [4216] [DEBUG] Arbiter booted
2016-03-23 20:56:32 [4216] [INFO] Listening at: http://0.0.0.0:8000 (4216)
2016-03-23 20:56:32 [4216] [INFO] Using worker: sync
2016-03-23 20:56:32 [4221] [INFO] Booting worker with pid: 4221
2016-03-23 17:56:50 [4221] [DEBUG] GET /ask/
Not Found: /ask/
2016-03-23 17:59:12 [4221] [DEBUG] GET /ask/
Not Found: /ask/
2016-03-23 17:59:15 [4221] [DEBUG] GET /
Internal Server Error: /
Traceback (most recent call last):
  File "/usr/local/lib/python2.7/dist-packages/django/core/handlers/base.py", line 149, in get_response
    response = self.process_exception_by_middleware(e, request)
  File "/usr/local/lib/python2.7/dist-packages/django/core/handlers/base.py", line 147, in get_response
    response = wrapped_callback(request, *callback_args, **callback_kwargs)
  File "/home/tayfen/develop/stepic/web_apps/web/ask/qa/views.py", line 20, in top
    page = paginator.page(page)
  File "/usr/local/lib/python2.7/dist-packages/django/core/paginator.py", line 50, in page
    number = self.validate_number(number)
  File "/usr/local/lib/python2.7/dist-packages/django/core/paginator.py", line 39, in validate_number
    if number > self.num_pages:
  File "/usr/local/lib/python2.7/dist-packages/django/core/paginator.py", line 86, in _get_num_pages
    if self.count == 0 and not self.allow_empty_first_page:
  File "/usr/local/lib/python2.7/dist-packages/django/core/paginator.py", line 72, in _get_count
    self._count = self.object_list.count()
  File "/usr/local/lib/python2.7/dist-packages/django/db/models/query.py", line 371, in count
    return self.query.get_count(using=self.db)
  File "/usr/local/lib/python2.7/dist-packages/django/db/models/sql/query.py", line 483, in get_count
    number = obj.get_aggregation(using, ['__count'])['__count']
  File "/usr/local/lib/python2.7/dist-packages/django/db/models/sql/query.py", line 464, in get_aggregation
    result = compiler.execute_sql(SINGLE)
  File "/usr/local/lib/python2.7/dist-packages/django/db/models/sql/compiler.py", line 846, in execute_sql
    cursor = self.connection.cursor()
  File "/usr/local/lib/python2.7/dist-packages/django/db/backends/base/base.py", line 231, in cursor
    cursor = self.make_debug_cursor(self._cursor())
  File "/usr/local/lib/python2.7/dist-packages/django/db/backends/base/base.py", line 204, in _cursor
    self.ensure_connection()
  File "/usr/local/lib/python2.7/dist-packages/django/db/backends/base/base.py", line 199, in ensure_connection
    self.connect()
  File "/usr/local/lib/python2.7/dist-packages/django/db/utils.py", line 95, in __exit__
    six.reraise(dj_exc_type, dj_exc_value, traceback)
  File "/usr/local/lib/python2.7/dist-packages/django/db/backends/base/base.py", line 199, in ensure_connection
    self.connect()
  File "/usr/local/lib/python2.7/dist-packages/django/db/backends/base/base.py", line 171, in connect
    self.connection = self.get_new_connection(conn_params)
  File "/usr/local/lib/python2.7/dist-packages/django/db/backends/mysql/base.py", line 264, in get_new_connection
    conn = Database.connect(**conn_params)
  File "/usr/local/lib/python2.7/dist-packages/MySQLdb/__init__.py", line 81, in Connect
    return Connection(*args, **kwargs)
  File "/usr/local/lib/python2.7/dist-packages/MySQLdb/connections.py", line 193, in __init__
    super(Connection, self).__init__(*args, **kwargs2)
OperationalError: (1049, "Unknown database 'ask'")
2016-03-23 18:05:31 [4221] [INFO] Parent changed, shutting down: <Worker 4221>
2016-03-23 18:05:31 [4221] [INFO] Worker exiting (pid: 4221)
2016-03-23 21:14:18 [5678] [INFO] Starting gunicorn 17.5
2016-03-23 21:14:18 [5678] [DEBUG] Arbiter booted
2016-03-23 21:14:18 [5678] [INFO] Listening at: http://0.0.0.0:8000 (5678)
2016-03-23 21:14:18 [5678] [INFO] Using worker: sync
2016-03-23 21:14:18 [5683] [INFO] Booting worker with pid: 5683
2016-03-23 18:14:21 [5683] [DEBUG] GET /
/usr/local/lib/python2.7/dist-packages/django/template/utils.py:37: RemovedInDjango110Warning: You haven't defined a TEMPLATES setting. You must do so before upgrading to Django 1.10. Otherwise Django will be unable to load templates.
  "unable to load templates.", RemovedInDjango110Warning)

2016-03-23 18:16:11 [5683] [DEBUG] GET /
2016-03-23 19:51:12 [5683] [DEBUG] GET /
2016-03-23 19:51:47 [5683] [DEBUG] GET /ask/
Internal Server Error: /ask/
Traceback (most recent call last):
  File "/usr/local/lib/python2.7/dist-packages/django/core/handlers/base.py", line 149, in get_response
    response = self.process_exception_by_middleware(e, request)
  File "/usr/local/lib/python2.7/dist-packages/django/core/handlers/base.py", line 147, in get_response
    response = wrapped_callback(request, *callback_args, **callback_kwargs)
  File "/home/tayfen/develop/stepic/web_apps/web/ask/qa/views.py", line 68, in ask
    url = post.get_url()
AttributeError: 'Question' object has no attribute 'get_url'
2016-03-23 20:51:46 [5683] [DEBUG] GET /ask/
Internal Server Error: /ask/
Traceback (most recent call last):
  File "/usr/local/lib/python2.7/dist-packages/django/core/handlers/base.py", line 149, in get_response
    response = self.process_exception_by_middleware(e, request)
  File "/usr/local/lib/python2.7/dist-packages/django/core/handlers/base.py", line 147, in get_response
    response = wrapped_callback(request, *callback_args, **callback_kwargs)
  File "/home/tayfen/develop/stepic/web_apps/web/ask/qa/views.py", line 68, in ask
    url = post.get_url()
AttributeError: 'Question' object has no attribute 'get_url'
2016-03-23 20:51:52 [5683] [DEBUG] GET /ask/
Internal Server Error: /ask/
Traceback (most recent call last):
  File "/usr/local/lib/python2.7/dist-packages/django/core/handlers/base.py", line 149, in get_response
    response = self.process_exception_by_middleware(e, request)
  File "/usr/local/lib/python2.7/dist-packages/django/core/handlers/base.py", line 147, in get_response
    response = wrapped_callback(request, *callback_args, **callback_kwargs)
  File "/home/tayfen/develop/stepic/web_apps/web/ask/qa/views.py", line 68, in ask
    url = post.get_url()
AttributeError: 'Question' object has no attribute 'get_url'
2016-03-23 20:51:53 [5683] [DEBUG] GET /ask/
Internal Server Error: /ask/
Traceback (most recent call last):
  File "/usr/local/lib/python2.7/dist-packages/django/core/handlers/base.py", line 149, in get_response
    response = self.process_exception_by_middleware(e, request)
  File "/usr/local/lib/python2.7/dist-packages/django/core/handlers/base.py", line 147, in get_response
    response = wrapped_callback(request, *callback_args, **callback_kwargs)
  File "/home/tayfen/develop/stepic/web_apps/web/ask/qa/views.py", line 68, in ask
    url = post.get_url()
AttributeError: 'Question' object has no attribute 'get_url'
2016-03-23 20:51:53 [5683] [DEBUG] GET /ask/
Internal Server Error: /ask/
Traceback (most recent call last):
  File "/usr/local/lib/python2.7/dist-packages/django/core/handlers/base.py", line 149, in get_response
    response = self.process_exception_by_middleware(e, request)
  File "/usr/local/lib/python2.7/dist-packages/django/core/handlers/base.py", line 147, in get_response
    response = wrapped_callback(request, *callback_args, **callback_kwargs)
  File "/home/tayfen/develop/stepic/web_apps/web/ask/qa/views.py", line 68, in ask
    url = post.get_url()
AttributeError: 'Question' object has no attribute 'get_url'
2016-03-23 20:51:54 [5683] [DEBUG] GET /ask/
Internal Server Error: /ask/
Traceback (most recent call last):
  File "/usr/local/lib/python2.7/dist-packages/django/core/handlers/base.py", line 149, in get_response
    response = self.process_exception_by_middleware(e, request)
  File "/usr/local/lib/python2.7/dist-packages/django/core/handlers/base.py", line 147, in get_response
    response = wrapped_callback(request, *callback_args, **callback_kwargs)
  File "/home/tayfen/develop/stepic/web_apps/web/ask/qa/views.py", line 68, in ask
    url = post.get_url()
AttributeError: 'Question' object has no attribute 'get_url'
2016-03-23 20:51:54 [5683] [DEBUG] GET /ask/
Internal Server Error: /ask/
Traceback (most recent call last):
  File "/usr/local/lib/python2.7/dist-packages/django/core/handlers/base.py", line 149, in get_response
    response = self.process_exception_by_middleware(e, request)
  File "/usr/local/lib/python2.7/dist-packages/django/core/handlers/base.py", line 147, in get_response
    response = wrapped_callback(request, *callback_args, **callback_kwargs)
  File "/home/tayfen/develop/stepic/web_apps/web/ask/qa/views.py", line 68, in ask
    url = post.get_url()
AttributeError: 'Question' object has no attribute 'get_url'
2016-03-23 20:51:55 [5683] [DEBUG] GET /ask/
Internal Server Error: /ask/
Traceback (most recent call last):
  File "/usr/local/lib/python2.7/dist-packages/django/core/handlers/base.py", line 149, in get_response
    response = self.process_exception_by_middleware(e, request)
  File "/usr/local/lib/python2.7/dist-packages/django/core/handlers/base.py", line 147, in get_response
    response = wrapped_callback(request, *callback_args, **callback_kwargs)
  File "/home/tayfen/develop/stepic/web_apps/web/ask/qa/views.py", line 68, in ask
    url = post.get_url()
AttributeError: 'Question' object has no attribute 'get_url'
2016-03-23 21:00:03 [5683] [DEBUG] GET /ask/
Internal Server Error: /ask/
Traceback (most recent call last):
  File "/usr/local/lib/python2.7/dist-packages/django/core/handlers/base.py", line 149, in get_response
    response = self.process_exception_by_middleware(e, request)
  File "/usr/local/lib/python2.7/dist-packages/django/core/handlers/base.py", line 147, in get_response
    response = wrapped_callback(request, *callback_args, **callback_kwargs)
  File "/home/tayfen/develop/stepic/web_apps/web/ask/qa/views.py", line 68, in ask
    url = post.get_absolute_url()
AttributeError: 'Question' object has no attribute 'get_url'
2016-03-23 21:00:04 [5683] [DEBUG] GET /ask/
Internal Server Error: /ask/
Traceback (most recent call last):
  File "/usr/local/lib/python2.7/dist-packages/django/core/handlers/base.py", line 149, in get_response
    response = self.process_exception_by_middleware(e, request)
  File "/usr/local/lib/python2.7/dist-packages/django/core/handlers/base.py", line 147, in get_response
    response = wrapped_callback(request, *callback_args, **callback_kwargs)
  File "/home/tayfen/develop/stepic/web_apps/web/ask/qa/views.py", line 68, in ask
    url = post.get_absolute_url()
AttributeError: 'Question' object has no attribute 'get_url'
2016-03-23 21:00:05 [5683] [DEBUG] GET /ask/
Internal Server Error: /ask/
Traceback (most recent call last):
  File "/usr/local/lib/python2.7/dist-packages/django/core/handlers/base.py", line 149, in get_response
    response = self.process_exception_by_middleware(e, request)
  File "/usr/local/lib/python2.7/dist-packages/django/core/handlers/base.py", line 147, in get_response
    response = wrapped_callback(request, *callback_args, **callback_kwargs)
  File "/home/tayfen/develop/stepic/web_apps/web/ask/qa/views.py", line 68, in ask
    url = post.get_absolute_url()
AttributeError: 'Question' object has no attribute 'get_url'
2016-03-23 21:00:06 [5683] [DEBUG] GET /ask/
Internal Server Error: /ask/
Traceback (most recent call last):
  File "/usr/local/lib/python2.7/dist-packages/django/core/handlers/base.py", line 149, in get_response
    response = self.process_exception_by_middleware(e, request)
  File "/usr/local/lib/python2.7/dist-packages/django/core/handlers/base.py", line 147, in get_response
    response = wrapped_callback(request, *callback_args, **callback_kwargs)
  File "/home/tayfen/develop/stepic/web_apps/web/ask/qa/views.py", line 68, in ask
    url = post.get_absolute_url()
AttributeError: 'Question' object has no attribute 'get_url'
2016-03-23 21:00:06 [5683] [DEBUG] GET /ask/
Internal Server Error: /ask/
Traceback (most recent call last):
  File "/usr/local/lib/python2.7/dist-packages/django/core/handlers/base.py", line 149, in get_response
    response = self.process_exception_by_middleware(e, request)
  File "/usr/local/lib/python2.7/dist-packages/django/core/handlers/base.py", line 147, in get_response
    response = wrapped_callback(request, *callback_args, **callback_kwargs)
  File "/home/tayfen/develop/stepic/web_apps/web/ask/qa/views.py", line 68, in ask
    url = post.get_absolute_url()
AttributeError: 'Question' object has no attribute 'get_url'
2016-03-23 21:00:07 [5683] [DEBUG] GET /ask/
Internal Server Error: /ask/
Traceback (most recent call last):
  File "/usr/local/lib/python2.7/dist-packages/django/core/handlers/base.py", line 149, in get_response
    response = self.process_exception_by_middleware(e, request)
  File "/usr/local/lib/python2.7/dist-packages/django/core/handlers/base.py", line 147, in get_response
    response = wrapped_callback(request, *callback_args, **callback_kwargs)
  File "/home/tayfen/develop/stepic/web_apps/web/ask/qa/views.py", line 68, in ask
    url = post.get_absolute_url()
AttributeError: 'Question' object has no attribute 'get_url'
2016-03-23 21:00:47 [5683] [DEBUG] GET /ask/
Internal Server Error: /ask/
Traceback (most recent call last):
  File "/usr/local/lib/python2.7/dist-packages/django/core/handlers/base.py", line 149, in get_response
    response = self.process_exception_by_middleware(e, request)
  File "/usr/local/lib/python2.7/dist-packages/django/core/handlers/base.py", line 147, in get_response
    response = wrapped_callback(request, *callback_args, **callback_kwargs)
  File "/home/tayfen/develop/stepic/web_apps/web/ask/qa/views.py", line 68, in ask
    url = post.get_absolute_url()
AttributeError: 'Question' object has no attribute 'get_url'
2016-03-23 21:00:48 [5683] [DEBUG] GET /ask/
Internal Server Error: /ask/
Traceback (most recent call last):
  File "/usr/local/lib/python2.7/dist-packages/django/core/handlers/base.py", line 149, in get_response
    response = self.process_exception_by_middleware(e, request)
  File "/usr/local/lib/python2.7/dist-packages/django/core/handlers/base.py", line 147, in get_response
    response = wrapped_callback(request, *callback_args, **callback_kwargs)
  File "/home/tayfen/develop/stepic/web_apps/web/ask/qa/views.py", line 68, in ask
    url = post.get_absolute_url()
AttributeError: 'Question' object has no attribute 'get_url'
2016-03-23 21:00:49 [5683] [DEBUG] GET /ask/
Internal Server Error: /ask/
Traceback (most recent call last):
  File "/usr/local/lib/python2.7/dist-packages/django/core/handlers/base.py", line 149, in get_response
    response = self.process_exception_by_middleware(e, request)
  File "/usr/local/lib/python2.7/dist-packages/django/core/handlers/base.py", line 147, in get_response
    response = wrapped_callback(request, *callback_args, **callback_kwargs)
  File "/home/tayfen/develop/stepic/web_apps/web/ask/qa/views.py", line 68, in ask
    url = post.get_absolute_url()
AttributeError: 'Question' object has no attribute 'get_url'
2016-03-23 21:00:49 [5683] [DEBUG] GET /ask/
Internal Server Error: /ask/
Traceback (most recent call last):
  File "/usr/local/lib/python2.7/dist-packages/django/core/handlers/base.py", line 149, in get_response
    response = self.process_exception_by_middleware(e, request)
  File "/usr/local/lib/python2.7/dist-packages/django/core/handlers/base.py", line 147, in get_response
    response = wrapped_callback(request, *callback_args, **callback_kwargs)
  File "/home/tayfen/develop/stepic/web_apps/web/ask/qa/views.py", line 68, in ask
    url = post.get_absolute_url()
AttributeError: 'Question' object has no attribute 'get_url'
2016-03-23 21:00:50 [5683] [DEBUG] GET /ask/
Internal Server Error: /ask/
Traceback (most recent call last):
  File "/usr/local/lib/python2.7/dist-packages/django/core/handlers/base.py", line 149, in get_response
    response = self.process_exception_by_middleware(e, request)
  File "/usr/local/lib/python2.7/dist-packages/django/core/handlers/base.py", line 147, in get_response
    response = wrapped_callback(request, *callback_args, **callback_kwargs)
  File "/home/tayfen/develop/stepic/web_apps/web/ask/qa/views.py", line 68, in ask
    url = post.get_absolute_url()
AttributeError: 'Question' object has no attribute 'get_url'
2016-03-24 00:01:49 [8380] [INFO] Starting gunicorn 17.5
2016-03-24 00:01:49 [8380] [ERROR] Connection in use: ('0', 8000)
2016-03-24 00:01:49 [8380] [ERROR] Retrying in 1 second.
2016-03-23 21:01:50 [5683] [INFO] Parent changed, shutting down: <Worker 5683>
2016-03-23 21:01:50 [5683] [INFO] Worker exiting (pid: 5683)
2016-03-24 00:01:50 [8380] [DEBUG] Arbiter booted
2016-03-24 00:01:50 [8380] [INFO] Listening at: http://0.0.0.0:8000 (8380)
2016-03-24 00:01:50 [8380] [INFO] Using worker: sync
2016-03-24 00:01:50 [8385] [INFO] Booting worker with pid: 8385
2016-03-23 21:01:53 [8385] [DEBUG] GET /ask/
Internal Server Error: /ask/
Traceback (most recent call last):
  File "/usr/local/lib/python2.7/dist-packages/django/core/handlers/base.py", line 149, in get_response
    response = self.process_exception_by_middleware(e, request)
  File "/usr/local/lib/python2.7/dist-packages/django/core/handlers/base.py", line 147, in get_response
    response = wrapped_callback(request, *callback_args, **callback_kwargs)
  File "/home/tayfen/develop/stepic/web_apps/web/ask/qa/views.py", line 68, in ask
    url = post.get_absolute_url()
AttributeError: 'Question' object has no attribute 'get_absolute_url'
2016-03-23 21:01:54 [8385] [DEBUG] GET /ask/
Internal Server Error: /ask/
Traceback (most recent call last):
  File "/usr/local/lib/python2.7/dist-packages/django/core/handlers/base.py", line 149, in get_response
    response = self.process_exception_by_middleware(e, request)
  File "/usr/local/lib/python2.7/dist-packages/django/core/handlers/base.py", line 147, in get_response
    response = wrapped_callback(request, *callback_args, **callback_kwargs)
  File "/home/tayfen/develop/stepic/web_apps/web/ask/qa/views.py", line 68, in ask
    url = post.get_absolute_url()
AttributeError: 'Question' object has no attribute 'get_absolute_url'
2016-03-23 21:01:55 [8385] [DEBUG] GET /ask/
Internal Server Error: /ask/
Traceback (most recent call last):
  File "/usr/local/lib/python2.7/dist-packages/django/core/handlers/base.py", line 149, in get_response
    response = self.process_exception_by_middleware(e, request)
  File "/usr/local/lib/python2.7/dist-packages/django/core/handlers/base.py", line 147, in get_response
    response = wrapped_callback(request, *callback_args, **callback_kwargs)
  File "/home/tayfen/develop/stepic/web_apps/web/ask/qa/views.py", line 68, in ask
    url = post.get_absolute_url()
AttributeError: 'Question' object has no attribute 'get_absolute_url'
2016-03-23 21:07:44 [8385] [DEBUG] GET /ask/
Internal Server Error: /ask/
Traceback (most recent call last):
  File "/usr/local/lib/python2.7/dist-packages/django/core/handlers/base.py", line 149, in get_response
    response = self.process_exception_by_middleware(e, request)
  File "/usr/local/lib/python2.7/dist-packages/django/core/handlers/base.py", line 147, in get_response
    response = wrapped_callback(request, *callback_args, **callback_kwargs)
  File "/home/tayfen/develop/stepic/web_apps/web/ask/qa/views.py", line 68, in ask
    url = post.get_url()
AttributeError: 'Question' object has no attribute 'get_absolute_url'
2016-03-23 21:07:45 [8385] [DEBUG] GET /ask/
Internal Server Error: /ask/
Traceback (most recent call last):
  File "/usr/local/lib/python2.7/dist-packages/django/core/handlers/base.py", line 149, in get_response
    response = self.process_exception_by_middleware(e, request)
  File "/usr/local/lib/python2.7/dist-packages/django/core/handlers/base.py", line 147, in get_response
    response = wrapped_callback(request, *callback_args, **callback_kwargs)
  File "/home/tayfen/develop/stepic/web_apps/web/ask/qa/views.py", line 68, in ask
    url = post.get_url()
AttributeError: 'Question' object has no attribute 'get_absolute_url'
2016-03-24 00:07:58 [8399] [INFO] Starting gunicorn 17.5
2016-03-24 00:07:58 [8399] [ERROR] Connection in use: ('0', 8000)
2016-03-24 00:07:58 [8399] [ERROR] Retrying in 1 second.
2016-03-24 00:07:59 [8399] [ERROR] Connection in use: ('0', 8000)
2016-03-24 00:07:59 [8399] [ERROR] Retrying in 1 second.
2016-03-24 00:08:00 [8399] [ERROR] Connection in use: ('0', 8000)
2016-03-24 00:08:00 [8399] [ERROR] Retrying in 1 second.
2016-03-23 21:08:00 [8385] [INFO] Parent changed, shutting down: <Worker 8385>
2016-03-23 21:08:00 [8385] [INFO] Worker exiting (pid: 8385)
2016-03-24 00:08:01 [8399] [DEBUG] Arbiter booted
2016-03-24 00:08:01 [8399] [INFO] Listening at: http://0.0.0.0:8000 (8399)
2016-03-24 00:08:01 [8399] [INFO] Using worker: sync
2016-03-24 00:08:01 [8404] [INFO] Booting worker with pid: 8404
2016-03-23 21:08:01 [8404] [ERROR] Exception in worker process:
Traceback (most recent call last):
  File "/usr/lib/python2.7/dist-packages/gunicorn/arbiter.py", line 473, in spawn_worker
    worker.init_process()
  File "/usr/lib/python2.7/dist-packages/gunicorn/workers/base.py", line 100, in init_process
    self.wsgi = self.app.wsgi()
  File "/usr/lib/python2.7/dist-packages/gunicorn/app/base.py", line 115, in wsgi
    self.callable = self.load()
  File "/usr/lib/python2.7/dist-packages/gunicorn/app/wsgiapp.py", line 33, in load
    return util.import_app(self.app_uri)
  File "/usr/lib/python2.7/dist-packages/gunicorn/util.py", line 362, in import_app
    __import__(module)
  File "/home/tayfen/develop/stepic/web_apps/web/ask/ask/wsgi.py", line 14, in <module>
    application = get_wsgi_application()
  File "/usr/local/lib/python2.7/dist-packages/django/core/wsgi.py", line 13, in get_wsgi_application
    django.setup()
  File "/usr/local/lib/python2.7/dist-packages/django/__init__.py", line 18, in setup
    apps.populate(settings.INSTALLED_APPS)
  File "/usr/local/lib/python2.7/dist-packages/django/apps/registry.py", line 108, in populate
    app_config.import_models(all_models)
  File "/usr/local/lib/python2.7/dist-packages/django/apps/config.py", line 202, in import_models
    self.models_module = import_module(models_module_name)
  File "/usr/lib/python2.7/importlib/__init__.py", line 37, in import_module
    __import__(name)
  File "/home/tayfen/develop/stepic/web_apps/web/ask/qa/models.py", line 17
    def _get_url(self):
                      ^
IndentationError: unindent does not match any outer indentation level
Traceback (most recent call last):
  File "/usr/lib/python2.7/dist-packages/gunicorn/arbiter.py", line 473, in spawn_worker
    worker.init_process()
  File "/usr/lib/python2.7/dist-packages/gunicorn/workers/base.py", line 100, in init_process
    self.wsgi = self.app.wsgi()
  File "/usr/lib/python2.7/dist-packages/gunicorn/app/base.py", line 115, in wsgi
    self.callable = self.load()
  File "/usr/lib/python2.7/dist-packages/gunicorn/app/wsgiapp.py", line 33, in load
    return util.import_app(self.app_uri)
  File "/usr/lib/python2.7/dist-packages/gunicorn/util.py", line 362, in import_app
    __import__(module)
  File "/home/tayfen/develop/stepic/web_apps/web/ask/ask/wsgi.py", line 14, in <module>
    application = get_wsgi_application()
  File "/usr/local/lib/python2.7/dist-packages/django/core/wsgi.py", line 13, in get_wsgi_application
    django.setup()
  File "/usr/local/lib/python2.7/dist-packages/django/__init__.py", line 18, in setup
    apps.populate(settings.INSTALLED_APPS)
  File "/usr/local/lib/python2.7/dist-packages/django/apps/registry.py", line 108, in populate
    app_config.import_models(all_models)
  File "/usr/local/lib/python2.7/dist-packages/django/apps/config.py", line 202, in import_models
    self.models_module = import_module(models_module_name)
  File "/usr/lib/python2.7/importlib/__init__.py", line 37, in import_module
    __import__(name)
  File "/home/tayfen/develop/stepic/web_apps/web/ask/qa/models.py", line 17
    def _get_url(self):
                      ^
IndentationError: unindent does not match any outer indentation level
2016-03-23 21:08:01 [8404] [INFO] Worker exiting (pid: 8404)
2016-03-24 00:08:01 [8399] [INFO] Shutting down: Master
2016-03-24 00:08:01 [8399] [INFO] Reason: Worker failed to boot.
2016-03-24 00:11:22 [8455] [INFO] Starting gunicorn 17.5
2016-03-24 00:11:22 [8455] [DEBUG] Arbiter booted
2016-03-24 00:11:22 [8455] [INFO] Listening at: http://0.0.0.0:8000 (8455)
2016-03-24 00:11:22 [8455] [INFO] Using worker: sync
2016-03-24 00:11:22 [8460] [INFO] Booting worker with pid: 8460
2016-03-23 21:11:22 [8460] [ERROR] Exception in worker process:
Traceback (most recent call last):
  File "/usr/lib/python2.7/dist-packages/gunicorn/arbiter.py", line 473, in spawn_worker
    worker.init_process()
  File "/usr/lib/python2.7/dist-packages/gunicorn/workers/base.py", line 100, in init_process
    self.wsgi = self.app.wsgi()
  File "/usr/lib/python2.7/dist-packages/gunicorn/app/base.py", line 115, in wsgi
    self.callable = self.load()
  File "/usr/lib/python2.7/dist-packages/gunicorn/app/wsgiapp.py", line 33, in load
    return util.import_app(self.app_uri)
  File "/usr/lib/python2.7/dist-packages/gunicorn/util.py", line 362, in import_app
    __import__(module)
  File "/home/tayfen/develop/stepic/web_apps/web/ask/ask/wsgi.py", line 14, in <module>
    application = get_wsgi_application()
  File "/usr/local/lib/python2.7/dist-packages/django/core/wsgi.py", line 13, in get_wsgi_application
    django.setup()
  File "/usr/local/lib/python2.7/dist-packages/django/__init__.py", line 18, in setup
    apps.populate(settings.INSTALLED_APPS)
  File "/usr/local/lib/python2.7/dist-packages/django/apps/registry.py", line 108, in populate
    app_config.import_models(all_models)
  File "/usr/local/lib/python2.7/dist-packages/django/apps/config.py", line 202, in import_models
    self.models_module = import_module(models_module_name)
  File "/usr/lib/python2.7/importlib/__init__.py", line 37, in import_module
    __import__(name)
  File "/home/tayfen/develop/stepic/web_apps/web/ask/qa/models.py", line 17
    def _get_url(self):
                      ^
IndentationError: unindent does not match any outer indentation level
Traceback (most recent call last):
  File "/usr/lib/python2.7/dist-packages/gunicorn/arbiter.py", line 473, in spawn_worker
    worker.init_process()
  File "/usr/lib/python2.7/dist-packages/gunicorn/workers/base.py", line 100, in init_process
    self.wsgi = self.app.wsgi()
  File "/usr/lib/python2.7/dist-packages/gunicorn/app/base.py", line 115, in wsgi
    self.callable = self.load()
  File "/usr/lib/python2.7/dist-packages/gunicorn/app/wsgiapp.py", line 33, in load
    return util.import_app(self.app_uri)
  File "/usr/lib/python2.7/dist-packages/gunicorn/util.py", line 362, in import_app
    __import__(module)
  File "/home/tayfen/develop/stepic/web_apps/web/ask/ask/wsgi.py", line 14, in <module>
    application = get_wsgi_application()
  File "/usr/local/lib/python2.7/dist-packages/django/core/wsgi.py", line 13, in get_wsgi_application
    django.setup()
  File "/usr/local/lib/python2.7/dist-packages/django/__init__.py", line 18, in setup
    apps.populate(settings.INSTALLED_APPS)
  File "/usr/local/lib/python2.7/dist-packages/django/apps/registry.py", line 108, in populate
    app_config.import_models(all_models)
  File "/usr/local/lib/python2.7/dist-packages/django/apps/config.py", line 202, in import_models
    self.models_module = import_module(models_module_name)
  File "/usr/lib/python2.7/importlib/__init__.py", line 37, in import_module
    __import__(name)
  File "/home/tayfen/develop/stepic/web_apps/web/ask/qa/models.py", line 17
    def _get_url(self):
                      ^
IndentationError: unindent does not match any outer indentation level
2016-03-23 21:11:22 [8460] [INFO] Worker exiting (pid: 8460)
2016-03-24 00:11:23 [8455] [INFO] Shutting down: Master
2016-03-24 00:11:23 [8455] [INFO] Reason: Worker failed to boot.
2016-03-24 00:15:50 [8477] [INFO] Starting gunicorn 17.5
2016-03-24 00:15:50 [8477] [DEBUG] Arbiter booted
2016-03-24 00:15:50 [8477] [INFO] Listening at: http://0.0.0.0:8000 (8477)
2016-03-24 00:15:50 [8477] [INFO] Using worker: sync
2016-03-24 00:15:50 [8482] [INFO] Booting worker with pid: 8482
2016-03-23 21:16:08 [8482] [DEBUG] GET /ask/
Internal Server Error: /ask/
Traceback (most recent call last):
  File "/usr/local/lib/python2.7/dist-packages/django/core/handlers/base.py", line 134, in get_response
    resolver_match = resolver.resolve(request.path_info)
  File "/usr/local/lib/python2.7/dist-packages/django/core/urlresolvers.py", line 374, in resolve
    for pattern in self.url_patterns:
  File "/usr/local/lib/python2.7/dist-packages/django/utils/functional.py", line 33, in __get__
    res = instance.__dict__[self.name] = self.func(instance)
  File "/usr/local/lib/python2.7/dist-packages/django/core/urlresolvers.py", line 417, in url_patterns
    patterns = getattr(self.urlconf_module, "urlpatterns", self.urlconf_module)
  File "/usr/local/lib/python2.7/dist-packages/django/utils/functional.py", line 33, in __get__
    res = instance.__dict__[self.name] = self.func(instance)
  File "/usr/local/lib/python2.7/dist-packages/django/core/urlresolvers.py", line 410, in urlconf_module
    return import_module(self.urlconf_name)
  File "/usr/lib/python2.7/importlib/__init__.py", line 37, in import_module
    __import__(name)
  File "/home/tayfen/develop/stepic/web_apps/web/ask/ask/urls.py", line 4, in <module>
    from qa.views import *
  File "/home/tayfen/develop/stepic/web_apps/web/ask/qa/views.py", line 2, in <module>
    from .models import Answer, Question, User, get_url
ImportError: cannot import name get_url
2016-03-23 21:16:29 [8482] [DEBUG] GET /ask/
Internal Server Error: /ask/
Traceback (most recent call last):
  File "/usr/local/lib/python2.7/dist-packages/django/core/handlers/base.py", line 149, in get_response
    response = self.process_exception_by_middleware(e, request)
  File "/usr/local/lib/python2.7/dist-packages/django/core/handlers/base.py", line 147, in get_response
    response = wrapped_callback(request, *callback_args, **callback_kwargs)
  File "/home/tayfen/develop/stepic/web_apps/web/ask/qa/views.py", line 68, in ask
    url = post.get_url()
AttributeError: 'Question' object has no attribute 'get_url'
2016-03-23 21:16:32 [8482] [DEBUG] GET /ask/
Internal Server Error: /ask/
Traceback (most recent call last):
  File "/usr/local/lib/python2.7/dist-packages/django/core/handlers/base.py", line 149, in get_response
    response = self.process_exception_by_middleware(e, request)
  File "/usr/local/lib/python2.7/dist-packages/django/core/handlers/base.py", line 147, in get_response
    response = wrapped_callback(request, *callback_args, **callback_kwargs)
  File "/home/tayfen/develop/stepic/web_apps/web/ask/qa/views.py", line 68, in ask
    url = post.get_url()
AttributeError: 'Question' object has no attribute 'get_url'
2016-03-23 21:16:33 [8482] [DEBUG] GET /ask/
Internal Server Error: /ask/
Traceback (most recent call last):
  File "/usr/local/lib/python2.7/dist-packages/django/core/handlers/base.py", line 149, in get_response
    response = self.process_exception_by_middleware(e, request)
  File "/usr/local/lib/python2.7/dist-packages/django/core/handlers/base.py", line 147, in get_response
    response = wrapped_callback(request, *callback_args, **callback_kwargs)
  File "/home/tayfen/develop/stepic/web_apps/web/ask/qa/views.py", line 68, in ask
    url = post.get_url()
AttributeError: 'Question' object has no attribute 'get_url'
2016-03-23 21:16:55 [8482] [DEBUG] GET /ask/
Internal Server Error: /ask/
Traceback (most recent call last):
  File "/usr/local/lib/python2.7/dist-packages/django/core/handlers/base.py", line 149, in get_response
    response = self.process_exception_by_middleware(e, request)
  File "/usr/local/lib/python2.7/dist-packages/django/core/handlers/base.py", line 147, in get_response
    response = wrapped_callback(request, *callback_args, **callback_kwargs)
  File "/home/tayfen/develop/stepic/web_apps/web/ask/qa/views.py", line 68, in ask
    url = post._get_url()
AttributeError: 'Question' object has no attribute 'get_url'
2016-03-23 21:16:56 [8482] [DEBUG] GET /ask/
Internal Server Error: /ask/
Traceback (most recent call last):
  File "/usr/local/lib/python2.7/dist-packages/django/core/handlers/base.py", line 149, in get_response
    response = self.process_exception_by_middleware(e, request)
  File "/usr/local/lib/python2.7/dist-packages/django/core/handlers/base.py", line 147, in get_response
    response = wrapped_callback(request, *callback_args, **callback_kwargs)
  File "/home/tayfen/develop/stepic/web_apps/web/ask/qa/views.py", line 68, in ask
    url = post._get_url()
AttributeError: 'Question' object has no attribute 'get_url'
2016-03-23 21:16:57 [8482] [DEBUG] GET /ask/
Internal Server Error: /ask/
Traceback (most recent call last):
  File "/usr/local/lib/python2.7/dist-packages/django/core/handlers/base.py", line 149, in get_response
    response = self.process_exception_by_middleware(e, request)
  File "/usr/local/lib/python2.7/dist-packages/django/core/handlers/base.py", line 147, in get_response
    response = wrapped_callback(request, *callback_args, **callback_kwargs)
  File "/home/tayfen/develop/stepic/web_apps/web/ask/qa/views.py", line 68, in ask
    url = post._get_url()
AttributeError: 'Question' object has no attribute 'get_url'
2016-03-23 21:16:58 [8482] [DEBUG] GET /ask/
Internal Server Error: /ask/
Traceback (most recent call last):
  File "/usr/local/lib/python2.7/dist-packages/django/core/handlers/base.py", line 149, in get_response
    response = self.process_exception_by_middleware(e, request)
  File "/usr/local/lib/python2.7/dist-packages/django/core/handlers/base.py", line 147, in get_response
    response = wrapped_callback(request, *callback_args, **callback_kwargs)
  File "/home/tayfen/develop/stepic/web_apps/web/ask/qa/views.py", line 68, in ask
    url = post._get_url()
AttributeError: 'Question' object has no attribute 'get_url'
2016-03-23 21:16:59 [8482] [DEBUG] GET /ask/
Internal Server Error: /ask/
Traceback (most recent call last):
  File "/usr/local/lib/python2.7/dist-packages/django/core/handlers/base.py", line 149, in get_response
    response = self.process_exception_by_middleware(e, request)
  File "/usr/local/lib/python2.7/dist-packages/django/core/handlers/base.py", line 147, in get_response
    response = wrapped_callback(request, *callback_args, **callback_kwargs)
  File "/home/tayfen/develop/stepic/web_apps/web/ask/qa/views.py", line 68, in ask
    url = post._get_url()
AttributeError: 'Question' object has no attribute 'get_url'
2016-03-23 21:17:00 [8482] [DEBUG] GET /ask/
Internal Server Error: /ask/
Traceback (most recent call last):
  File "/usr/local/lib/python2.7/dist-packages/django/core/handlers/base.py", line 149, in get_response
    response = self.process_exception_by_middleware(e, request)
  File "/usr/local/lib/python2.7/dist-packages/django/core/handlers/base.py", line 147, in get_response
    response = wrapped_callback(request, *callback_args, **callback_kwargs)
  File "/home/tayfen/develop/stepic/web_apps/web/ask/qa/views.py", line 68, in ask
    url = post._get_url()
AttributeError: 'Question' object has no attribute 'get_url'
2016-03-23 21:17:02 [8482] [DEBUG] GET /ask/
Internal Server Error: /ask/
Traceback (most recent call last):
  File "/usr/local/lib/python2.7/dist-packages/django/core/handlers/base.py", line 149, in get_response
    response = self.process_exception_by_middleware(e, request)
  File "/usr/local/lib/python2.7/dist-packages/django/core/handlers/base.py", line 147, in get_response
    response = wrapped_callback(request, *callback_args, **callback_kwargs)
  File "/home/tayfen/develop/stepic/web_apps/web/ask/qa/views.py", line 68, in ask
    url = post._get_url()
AttributeError: 'Question' object has no attribute 'get_url'
2016-03-24 00:17:24 [8495] [INFO] Starting gunicorn 17.5
2016-03-24 00:17:24 [8495] [ERROR] Connection in use: ('0', 8000)
2016-03-24 00:17:24 [8495] [ERROR] Retrying in 1 second.
2016-03-24 00:17:25 [8495] [ERROR] Connection in use: ('0', 8000)
2016-03-24 00:17:25 [8495] [ERROR] Retrying in 1 second.
2016-03-24 00:17:26 [8495] [ERROR] Connection in use: ('0', 8000)
2016-03-24 00:17:26 [8495] [ERROR] Retrying in 1 second.
2016-03-24 00:17:27 [8495] [ERROR] Connection in use: ('0', 8000)
2016-03-24 00:17:27 [8495] [ERROR] Retrying in 1 second.
2016-03-24 00:17:28 [8495] [ERROR] Connection in use: ('0', 8000)
2016-03-24 00:17:28 [8495] [ERROR] Retrying in 1 second.
2016-03-24 00:17:29 [8495] [ERROR] Can't connect to ('0', 8000)
2016-03-23 21:17:32 [8482] [INFO] Parent changed, shutting down: <Worker 8482>
2016-03-23 21:17:32 [8482] [INFO] Worker exiting (pid: 8482)
2016-03-24 00:17:52 [8506] [INFO] Starting gunicorn 17.5
2016-03-24 00:17:52 [8506] [DEBUG] Arbiter booted
2016-03-24 00:17:52 [8506] [INFO] Listening at: http://0.0.0.0:8000 (8506)
2016-03-24 00:17:52 [8506] [INFO] Using worker: sync
2016-03-24 00:17:52 [8511] [INFO] Booting worker with pid: 8511
2016-03-23 21:18:02 [8511] [DEBUG] GET /ask/
2016-03-23 21:18:02 [8511] [DEBUG] GET /ask/question/
Not Found: /ask/question/
2016-03-23 21:18:05 [8511] [DEBUG] GET /ask/question/
Not Found: /ask/question/
2016-03-23 21:18:42 [8511] [DEBUG] GET /ask/
2016-03-23 21:18:42 [8511] [DEBUG] GET /ask/question/
Not Found: /ask/question/
2016-03-23 21:34:43 [8511] [DEBUG] GET /ask/
2016-03-23 21:34:43 [8511] [DEBUG] GET /ask/question/
Not Found: /ask/question/
2016-03-23 21:34:51 [8511] [DEBUG] GET /ask/
2016-03-23 21:34:52 [8511] [DEBUG] GET /ask/question/
Not Found: /ask/question/
2016-03-24 00:35:06 [8895] [INFO] Starting gunicorn 17.5
2016-03-24 00:35:06 [8895] [ERROR] Connection in use: ('0', 8000)
2016-03-24 00:35:06 [8895] [ERROR] Retrying in 1 second.
2016-03-23 21:35:07 [8511] [INFO] Parent changed, shutting down: <Worker 8511>
2016-03-23 21:35:07 [8511] [INFO] Worker exiting (pid: 8511)
2016-03-24 00:35:07 [8895] [DEBUG] Arbiter booted
2016-03-24 00:35:07 [8895] [INFO] Listening at: http://0.0.0.0:8000 (8895)
2016-03-24 00:35:07 [8895] [INFO] Using worker: sync
2016-03-24 00:35:07 [8900] [INFO] Booting worker with pid: 8900
2016-03-23 21:35:14 [8900] [DEBUG] GET /ask/
Internal Server Error: /ask/
Traceback (most recent call last):
  File "/usr/local/lib/python2.7/dist-packages/django/core/handlers/base.py", line 149, in get_response
    response = self.process_exception_by_middleware(e, request)
  File "/usr/local/lib/python2.7/dist-packages/django/core/handlers/base.py", line 147, in get_response
    response = wrapped_callback(request, *callback_args, **callback_kwargs)
  File "/home/tayfen/develop/stepic/web_apps/web/ask/qa/views.py", line 68, in ask
    url = post._get_url()
  File "/home/tayfen/develop/stepic/web_apps/web/ask/qa/models.py", line 18, in _get_url
    return "http://127.0.0.1/question/"+self.id
TypeError: coercing to Unicode: need string or buffer, long found
2016-03-23 21:35:58 [8900] [DEBUG] GET /ask/
Internal Server Error: /ask/
Traceback (most recent call last):
  File "/usr/local/lib/python2.7/dist-packages/django/core/handlers/base.py", line 149, in get_response
    response = self.process_exception_by_middleware(e, request)
  File "/usr/local/lib/python2.7/dist-packages/django/core/handlers/base.py", line 147, in get_response
    response = wrapped_callback(request, *callback_args, **callback_kwargs)
  File "/home/tayfen/develop/stepic/web_apps/web/ask/qa/views.py", line 68, in ask
    url = post._get_url()
  File "/home/tayfen/develop/stepic/web_apps/web/ask/qa/models.py", line 18, in _get_url
    return "http://127.0.0.1/question/"+u'self.id'
TypeError: coercing to Unicode: need string or buffer, long found
2016-03-23 21:35:59 [8900] [DEBUG] GET /ask/
Internal Server Error: /ask/
Traceback (most recent call last):
  File "/usr/local/lib/python2.7/dist-packages/django/core/handlers/base.py", line 149, in get_response
    response = self.process_exception_by_middleware(e, request)
  File "/usr/local/lib/python2.7/dist-packages/django/core/handlers/base.py", line 147, in get_response
    response = wrapped_callback(request, *callback_args, **callback_kwargs)
  File "/home/tayfen/develop/stepic/web_apps/web/ask/qa/views.py", line 68, in ask
    url = post._get_url()
  File "/home/tayfen/develop/stepic/web_apps/web/ask/qa/models.py", line 18, in _get_url
    return "http://127.0.0.1/question/"+u'self.id'
TypeError: coercing to Unicode: need string or buffer, long found
2016-03-24 00:36:07 [8910] [INFO] Starting gunicorn 17.5
2016-03-24 00:36:07 [8910] [ERROR] Connection in use: ('0', 8000)
2016-03-24 00:36:07 [8910] [ERROR] Retrying in 1 second.
2016-03-24 00:36:08 [8910] [ERROR] Connection in use: ('0', 8000)
2016-03-24 00:36:08 [8910] [ERROR] Retrying in 1 second.
2016-03-24 00:36:09 [8910] [ERROR] Connection in use: ('0', 8000)
2016-03-24 00:36:09 [8910] [ERROR] Retrying in 1 second.
2016-03-23 21:36:10 [8900] [DEBUG] GET /ask/
Internal Server Error: /ask/
Traceback (most recent call last):
  File "/usr/local/lib/python2.7/dist-packages/django/core/handlers/base.py", line 149, in get_response
    response = self.process_exception_by_middleware(e, request)
  File "/usr/local/lib/python2.7/dist-packages/django/core/handlers/base.py", line 147, in get_response
    response = wrapped_callback(request, *callback_args, **callback_kwargs)
  File "/home/tayfen/develop/stepic/web_apps/web/ask/qa/views.py", line 68, in ask
    url = post._get_url()
  File "/home/tayfen/develop/stepic/web_apps/web/ask/qa/models.py", line 18, in _get_url
    return "http://127.0.0.1/question/"+u'self.id'
TypeError: coercing to Unicode: need string or buffer, long found
2016-03-23 21:36:10 [8900] [INFO] Parent changed, shutting down: <Worker 8900>
2016-03-23 21:36:10 [8900] [INFO] Worker exiting (pid: 8900)
2016-03-24 00:36:10 [8910] [DEBUG] Arbiter booted
2016-03-24 00:36:10 [8910] [INFO] Listening at: http://0.0.0.0:8000 (8910)
2016-03-24 00:36:10 [8910] [INFO] Using worker: sync
2016-03-24 00:36:10 [8915] [INFO] Booting worker with pid: 8915
2016-03-23 21:36:11 [8915] [DEBUG] GET /ask/
2016-03-23 21:36:11 [8915] [DEBUG] GET /question/self.id
Not Found: /question/self.id
2016-03-23 21:37:31 [8915] [DEBUG] GET /ask/
2016-03-23 21:37:31 [8915] [DEBUG] GET /question/self.id
Not Found: /question/self.id
2016-03-24 00:37:38 [8926] [INFO] Starting gunicorn 17.5
2016-03-24 00:37:38 [8926] [ERROR] Connection in use: ('0', 8000)
2016-03-24 00:37:38 [8926] [ERROR] Retrying in 1 second.
2016-03-24 00:37:39 [8926] [ERROR] Connection in use: ('0', 8000)
2016-03-24 00:37:39 [8926] [ERROR] Retrying in 1 second.
2016-03-24 00:37:40 [8926] [ERROR] Connection in use: ('0', 8000)
2016-03-24 00:37:40 [8926] [ERROR] Retrying in 1 second.
2016-03-24 00:37:41 [8926] [ERROR] Connection in use: ('0', 8000)
2016-03-24 00:37:41 [8926] [ERROR] Retrying in 1 second.
2016-03-24 00:37:42 [8926] [ERROR] Connection in use: ('0', 8000)
2016-03-24 00:37:42 [8926] [ERROR] Retrying in 1 second.
2016-03-24 00:37:43 [8926] [ERROR] Can't connect to ('0', 8000)
2016-03-23 21:37:44 [8915] [DEBUG] GET /ask/
2016-03-23 21:37:44 [8915] [INFO] Parent changed, shutting down: <Worker 8915>
2016-03-23 21:37:44 [8915] [INFO] Worker exiting (pid: 8915)
2016-03-24 00:38:11 [8934] [INFO] Starting gunicorn 17.5
2016-03-24 00:38:11 [8934] [DEBUG] Arbiter booted
2016-03-24 00:38:11 [8934] [INFO] Listening at: http://0.0.0.0:8000 (8934)
2016-03-24 00:38:11 [8934] [INFO] Using worker: sync
2016-03-24 00:38:11 [8939] [INFO] Booting worker with pid: 8939
2016-03-23 21:38:20 [8939] [DEBUG] GET /ask/
2016-03-23 21:38:20 [8939] [DEBUG] GET /question/56
Not Found: /question/56
2016-03-23 21:38:20 [8939] [DEBUG] GET /question/56/
/usr/local/lib/python2.7/dist-packages/django/template/utils.py:37: RemovedInDjango110Warning: You haven't defined a TEMPLATES setting. You must do so before upgrading to Django 1.10. Otherwise Django will be unable to load templates.
  "unable to load templates.", RemovedInDjango110Warning)

2016-03-23 21:48:03 [8939] [DEBUG] GET /ask/
2016-03-23 21:48:03 [8939] [DEBUG] GET /question/57
Not Found: /question/57
2016-03-23 21:48:03 [8939] [DEBUG] GET /question/57/
2016-03-23 21:49:03 [8939] [DEBUG] GET /answer/
Internal Server Error: /answer/
Traceback (most recent call last):
  File "/usr/local/lib/python2.7/dist-packages/django/core/handlers/base.py", line 149, in get_response
    response = self.process_exception_by_middleware(e, request)
  File "/usr/local/lib/python2.7/dist-packages/django/core/handlers/base.py", line 147, in get_response
    response = wrapped_callback(request, *callback_args, **callback_kwargs)
  File "/home/tayfen/develop/stepic/web_apps/web/ask/qa/views.py", line 76, in answer
    if form.is_valid():
NameError: global name 'quest' is not defined
2016-03-23 21:49:48 [8939] [INFO] Parent changed, shutting down: <Worker 8939>
2016-03-23 21:49:48 [8939] [INFO] Worker exiting (pid: 8939)
2016-03-24 00:49:56 [9116] [INFO] Starting gunicorn 17.5
2016-03-24 00:49:56 [9116] [DEBUG] Arbiter booted
2016-03-24 00:49:56 [9116] [INFO] Listening at: http://0.0.0.0:8000 (9116)
2016-03-24 00:49:56 [9116] [INFO] Using worker: sync
2016-03-24 00:49:56 [9121] [INFO] Booting worker with pid: 9121
2016-03-23 21:50:06 [9121] [DEBUG] GET /answer/
Internal Server Error: /answer/
Traceback (most recent call last):
  File "/usr/local/lib/python2.7/dist-packages/django/core/handlers/base.py", line 134, in get_response
    resolver_match = resolver.resolve(request.path_info)
  File "/usr/local/lib/python2.7/dist-packages/django/core/urlresolvers.py", line 374, in resolve
    for pattern in self.url_patterns:
  File "/usr/local/lib/python2.7/dist-packages/django/utils/functional.py", line 33, in __get__
    res = instance.__dict__[self.name] = self.func(instance)
  File "/usr/local/lib/python2.7/dist-packages/django/core/urlresolvers.py", line 417, in url_patterns
    patterns = getattr(self.urlconf_module, "urlpatterns", self.urlconf_module)
  File "/usr/local/lib/python2.7/dist-packages/django/utils/functional.py", line 33, in __get__
    res = instance.__dict__[self.name] = self.func(instance)
  File "/usr/local/lib/python2.7/dist-packages/django/core/urlresolvers.py", line 410, in urlconf_module
    return import_module(self.urlconf_name)
  File "/usr/lib/python2.7/importlib/__init__.py", line 37, in import_module
    __import__(name)
  File "/home/tayfen/develop/stepic/web_apps/web/ask/ask/urls.py", line 4, in <module>
    from qa.views import *
  File "/home/tayfen/develop/stepic/web_apps/web/ask/qa/views.py", line 83
    
    ^
IndentationError: unexpected unindent
2016-03-23 21:51:01 [9121] [DEBUG] GET /answer/
Internal Server Error: /answer/
Traceback (most recent call last):
  File "/usr/local/lib/python2.7/dist-packages/django/core/handlers/base.py", line 149, in get_response
    response = self.process_exception_by_middleware(e, request)
  File "/usr/local/lib/python2.7/dist-packages/django/core/handlers/base.py", line 147, in get_response
    response = wrapped_callback(request, *callback_args, **callback_kwargs)
  File "/home/tayfen/develop/stepic/web_apps/web/ask/qa/views.py", line 74, in answer
    form = AnswerForm(request.Get)
AttributeError: 'WSGIRequest' object has no attribute 'Get'
2016-03-23 21:51:27 [9121] [DEBUG] GET /answer/
Internal Server Error: /answer/
Traceback (most recent call last):
  File "/usr/local/lib/python2.7/dist-packages/django/core/handlers/base.py", line 149, in get_response
    response = self.process_exception_by_middleware(e, request)
  File "/usr/local/lib/python2.7/dist-packages/django/core/handlers/base.py", line 147, in get_response
    response = wrapped_callback(request, *callback_args, **callback_kwargs)
  File "/home/tayfen/develop/stepic/web_apps/web/ask/qa/views.py", line 74, in answer
    form = AnswerForm(request.GET)
AttributeError: 'WSGIRequest' object has no attribute 'Get'
2016-03-23 21:51:28 [9121] [DEBUG] GET /answer/
Internal Server Error: /answer/
Traceback (most recent call last):
  File "/usr/local/lib/python2.7/dist-packages/django/core/handlers/base.py", line 149, in get_response
    response = self.process_exception_by_middleware(e, request)
  File "/usr/local/lib/python2.7/dist-packages/django/core/handlers/base.py", line 147, in get_response
    response = wrapped_callback(request, *callback_args, **callback_kwargs)
  File "/home/tayfen/develop/stepic/web_apps/web/ask/qa/views.py", line 74, in answer
    form = AnswerForm(request.GET)
AttributeError: 'WSGIRequest' object has no attribute 'Get'
2016-03-23 21:51:29 [9121] [DEBUG] GET /answer/
Internal Server Error: /answer/
Traceback (most recent call last):
  File "/usr/local/lib/python2.7/dist-packages/django/core/handlers/base.py", line 149, in get_response
    response = self.process_exception_by_middleware(e, request)
  File "/usr/local/lib/python2.7/dist-packages/django/core/handlers/base.py", line 147, in get_response
    response = wrapped_callback(request, *callback_args, **callback_kwargs)
  File "/home/tayfen/develop/stepic/web_apps/web/ask/qa/views.py", line 74, in answer
    form = AnswerForm(request.GET)
AttributeError: 'WSGIRequest' object has no attribute 'Get'
2016-03-23 21:51:42 [9121] [DEBUG] GET /answer/
Internal Server Error: /answer/
Traceback (most recent call last):
  File "/usr/local/lib/python2.7/dist-packages/django/core/handlers/base.py", line 149, in get_response
    response = self.process_exception_by_middleware(e, request)
  File "/usr/local/lib/python2.7/dist-packages/django/core/handlers/base.py", line 147, in get_response
    response = wrapped_callback(request, *callback_args, **callback_kwargs)
  File "/home/tayfen/develop/stepic/web_apps/web/ask/qa/views.py", line 74, in answer
    form = AnswerForm(request.GET)
AttributeError: 'WSGIRequest' object has no attribute 'Get'
2016-03-24 00:51:52 [9401] [INFO] Starting gunicorn 17.5
2016-03-24 00:51:52 [9401] [ERROR] Connection in use: ('0', 8000)
2016-03-24 00:51:52 [9401] [ERROR] Retrying in 1 second.
2016-03-24 00:51:53 [9401] [ERROR] Connection in use: ('0', 8000)
2016-03-24 00:51:53 [9401] [ERROR] Retrying in 1 second.
2016-03-24 00:51:54 [9401] [ERROR] Connection in use: ('0', 8000)
2016-03-24 00:51:54 [9401] [ERROR] Retrying in 1 second.
2016-03-24 00:51:55 [9401] [ERROR] Connection in use: ('0', 8000)
2016-03-24 00:51:55 [9401] [ERROR] Retrying in 1 second.
2016-03-24 00:51:56 [9401] [ERROR] Connection in use: ('0', 8000)
2016-03-24 00:51:56 [9401] [ERROR] Retrying in 1 second.
2016-03-23 21:51:57 [9121] [INFO] Parent changed, shutting down: <Worker 9121>
2016-03-23 21:51:57 [9121] [INFO] Worker exiting (pid: 9121)
2016-03-24 00:51:57 [9401] [ERROR] Can't connect to ('0', 8000)
2016-03-24 00:52:06 [9415] [INFO] Starting gunicorn 17.5
2016-03-24 00:52:06 [9415] [DEBUG] Arbiter booted
2016-03-24 00:52:06 [9415] [INFO] Listening at: http://0.0.0.0:8000 (9415)
2016-03-24 00:52:06 [9415] [INFO] Using worker: sync
2016-03-24 00:52:06 [9420] [INFO] Booting worker with pid: 9420
2016-03-23 21:52:09 [9420] [DEBUG] GET /answer/
2016-03-23 21:52:10 [9420] [DEBUG] GET /question/1
Not Found: /question/1
2016-03-23 21:52:10 [9420] [DEBUG] GET /question/1/
/usr/local/lib/python2.7/dist-packages/django/template/utils.py:37: RemovedInDjango110Warning: You haven't defined a TEMPLATES setting. You must do so before upgrading to Django 1.10. Otherwise Django will be unable to load templates.
  "unable to load templates.", RemovedInDjango110Warning)

